#######################################################################
# +-----------------------------------------------------------------+ #
# |                            BO3 object                           | #
# +-----------------------------------------------------------------+ #
#######################################################################

# The descriptions in this file are accurate only for TerrainControl and OTG.
# For MCW and OTG+ these descriptions are only accurate if the BO3 is used as a CustomObject.
# MCW and OTG+ completely reimplemented CustomStructure, check the MCW/OTG+ documentation for more information.

# This is the config file of a custom object.
# If you add this object correctly to your BiomeConfigs, it will spawn in the world.

# This is the creator of this BO3 object
Author: DedMaxim99

# A short description of this BO3 object
Description: This BO3 was converted from a schematic using OTGEdit. The author and description information of the schematic could not be found. If you know who the author of the schematic is then please add this information.

# The BO3 version, don't change this! It can be used by external applications to do a version check.
Version: 3

# The settings mode, WriteAll, WriteWithoutComments or WriteDisable. See WorldConfig.
SettingsMode: WriteDisable

#######################################################################
# +-----------------------------------------------------------------+ #
# |                          Main settings                          | #
# +-----------------------------------------------------------------+ #
#######################################################################

# This needs to be set to true to spawn the object in the Tree and Sapling resources.
Tree: false

# The frequency of the BO3 from 1 to 200. Tries this many times to spawn this BO3 when using the CustomObject(...) resource.
# Ignored by Tree(..), Sapling(..) and CustomStructure(..)
Frequency: 40

# The rarity of the BO3 from 0 to 100. Each spawn attempt has rarity% chance to succeed when using the CustomObject(...) resource.
# Ignored by Tree(..), Sapling(..) and CustomStructure(..)
Rarity: 100.0

# If you set this to true, the BO3 will be placed with a random rotation.
RotateRandomly: true

# The spawn height of the BO3 - randomY, highestBlock or highestSolidBlock.
SpawnHeight: randomY

# The height limits for the BO3.
MinHeight: 102

MaxHeight: 108

# Objects can have other objects attached to it: branches. Branches can also
# have branches attached to it, which can also have branches, etc. This is the
# maximum branch depth for this objects.
MaxBranchDepth: 10

# When spawned with the UseWorld keyword, this BO3 should NOT spawn in the following biomes.
# If you writer.write the BO3 name directly in the BiomeConfigs, this will be ignored.
ExcludedBiomes: All

# To optimise this BO3 for faster loading times you can use Notepad++ to find/replace comments and abbreviate things.
# Notepad++ find/replace with regex:
# Find: ^[#;].* replace to nothing removes all lines starting with # 
# Find: ^\s*$ replace to nothing removes most empty lines 
# Notepad++ find/replace without regex:
# *Warning: This will only work for OTG 1.10.2 v21 / OTG 1.11.2 v6 or higher. B( is not recognised by lower versions.
# Find: Block( replace to B(

#######################################################################
# +-----------------------------------------------------------------+ #
# |                      Source block settings                      | #
# +-----------------------------------------------------------------+ #
#######################################################################

# The block(s) the BO3 should spawn in.
SourceBlocks: AIR

# The maximum percentage of the BO3 that can be outside the SourceBlock.
# The BO3 won't be placed on a location with more blocks outside the SourceBlock than this percentage.
MaxPercentageOutsideSourceBlock: 100

# What to do when a block is about to be placed outside the SourceBlock? (dontPlace, placeAnyway)
OutsideSourceBlock: placeAnyway

#######################################################################
# +-----------------------------------------------------------------+ #
# |                              Blocks                             | #
# +-----------------------------------------------------------------+ #
#######################################################################

# All the blocks used in the BO3 are listed here. Possible blocks:
# Block(x,y,z,id[.data][,nbtfile.nbt) or B(x,y,z,id[.data][,nbtfile.nbt)
# RandomBlock(x,y,z,id[:data][,nbtfile.nbt],chance[,id[:data][,nbtfile.nbt],chance[,...]])
# So RandomBlock(0,0,0,CHEST,chest.nbt,50,CHEST,anotherchest.nbt,100) will spawn a chest at
# the BO3 origin, and give it a 50% chance to have the contents of chest.nbt, or, if that
# fails, a 100% percent chance to have the contents of anotherchest.nbt.

Block(-8,14,-7,24)
Block(-8,14,-6,24)
Block(-8,14,-5,24)
Block(-8,14,-4,24)
Block(-8,14,-3,24)
Block(-8,14,-2,24)
Block(-8,14,-1,24)
Block(-8,14,0,24)
Block(-8,14,1,24)
Block(-8,14,2,24)
Block(-8,14,3,24)
Block(-8,14,4,24)
Block(-8,14,5,24)
Block(-8,14,6,24)
Block(-8,14,7,24)
Block(-8,14,8,24)
Block(-8,15,-6,24)
Block(-8,15,-5,24)
Block(-8,15,-4,24)
Block(-8,15,-3,24)
Block(-8,15,-2,24)
Block(-8,15,-1,24)
Block(-8,15,0,24)
Block(-8,15,1,24)
Block(-8,15,2,24)
Block(-8,15,3,24)
Block(-8,15,4,24)
Block(-8,15,5,24)
Block(-8,15,6,24)
Block(-8,15,7,24)
Block(-8,15,8,24)
Block(-7,14,-7,24)
Block(-7,14,-6,24)
Block(-7,14,-5,24)
Block(-7,14,-4,24)
Block(-7,14,-3,24)
Block(-7,14,-2,24)
Block(-7,14,-1,24)
Block(-7,14,0,24)
Block(-7,14,1,24)
Block(-7,14,2,24)
Block(-7,14,3,24)
Block(-7,14,4,24)
Block(-7,14,5,24)
Block(-7,14,6,24)
Block(-7,14,7,24)
Block(-7,14,8,24)
Block(-7,15,-6,24)
Block(-7,15,-5,0)
Block(-7,15,-4,0)
Block(-7,15,-3,0)
Block(-7,15,-2,0)
Block(-7,15,-1,0)
Block(-7,15,0,0)
Block(-7,15,1,0)
Block(-7,15,2,0)
Block(-7,15,3,0)
Block(-7,15,4,0)
Block(-7,15,5,0)
Block(-7,15,6,0)
Block(-7,15,7,0)
Block(-7,15,8,0)
Block(-7,16,-5,24)
Block(-7,16,-4,24)
Block(-7,16,-3,24)
Block(-7,16,-2,24)
Block(-7,16,-1,24)
Block(-7,16,0,24)
Block(-7,16,1,24)
Block(-7,16,2,24)
Block(-7,16,3,24)
Block(-7,16,4,24)
Block(-7,16,5,24)
Block(-7,16,6,24)
Block(-7,16,7,24)
Block(-7,16,8,24)
Block(-6,14,-7,24)
Block(-6,14,-6,24)
Block(-6,14,-5,24)
Block(-6,14,-4,24)
Block(-6,14,-3,24)
Block(-6,14,-2,24)
Block(-6,14,-1,24)
Block(-6,14,0,24)
Block(-6,14,1,24)
Block(-6,14,2,24)
Block(-6,14,3,24)
Block(-6,14,4,24)
Block(-6,14,5,24)
Block(-6,14,6,24)
Block(-6,14,7,24)
Block(-6,14,8,24)
Block(-6,15,-6,24)
Block(-6,15,-5,0)
Block(-6,15,-4,0)
Block(-6,15,-3,24:2)
Block(-6,15,-2,0)
Block(-6,15,-1,0)
Block(-6,15,0,0)
Block(-6,15,1,0)
Block(-6,15,2,0)
Block(-6,15,3,0)
Block(-6,15,4,0)
Block(-6,15,5,0)
Block(-6,15,6,0)
Block(-6,15,7,0)
Block(-6,15,8,0)
Block(-6,16,-5,24)
Block(-6,16,-4,0)
Block(-6,16,-3,24:1)
Block(-6,16,-2,0)
Block(-6,16,-1,0)
Block(-6,16,0,0)
Block(-6,16,1,0)
Block(-6,16,2,0)
Block(-6,16,3,0)
Block(-6,16,4,0)
Block(-6,16,5,0)
Block(-6,16,6,0)
Block(-6,16,7,0)
Block(-6,16,8,0)
Block(-6,17,-4,24)
Block(-6,17,-3,24)
Block(-6,17,-2,24)
Block(-6,17,-1,24)
Block(-6,17,0,24)
Block(-6,17,1,24)
Block(-6,17,2,24)
Block(-6,17,3,24)
Block(-6,17,4,24)
Block(-6,17,5,24)
Block(-6,17,6,24)
Block(-6,17,7,24)
Block(-6,17,8,24)
Block(-5,14,-7,24)
Block(-5,14,-6,24)
Block(-5,14,-5,24)
Block(-5,14,-4,24)
Block(-5,14,-3,24)
Block(-5,14,-2,24)
Block(-5,14,-1,24)
Block(-5,14,0,24)
Block(-5,14,1,24)
Block(-5,14,2,24)
Block(-5,14,3,24)
Block(-5,14,4,24)
Block(-5,14,5,24)
Block(-5,14,6,24)
Block(-5,14,7,24)
Block(-5,14,8,24)
Block(-5,15,-6,24)
Block(-5,15,-5,0)
Block(-5,15,-4,0)
Block(-5,15,-3,0)
Block(-5,15,-2,0)
Block(-5,15,-1,0)
Block(-5,15,0,0)
Block(-5,15,1,0)
Block(-5,15,2,0)
Block(-5,15,3,0)
Block(-5,15,4,0)
Block(-5,15,5,0)
Block(-5,15,6,0)
Block(-5,15,7,0)
Block(-5,15,8,0)
Block(-5,16,-5,24)
Block(-5,16,-4,0)
Block(-5,16,-3,0)
Block(-5,16,-2,0)
Block(-5,16,-1,0)
Block(-5,16,0,0)
Block(-5,16,1,0)
Block(-5,16,2,0)
Block(-5,16,3,0)
Block(-5,16,4,0)
Block(-5,16,5,0)
Block(-5,16,6,0)
Block(-5,16,7,0)
Block(-5,16,8,0)
Block(-5,17,-4,24)
Block(-5,17,-3,24)
Block(-5,17,-2,0)
Block(-5,17,-1,0)
Block(-5,17,0,0)
Block(-5,17,1,0)
Block(-5,17,2,0)
Block(-5,17,3,0)
Block(-5,17,4,0)
Block(-5,17,5,0)
Block(-5,17,6,0)
Block(-5,17,7,0)
Block(-5,17,8,0)
Block(-5,18,-3,24)
Block(-5,18,-2,24)
Block(-5,18,-1,24)
Block(-5,18,0,24)
Block(-5,18,1,24)
Block(-5,18,2,24)
Block(-5,18,3,24)
Block(-5,18,4,24)
Block(-5,18,5,24)
Block(-5,18,6,24)
Block(-5,18,7,24)
Block(-5,18,8,24)
Block(-4,3,-1,24)
Block(-4,3,0,24)
Block(-4,3,1,24)
Block(-4,3,2,24)
Block(-4,3,3,24)
Block(-4,3,4,24)
Block(-4,3,5,24)
Block(-4,3,6,24)
Block(-4,3,7,24)
Block(-4,4,-1,24:2)
Block(-4,4,0,24:2)
Block(-4,4,1,24:2)
Block(-4,4,2,24:1)
Block(-4,4,3,24:1)
Block(-4,4,4,24:1)
Block(-4,4,5,24:2)
Block(-4,4,6,24:2)
Block(-4,4,7,24:2)
Block(-4,5,-1,24:2)
Block(-4,5,0,24:2)
Block(-4,5,1,24:2)
Block(-4,5,2,24:2)
Block(-4,5,3,24:2)
Block(-4,5,4,24:2)
Block(-4,5,5,24:2)
Block(-4,5,6,24:2)
Block(-4,5,7,24:2)
Block(-4,14,-7,24)
Block(-4,14,-6,24)
Block(-4,14,-5,24)
Block(-4,14,-4,24)
Block(-4,14,-3,24)
Block(-4,14,-2,24)
Block(-4,14,-1,24)
Block(-4,14,0,24)
Block(-4,14,1,24)
Block(-4,14,2,24)
Block(-4,14,3,24)
Block(-4,14,4,24)
Block(-4,14,5,24)
Block(-4,14,6,24)
Block(-4,14,7,24)
Block(-4,14,8,24)
Block(-4,15,-6,24)
Block(-4,15,-5,0)
Block(-4,15,-4,0)
Block(-4,15,-3,24:2)
Block(-4,15,-2,0)
Block(-4,15,-1,0)
Block(-4,15,0,0)
Block(-4,15,1,0)
Block(-4,15,2,0)
Block(-4,15,3,0)
Block(-4,15,4,0)
Block(-4,15,5,0)
Block(-4,15,6,0)
Block(-4,15,7,0)
Block(-4,15,8,0)
Block(-4,16,-5,24)
Block(-4,16,-4,0)
Block(-4,16,-3,24:1)
Block(-4,16,-2,0)
Block(-4,16,-1,0)
Block(-4,16,0,0)
Block(-4,16,1,0)
Block(-4,16,2,0)
Block(-4,16,3,0)
Block(-4,16,4,0)
Block(-4,16,5,0)
Block(-4,16,6,0)
Block(-4,16,7,0)
Block(-4,16,8,0)
Block(-4,17,-4,24)
Block(-4,17,-3,24)
Block(-4,17,-2,0)
Block(-4,17,-1,0)
Block(-4,17,0,0)
Block(-4,17,1,0)
Block(-4,17,2,0)
Block(-4,17,3,0)
Block(-4,17,4,0)
Block(-4,17,5,0)
Block(-4,17,6,0)
Block(-4,17,7,0)
Block(-4,17,8,0)
Block(-4,18,-3,24)
Block(-4,18,-2,24)
Block(-4,18,-1,24)
Block(-4,18,0,24)
Block(-4,18,1,24)
Block(-4,18,2,24)
Block(-4,18,3,24)
Block(-4,18,4,24)
Block(-4,18,5,24)
Block(-4,18,6,24)
Block(-4,18,7,24)
Block(-4,18,8,24)
Block(-4,19,-2,24)
Block(-4,19,-1,24)
Block(-4,19,0,24)
Block(-4,19,1,24)
Block(-4,19,2,24)
Block(-4,19,3,24)
Block(-4,19,4,24)
Block(-4,19,5,24)
Block(-4,19,6,24)
Block(-4,19,7,24)
Block(-4,19,8,24)
Block(-3,1,3,24)
Block(-3,2,-1,159:14)
Block(-3,2,0,159:14)
Block(-3,2,1,159:14)
Block(-3,2,2,159:14)
Block(-3,2,3,46)
Block(-3,2,4,159:14)
Block(-3,2,5,159:14)
Block(-3,2,6,159:14)
Block(-3,2,7,159:14)
Block(-3,3,-2,24)
Block(-3,3,-1,0)
Block(-3,3,0,0)
Block(-3,3,1,0)
Block(-3,3,2,0)
Block(-3,3,3,146:5,../../nbt/chestDesert.nbt,100)
Block(-3,3,4,0)
Block(-3,3,5,0)
Block(-3,3,6,0)
Block(-3,3,7,0)
Block(-3,3,8,24)
Block(-3,4,-2,24:2)
Block(-3,4,-1,0)
Block(-3,4,0,0)
Block(-3,4,1,0)
Block(-3,4,2,0)
Block(-3,4,3,0)
Block(-3,4,4,0)
Block(-3,4,5,0)
Block(-3,4,6,0)
Block(-3,4,7,0)
Block(-3,4,8,24:2)
Block(-3,5,-2,24:2)
Block(-3,5,-1,0)
Block(-3,5,0,0)
Block(-3,5,1,0)
Block(-3,5,2,0)
Block(-3,5,3,0)
Block(-3,5,4,0)
Block(-3,5,5,0)
Block(-3,5,6,0)
Block(-3,5,7,0)
Block(-3,5,8,24:2)
Block(-3,6,-1,24:2)
Block(-3,6,0,24:2)
Block(-3,6,1,24:2)
Block(-3,6,2,24:2)
Block(-3,6,3,24:2)
Block(-3,6,4,24:2)
Block(-3,6,5,24:2)
Block(-3,6,6,24:2)
Block(-3,6,7,24:2)
Block(-3,14,-7,24)
Block(-3,14,-6,24)
Block(-3,14,-5,24)
Block(-3,14,-4,24)
Block(-3,14,-3,24)
Block(-3,14,-2,24)
Block(-3,14,-1,24)
Block(-3,14,0,24)
Block(-3,14,1,24)
Block(-3,14,2,24)
Block(-3,14,3,24)
Block(-3,14,4,24)
Block(-3,14,5,24)
Block(-3,14,6,24)
Block(-3,14,7,24)
Block(-3,14,8,24)
Block(-3,15,-6,24)
Block(-3,15,-5,0)
Block(-3,15,-4,0)
Block(-3,15,-3,0)
Block(-3,15,-2,0)
Block(-3,15,-1,0)
Block(-3,15,0,0)
Block(-3,15,1,0)
Block(-3,15,2,0)
Block(-3,15,3,0)
Block(-3,15,4,0)
Block(-3,15,5,0)
Block(-3,15,6,0)
Block(-3,15,7,0)
Block(-3,15,8,0)
Block(-3,16,-5,24)
Block(-3,16,-4,0)
Block(-3,16,-3,0)
Block(-3,16,-2,0)
Block(-3,16,-1,0)
Block(-3,16,0,0)
Block(-3,16,1,0)
Block(-3,16,2,0)
Block(-3,16,3,0)
Block(-3,16,4,0)
Block(-3,16,5,0)
Block(-3,16,6,0)
Block(-3,16,7,0)
Block(-3,16,8,0)
Block(-3,17,-4,24)
Block(-3,17,-3,24)
Block(-3,17,-2,0)
Block(-3,17,-1,0)
Block(-3,17,0,0)
Block(-3,17,1,0)
Block(-3,17,2,0)
Block(-3,17,3,0)
Block(-3,17,4,0)
Block(-3,17,5,0)
Block(-3,17,6,0)
Block(-3,17,7,0)
Block(-3,17,8,0)
Block(-3,18,-3,24)
Block(-3,18,-2,24)
Block(-3,18,-1,24)
Block(-3,18,0,24)
Block(-3,18,1,24)
Block(-3,18,2,24)
Block(-3,18,3,24)
Block(-3,18,4,24)
Block(-3,18,5,24)
Block(-3,18,6,24)
Block(-3,18,7,24)
Block(-3,18,8,24)
Block(-3,19,-2,24)
Block(-3,19,-1,0)
Block(-3,19,0,0)
Block(-3,19,1,0)
Block(-3,19,2,0)
Block(-3,19,3,0)
Block(-3,19,4,0)
Block(-3,19,5,0)
Block(-3,19,6,0)
Block(-3,19,7,0)
Block(-3,19,8,24)
Block(-3,20,-1,24)
Block(-3,20,0,24)
Block(-3,20,1,24)
Block(-3,20,2,24)
Block(-3,20,3,24)
Block(-3,20,4,24)
Block(-3,20,5,24)
Block(-3,20,6,24)
Block(-3,20,7,24)
Block(-2,0,3,24:2)
Block(-2,1,3,46)
Block(-2,2,-1,159:14)
Block(-2,2,0,24:2)
Block(-2,2,1,24:2)
Block(-2,2,2,24:2)
Block(-2,2,3,24:2)
Block(-2,2,4,24:2)
Block(-2,2,5,24:2)
Block(-2,2,6,24:2)
Block(-2,2,7,159:14)
Block(-2,3,-2,24)
Block(-2,3,-1,0)
Block(-2,3,0,0)
Block(-2,3,1,0)
Block(-2,3,2,0)
Block(-2,3,3,0)
Block(-2,3,4,0)
Block(-2,3,5,0)
Block(-2,3,6,0)
Block(-2,3,7,0)
Block(-2,3,8,24)
Block(-2,4,-2,24:2)
Block(-2,4,-1,0)
Block(-2,4,0,0)
Block(-2,4,1,0)
Block(-2,4,2,0)
Block(-2,4,3,0)
Block(-2,4,4,0)
Block(-2,4,5,0)
Block(-2,4,6,0)
Block(-2,4,7,0)
Block(-2,4,8,24:2)
Block(-2,5,-2,24:2)
Block(-2,5,-1,0)
Block(-2,5,0,0)
Block(-2,5,1,0)
Block(-2,5,2,0)
Block(-2,5,3,0)
Block(-2,5,4,0)
Block(-2,5,5,0)
Block(-2,5,6,0)
Block(-2,5,7,0)
Block(-2,5,8,24:2)
Block(-2,6,-1,24:2)
Block(-2,6,0,24:2)
Block(-2,6,1,24:2)
Block(-2,6,2,24:2)
Block(-2,6,3,24:2)
Block(-2,6,4,24:2)
Block(-2,6,5,24:2)
Block(-2,6,6,24:2)
Block(-2,6,7,24:2)
Block(-2,14,-7,24)
Block(-2,14,-6,24)
Block(-2,14,-5,24)
Block(-2,14,-4,24)
Block(-2,14,-3,24)
Block(-2,14,-2,24)
Block(-2,14,-1,24)
Block(-2,14,0,24)
Block(-2,14,1,24)
Block(-2,14,2,24)
Block(-2,14,3,159:1)
Block(-2,14,4,24)
Block(-2,14,5,24)
Block(-2,14,6,24)
Block(-2,14,7,24)
Block(-2,14,8,24)
Block(-2,15,-6,24)
Block(-2,15,-5,0)
Block(-2,15,-4,0)
Block(-2,15,-3,24:2)
Block(-2,15,-2,0)
Block(-2,15,-1,0)
Block(-2,15,0,0)
Block(-2,15,1,0)
Block(-2,15,2,0)
Block(-2,15,3,0)
Block(-2,15,4,0)
Block(-2,15,5,0)
Block(-2,15,6,0)
Block(-2,15,7,0)
Block(-2,15,8,0)
Block(-2,16,-5,24)
Block(-2,16,-4,0)
Block(-2,16,-3,24:1)
Block(-2,16,-2,0)
Block(-2,16,-1,0)
Block(-2,16,0,0)
Block(-2,16,1,0)
Block(-2,16,2,0)
Block(-2,16,3,0)
Block(-2,16,4,0)
Block(-2,16,5,0)
Block(-2,16,6,0)
Block(-2,16,7,0)
Block(-2,16,8,0)
Block(-2,17,-4,24)
Block(-2,17,-3,24)
Block(-2,17,-2,0)
Block(-2,17,-1,0)
Block(-2,17,0,0)
Block(-2,17,1,0)
Block(-2,17,2,0)
Block(-2,17,3,0)
Block(-2,17,4,0)
Block(-2,17,5,0)
Block(-2,17,6,0)
Block(-2,17,7,0)
Block(-2,17,8,0)
Block(-2,18,-3,24)
Block(-2,18,-2,24)
Block(-2,18,-1,24)
Block(-2,18,0,24)
Block(-2,18,1,24)
Block(-2,18,2,24)
Block(-2,18,3,24)
Block(-2,18,4,24)
Block(-2,18,5,24)
Block(-2,18,6,24)
Block(-2,18,7,24)
Block(-2,18,8,24)
Block(-2,19,-2,24)
Block(-2,19,-1,0)
Block(-2,19,0,0)
Block(-2,19,1,0)
Block(-2,19,2,0)
Block(-2,19,3,0)
Block(-2,19,4,0)
Block(-2,19,5,0)
Block(-2,19,6,0)
Block(-2,19,7,0)
Block(-2,19,8,24)
Block(-2,20,-1,24)
Block(-2,20,0,0)
Block(-2,20,1,0)
Block(-2,20,2,0)
Block(-2,20,3,0)
Block(-2,20,4,0)
Block(-2,20,5,0)
Block(-2,20,6,0)
Block(-2,20,7,24)
Block(-2,21,0,24)
Block(-2,21,1,24)
Block(-2,21,2,24)
Block(-2,21,3,24)
Block(-2,21,4,24)
Block(-2,21,5,24)
Block(-2,21,6,24)
Block(-1,0,1,24:2)
Block(-1,0,2,24:2)
Block(-1,0,3,24:2)
Block(-1,0,4,24:2)
Block(-1,0,5,24:2)
Block(-1,1,1,24:2)
Block(-1,1,2,24:2)
Block(-1,1,3,24:2)
Block(-1,1,4,24:2)
Block(-1,1,5,24:2)
Block(-1,2,-1,159:14)
Block(-1,2,0,24:2)
Block(-1,2,1,24:2)
Block(-1,2,2,24:2)
Block(-1,2,3,24:2)
Block(-1,2,4,24:2)
Block(-1,2,5,24:2)
Block(-1,2,6,24:2)
Block(-1,2,7,159:14)
Block(-1,3,-2,24)
Block(-1,3,-1,0)
Block(-1,3,0,0)
Block(-1,3,1,24:2)
Block(-1,3,2,0)
Block(-1,3,3,0)
Block(-1,3,4,0)
Block(-1,3,5,24:2)
Block(-1,3,6,0)
Block(-1,3,7,0)
Block(-1,3,8,24)
Block(-1,4,-2,24:2)
Block(-1,4,-1,0)
Block(-1,4,0,0)
Block(-1,4,1,24:2)
Block(-1,4,2,0)
Block(-1,4,3,0)
Block(-1,4,4,0)
Block(-1,4,5,24:2)
Block(-1,4,6,0)
Block(-1,4,7,0)
Block(-1,4,8,24:2)
Block(-1,5,-2,24:2)
Block(-1,5,-1,0)
Block(-1,5,0,0)
Block(-1,5,1,24:2)
Block(-1,5,2,0)
Block(-1,5,3,0)
Block(-1,5,4,0)
Block(-1,5,5,24:2)
Block(-1,5,6,0)
Block(-1,5,7,0)
Block(-1,5,8,24:2)
Block(-1,6,-1,24:2)
Block(-1,6,0,24:2)
Block(-1,6,1,24)
Block(-1,6,2,24)
Block(-1,6,3,24)
Block(-1,6,4,24)
Block(-1,6,5,24)
Block(-1,6,6,24:2)
Block(-1,6,7,24:2)
Block(-1,7,2,24)
Block(-1,7,3,24)
Block(-1,7,4,24)
Block(-1,8,2,24)
Block(-1,8,3,24)
Block(-1,8,4,24)
Block(-1,9,2,24)
Block(-1,9,3,24)
Block(-1,9,4,24)
Block(-1,10,2,24)
Block(-1,10,3,24)
Block(-1,10,4,24)
Block(-1,11,2,24)
Block(-1,11,3,24)
Block(-1,11,4,24)
Block(-1,12,2,24)
Block(-1,12,3,24)
Block(-1,12,4,24)
Block(-1,13,2,24)
Block(-1,13,3,24)
Block(-1,13,4,24)
Block(-1,14,-7,24)
Block(-1,14,-6,24)
Block(-1,14,-5,24)
Block(-1,14,-4,24)
Block(-1,14,-3,24)
Block(-1,14,-2,24)
Block(-1,14,-1,24)
Block(-1,14,0,24)
Block(-1,14,1,24)
Block(-1,14,2,24)
Block(-1,14,3,159:1)
Block(-1,14,4,24)
Block(-1,14,5,24)
Block(-1,14,6,24)
Block(-1,14,7,24)
Block(-1,14,8,24)
Block(-1,15,-6,24)
Block(-1,15,-5,0)
Block(-1,15,-4,0)
Block(-1,15,-3,0)
Block(-1,15,-2,0)
Block(-1,15,-1,0)
Block(-1,15,0,0)
Block(-1,15,1,24:2)
Block(-1,15,2,0)
Block(-1,15,3,0)
Block(-1,15,4,0)
Block(-1,15,5,24:2)
Block(-1,15,6,0)
Block(-1,15,7,0)
Block(-1,15,8,0)
Block(-1,16,-5,24)
Block(-1,16,-4,0)
Block(-1,16,-3,0)
Block(-1,16,-2,0)
Block(-1,16,-1,0)
Block(-1,16,0,0)
Block(-1,16,1,24:2)
Block(-1,16,2,0)
Block(-1,16,3,0)
Block(-1,16,4,0)
Block(-1,16,5,24:2)
Block(-1,16,6,0)
Block(-1,16,7,0)
Block(-1,16,8,0)
Block(-1,17,-4,24)
Block(-1,17,-3,24)
Block(-1,17,-2,0)
Block(-1,17,-1,0)
Block(-1,17,0,0)
Block(-1,17,1,24:2)
Block(-1,17,2,0)
Block(-1,17,3,0)
Block(-1,17,4,0)
Block(-1,17,5,24:2)
Block(-1,17,6,0)
Block(-1,17,7,0)
Block(-1,17,8,0)
Block(-1,18,-3,24)
Block(-1,18,-2,24)
Block(-1,18,-1,24)
Block(-1,18,0,24)
Block(-1,18,1,24)
Block(-1,18,2,24)
Block(-1,18,3,24)
Block(-1,18,4,24)
Block(-1,18,5,24)
Block(-1,18,6,24)
Block(-1,18,7,24)
Block(-1,18,8,24)
Block(-1,19,-2,24)
Block(-1,19,-1,0)
Block(-1,19,0,0)
Block(-1,19,1,0)
Block(-1,19,2,0)
Block(-1,19,3,0)
Block(-1,19,4,0)
Block(-1,19,5,0)
Block(-1,19,6,0)
Block(-1,19,7,0)
Block(-1,19,8,24)
Block(-1,20,-1,24)
Block(-1,20,0,0)
Block(-1,20,1,0)
Block(-1,20,2,0)
Block(-1,20,3,0)
Block(-1,20,4,0)
Block(-1,20,5,0)
Block(-1,20,6,0)
Block(-1,20,7,24)
Block(-1,21,0,24)
Block(-1,21,1,0)
Block(-1,21,2,0)
Block(-1,21,3,0)
Block(-1,21,4,0)
Block(-1,21,5,0)
Block(-1,21,6,24)
Block(-1,22,1,24)
Block(-1,22,2,24)
Block(-1,22,3,24)
Block(-1,22,4,24)
Block(-1,22,5,24)
Block(0,0,1,24:2)
Block(0,0,2,24:2)
Block(0,0,3,24:2)
Block(0,0,4,24:2)
Block(0,0,5,24:2)
Block(0,1,1,24:2)
Block(0,1,2,24:2)
Block(0,1,3,46)
Block(0,1,4,24:2)
Block(0,1,5,24:2)
Block(0,2,-1,159:14)
Block(0,2,0,24:2)
Block(0,2,1,24:2)
Block(0,2,2,24:2)
Block(0,2,3,24:2)
Block(0,2,4,24:2)
Block(0,2,5,24:2)
Block(0,2,6,24:2)
Block(0,2,7,159:14)
Block(0,3,-2,24)
Block(0,3,-1,0)
Block(0,3,0,0)
Block(0,3,1,0)
Block(0,3,2,0)
Block(0,3,3,0)
Block(0,3,4,0)
Block(0,3,5,0)
Block(0,3,6,0)
Block(0,3,7,0)
Block(0,3,8,24)
Block(0,4,-2,24:1)
Block(0,4,-1,0)
Block(0,4,0,0)
Block(0,4,1,0)
Block(0,4,2,0)
Block(0,4,3,0)
Block(0,4,4,0)
Block(0,4,5,0)
Block(0,4,6,0)
Block(0,4,7,0)
Block(0,4,8,24:1)
Block(0,5,-2,24:2)
Block(0,5,-1,0)
Block(0,5,0,0)
Block(0,5,1,0)
Block(0,5,2,0)
Block(0,5,3,0)
Block(0,5,4,0)
Block(0,5,5,0)
Block(0,5,6,0)
Block(0,5,7,0)
Block(0,5,8,24:2)
Block(0,6,-1,24:2)
Block(0,6,0,24:2)
Block(0,6,1,24)
Block(0,6,2,0)
Block(0,6,3,0)
Block(0,6,4,0)
Block(0,6,5,24)
Block(0,6,6,24:2)
Block(0,6,7,24:2)
Block(0,7,1,24)
Block(0,7,2,0)
Block(0,7,3,0)
Block(0,7,4,0)
Block(0,7,5,24)
Block(0,8,1,24)
Block(0,8,2,0)
Block(0,8,3,0)
Block(0,8,4,0)
Block(0,8,5,24)
Block(0,9,1,24)
Block(0,9,2,0)
Block(0,9,3,0)
Block(0,9,4,0)
Block(0,9,5,24)
Block(0,10,1,24)
Block(0,10,2,0)
Block(0,10,3,0)
Block(0,10,4,0)
Block(0,10,5,24)
Block(0,11,1,24)
Block(0,11,2,0)
Block(0,11,3,0)
Block(0,11,4,0)
Block(0,11,5,24)
Block(0,12,1,24)
Block(0,12,2,0)
Block(0,12,3,0)
Block(0,12,4,0)
Block(0,12,5,24)
Block(0,13,1,24)
Block(0,13,2,0)
Block(0,13,3,0)
Block(0,13,4,0)
Block(0,13,5,24)
Block(0,14,-7,24)
Block(0,14,-6,24)
Block(0,14,-5,24)
Block(0,14,-4,24)
Block(0,14,-3,24)
Block(0,14,-2,24)
Block(0,14,-1,24)
Block(0,14,0,24)
Block(0,14,1,24)
Block(0,14,2,159:1)
Block(0,14,3,24)
Block(0,14,4,159:1)
Block(0,14,5,24)
Block(0,14,6,24)
Block(0,14,7,24)
Block(0,14,8,24)
Block(0,15,-7,24)
Block(0,15,-6,24)
Block(0,15,-5,0)
Block(0,15,-4,0)
Block(0,15,-3,24:2)
Block(0,15,-2,0)
Block(0,15,-1,0)
Block(0,15,0,0)
Block(0,15,1,0)
Block(0,15,2,0)
Block(0,15,3,0)
Block(0,15,4,0)
Block(0,15,5,0)
Block(0,15,6,0)
Block(0,15,7,0)
Block(0,15,8,0)
Block(0,16,-7,24)
Block(0,16,-6,24)
Block(0,16,-5,24)
Block(0,16,-4,0)
Block(0,16,-3,24:1)
Block(0,16,-2,0)
Block(0,16,-1,0)
Block(0,16,0,0)
Block(0,16,1,0)
Block(0,16,2,0)
Block(0,16,3,0)
Block(0,16,4,0)
Block(0,16,5,0)
Block(0,16,6,0)
Block(0,16,7,0)
Block(0,16,8,0)
Block(0,17,-7,24)
Block(0,17,-6,24)
Block(0,17,-5,24)
Block(0,17,-4,24)
Block(0,17,-3,24)
Block(0,17,-2,0)
Block(0,17,-1,0)
Block(0,17,0,0)
Block(0,17,1,0)
Block(0,17,2,0)
Block(0,17,3,0)
Block(0,17,4,0)
Block(0,17,5,0)
Block(0,17,6,0)
Block(0,17,7,0)
Block(0,17,8,0)
Block(0,18,-7,24)
Block(0,18,-6,24)
Block(0,18,-5,24)
Block(0,18,-4,24)
Block(0,18,-3,24)
Block(0,18,-2,24)
Block(0,18,-1,24)
Block(0,18,0,24)
Block(0,18,1,24)
Block(0,18,2,0)
Block(0,18,3,0)
Block(0,18,4,0)
Block(0,18,5,24)
Block(0,18,6,24)
Block(0,18,7,24)
Block(0,18,8,24)
Block(0,19,-3,24)
Block(0,19,-2,24:2)
Block(0,19,-1,0)
Block(0,19,0,0)
Block(0,19,1,0)
Block(0,19,2,0)
Block(0,19,3,0)
Block(0,19,4,0)
Block(0,19,5,0)
Block(0,19,6,0)
Block(0,19,7,0)
Block(0,19,8,24:2)
Block(0,20,-2,24:2)
Block(0,20,-1,24)
Block(0,20,0,0)
Block(0,20,1,0)
Block(0,20,2,0)
Block(0,20,3,0)
Block(0,20,4,0)
Block(0,20,5,0)
Block(0,20,6,0)
Block(0,20,7,24)
Block(0,20,8,24:2)
Block(0,21,-2,24:2)
Block(0,21,-1,24)
Block(0,21,0,24)
Block(0,21,1,0)
Block(0,21,2,0)
Block(0,21,3,0)
Block(0,21,4,0)
Block(0,21,5,0)
Block(0,21,6,24)
Block(0,21,7,24)
Block(0,21,8,24:2)
Block(0,22,1,24)
Block(0,22,2,0)
Block(0,22,3,0)
Block(0,22,4,0)
Block(0,22,5,24)
Block(0,23,2,24)
Block(0,23,3,24)
Block(0,23,4,24)
Block(1,0,0,24:2)
Block(1,0,1,24:2)
Block(1,0,2,24:2)
Block(1,0,3,24:2)
Block(1,0,4,24:2)
Block(1,0,5,24:2)
Block(1,0,6,24:2)
Block(1,1,-1,24)
Block(1,1,0,46)
Block(1,1,1,24:2)
Block(1,1,2,46)
Block(1,1,3,46)
Block(1,1,4,46)
Block(1,1,5,24:2)
Block(1,1,6,46)
Block(1,1,7,24)
Block(1,2,-1,46)
Block(1,2,0,24:2)
Block(1,2,1,24:2)
Block(1,2,2,24:2)
Block(1,2,3,24:2)
Block(1,2,4,24:2)
Block(1,2,5,24:2)
Block(1,2,6,24:2)
Block(1,2,7,46)
Block(1,3,-2,24)
Block(1,3,-1,146:3,../../nbt/chestDesert.nbt,100)
Block(1,3,0,0)
Block(1,3,1,0)
Block(1,3,2,0)
Block(1,3,3,70)
Block(1,3,4,0)
Block(1,3,5,0)
Block(1,3,6,0)
Block(1,3,7,146:0,../../nbt/chestDesert.nbt,100)
Block(1,3,8,24)
Block(1,4,-2,24:1)
Block(1,4,-1,0)
Block(1,4,0,0)
Block(1,4,1,0)
Block(1,4,2,0)
Block(1,4,3,0)
Block(1,4,4,0)
Block(1,4,5,0)
Block(1,4,6,0)
Block(1,4,7,0)
Block(1,4,8,24:1)
Block(1,5,-2,24:2)
Block(1,5,-1,0)
Block(1,5,0,0)
Block(1,5,1,0)
Block(1,5,2,0)
Block(1,5,3,0)
Block(1,5,4,0)
Block(1,5,5,0)
Block(1,5,6,0)
Block(1,5,7,0)
Block(1,5,8,24:2)
Block(1,6,-1,24:2)
Block(1,6,0,24:2)
Block(1,6,1,24)
Block(1,6,2,0)
Block(1,6,3,0)
Block(1,6,4,0)
Block(1,6,5,24)
Block(1,6,6,24:2)
Block(1,6,7,24:2)
Block(1,7,1,24)
Block(1,7,2,0)
Block(1,7,3,0)
Block(1,7,4,0)
Block(1,7,5,24)
Block(1,8,1,24)
Block(1,8,2,0)
Block(1,8,3,0)
Block(1,8,4,0)
Block(1,8,5,24)
Block(1,9,1,24)
Block(1,9,2,0)
Block(1,9,3,0)
Block(1,9,4,0)
Block(1,9,5,24)
Block(1,10,1,24)
Block(1,10,2,0)
Block(1,10,3,0)
Block(1,10,4,0)
Block(1,10,5,24)
Block(1,11,1,24)
Block(1,11,2,0)
Block(1,11,3,0)
Block(1,11,4,0)
Block(1,11,5,24)
Block(1,12,1,24)
Block(1,12,2,0)
Block(1,12,3,0)
Block(1,12,4,0)
Block(1,12,5,24)
Block(1,13,1,24)
Block(1,13,2,0)
Block(1,13,3,0)
Block(1,13,4,0)
Block(1,13,5,24)
Block(1,14,-7,24)
Block(1,14,-6,24)
Block(1,14,-5,24)
Block(1,14,-4,24)
Block(1,14,-3,24)
Block(1,14,-2,24)
Block(1,14,-1,24)
Block(1,14,0,159:1)
Block(1,14,1,159:1)
Block(1,14,2,24)
Block(1,14,3,159:11)
Block(1,14,4,24)
Block(1,14,5,159:1)
Block(1,14,6,159:1)
Block(1,14,7,24)
Block(1,14,8,24)
Block(1,15,-7,24)
Block(1,15,-6,24)
Block(1,15,-5,0)
Block(1,15,-4,0)
Block(1,15,-3,0)
Block(1,15,-2,0)
Block(1,15,-1,0)
Block(1,15,0,0)
Block(1,15,1,0)
Block(1,15,2,0)
Block(1,15,3,0)
Block(1,15,4,0)
Block(1,15,5,0)
Block(1,15,6,0)
Block(1,15,7,0)
Block(1,15,8,0)
Block(1,16,-7,24)
Block(1,16,-6,24)
Block(1,16,-5,24)
Block(1,16,-4,0)
Block(1,16,-3,0)
Block(1,16,-2,0)
Block(1,16,-1,0)
Block(1,16,0,0)
Block(1,16,1,0)
Block(1,16,2,0)
Block(1,16,3,0)
Block(1,16,4,0)
Block(1,16,5,0)
Block(1,16,6,0)
Block(1,16,7,0)
Block(1,16,8,0)
Block(1,17,-7,24)
Block(1,17,-6,24)
Block(1,17,-5,24)
Block(1,17,-4,24)
Block(1,17,-3,24)
Block(1,17,-2,0)
Block(1,17,-1,0)
Block(1,17,0,0)
Block(1,17,1,0)
Block(1,17,2,0)
Block(1,17,3,0)
Block(1,17,4,0)
Block(1,17,5,0)
Block(1,17,6,0)
Block(1,17,7,0)
Block(1,17,8,0)
Block(1,18,-7,24)
Block(1,18,-6,24)
Block(1,18,-5,24)
Block(1,18,-4,24)
Block(1,18,-3,24)
Block(1,18,-2,24)
Block(1,18,-1,24)
Block(1,18,0,24)
Block(1,18,1,24)
Block(1,18,2,0)
Block(1,18,3,0)
Block(1,18,4,0)
Block(1,18,5,24)
Block(1,18,6,24)
Block(1,18,7,24)
Block(1,18,8,24)
Block(1,19,-2,0)
Block(1,19,-1,0)
Block(1,19,0,0)
Block(1,19,1,0)
Block(1,19,2,0)
Block(1,19,3,0)
Block(1,19,4,0)
Block(1,19,5,0)
Block(1,19,6,0)
Block(1,19,7,0)
Block(1,19,8,0)
Block(1,20,-2,0)
Block(1,20,-1,0)
Block(1,20,0,0)
Block(1,20,1,0)
Block(1,20,2,0)
Block(1,20,3,0)
Block(1,20,4,0)
Block(1,20,5,0)
Block(1,20,6,0)
Block(1,20,7,0)
Block(1,20,8,0)
Block(1,21,-2,24:2)
Block(1,21,-1,24)
Block(1,21,0,24)
Block(1,21,1,0)
Block(1,21,2,0)
Block(1,21,3,0)
Block(1,21,4,0)
Block(1,21,5,0)
Block(1,21,6,24)
Block(1,21,7,24)
Block(1,21,8,24:2)
Block(1,22,1,24)
Block(1,22,2,0)
Block(1,22,3,0)
Block(1,22,4,0)
Block(1,22,5,24)
Block(1,23,2,24)
Block(1,23,3,0)
Block(1,23,4,24)
Block(2,0,1,24:2)
Block(2,0,2,24:2)
Block(2,0,3,24:2)
Block(2,0,4,24:2)
Block(2,0,5,24:2)
Block(2,1,1,24:2)
Block(2,1,2,24:2)
Block(2,1,3,46)
Block(2,1,4,24:2)
Block(2,1,5,24:2)
Block(2,2,-1,159:14)
Block(2,2,0,24:2)
Block(2,2,1,24:2)
Block(2,2,2,24:2)
Block(2,2,3,24:2)
Block(2,2,4,24:2)
Block(2,2,5,24:2)
Block(2,2,6,24:2)
Block(2,2,7,159:14)
Block(2,3,-2,24)
Block(2,3,-1,0)
Block(2,3,0,0)
Block(2,3,1,0)
Block(2,3,2,0)
Block(2,3,3,0)
Block(2,3,4,0)
Block(2,3,5,0)
Block(2,3,6,0)
Block(2,3,7,0)
Block(2,3,8,24)
Block(2,4,-2,24:1)
Block(2,4,-1,0)
Block(2,4,0,0)
Block(2,4,1,0)
Block(2,4,2,0)
Block(2,4,3,0)
Block(2,4,4,0)
Block(2,4,5,0)
Block(2,4,6,0)
Block(2,4,7,0)
Block(2,4,8,24:1)
Block(2,5,-2,24:2)
Block(2,5,-1,0)
Block(2,5,0,0)
Block(2,5,1,0)
Block(2,5,2,0)
Block(2,5,3,0)
Block(2,5,4,0)
Block(2,5,5,0)
Block(2,5,6,0)
Block(2,5,7,0)
Block(2,5,8,24:2)
Block(2,6,-1,24:2)
Block(2,6,0,24:2)
Block(2,6,1,24)
Block(2,6,2,0)
Block(2,6,3,0)
Block(2,6,4,0)
Block(2,6,5,24)
Block(2,6,6,24:2)
Block(2,6,7,24:2)
Block(2,7,1,24)
Block(2,7,2,0)
Block(2,7,3,0)
Block(2,7,4,0)
Block(2,7,5,24)
Block(2,8,1,24)
Block(2,8,2,0)
Block(2,8,3,0)
Block(2,8,4,0)
Block(2,8,5,24)
Block(2,9,1,24)
Block(2,9,2,0)
Block(2,9,3,0)
Block(2,9,4,0)
Block(2,9,5,24)
Block(2,10,1,24)
Block(2,10,2,0)
Block(2,10,3,0)
Block(2,10,4,0)
Block(2,10,5,24)
Block(2,11,1,24)
Block(2,11,2,0)
Block(2,11,3,0)
Block(2,11,4,0)
Block(2,11,5,24)
Block(2,12,1,24)
Block(2,12,2,0)
Block(2,12,3,0)
Block(2,12,4,0)
Block(2,12,5,24)
Block(2,13,1,24)
Block(2,13,2,0)
Block(2,13,3,0)
Block(2,13,4,0)
Block(2,13,5,24)
Block(2,14,-7,24)
Block(2,14,-6,24)
Block(2,14,-5,24)
Block(2,14,-4,24)
Block(2,14,-3,24)
Block(2,14,-2,24)
Block(2,14,-1,24)
Block(2,14,0,24)
Block(2,14,1,24)
Block(2,14,2,159:1)
Block(2,14,3,24)
Block(2,14,4,159:1)
Block(2,14,5,24)
Block(2,14,6,24)
Block(2,14,7,24)
Block(2,14,8,24)
Block(2,15,-7,24)
Block(2,15,-6,24)
Block(2,15,-5,0)
Block(2,15,-4,0)
Block(2,15,-3,24:2)
Block(2,15,-2,0)
Block(2,15,-1,0)
Block(2,15,0,0)
Block(2,15,1,0)
Block(2,15,2,0)
Block(2,15,3,0)
Block(2,15,4,0)
Block(2,15,5,0)
Block(2,15,6,0)
Block(2,15,7,0)
Block(2,15,8,0)
Block(2,16,-7,24)
Block(2,16,-6,24)
Block(2,16,-5,24)
Block(2,16,-4,0)
Block(2,16,-3,24:1)
Block(2,16,-2,0)
Block(2,16,-1,0)
Block(2,16,0,0)
Block(2,16,1,0)
Block(2,16,2,0)
Block(2,16,3,0)
Block(2,16,4,0)
Block(2,16,5,0)
Block(2,16,6,0)
Block(2,16,7,0)
Block(2,16,8,0)
Block(2,17,-7,24)
Block(2,17,-6,24)
Block(2,17,-5,24)
Block(2,17,-4,24)
Block(2,17,-3,24)
Block(2,17,-2,0)
Block(2,17,-1,0)
Block(2,17,0,0)
Block(2,17,1,0)
Block(2,17,2,0)
Block(2,17,3,0)
Block(2,17,4,0)
Block(2,17,5,0)
Block(2,17,6,0)
Block(2,17,7,0)
Block(2,17,8,0)
Block(2,18,-7,24)
Block(2,18,-6,24)
Block(2,18,-5,24)
Block(2,18,-4,24)
Block(2,18,-3,24)
Block(2,18,-2,24)
Block(2,18,-1,24)
Block(2,18,0,24)
Block(2,18,1,24)
Block(2,18,2,0)
Block(2,18,3,0)
Block(2,18,4,0)
Block(2,18,5,24)
Block(2,18,6,24)
Block(2,18,7,24)
Block(2,18,8,24)
Block(2,19,-3,24)
Block(2,19,-2,24:2)
Block(2,19,-1,0)
Block(2,19,0,0)
Block(2,19,1,0)
Block(2,19,2,0)
Block(2,19,3,0)
Block(2,19,4,0)
Block(2,19,5,0)
Block(2,19,6,0)
Block(2,19,7,0)
Block(2,19,8,24:2)
Block(2,20,-2,24:2)
Block(2,20,-1,24)
Block(2,20,0,0)
Block(2,20,1,0)
Block(2,20,2,0)
Block(2,20,3,0)
Block(2,20,4,0)
Block(2,20,5,0)
Block(2,20,6,0)
Block(2,20,7,24)
Block(2,20,8,24:2)
Block(2,21,-2,24:2)
Block(2,21,-1,24)
Block(2,21,0,24)
Block(2,21,1,0)
Block(2,21,2,0)
Block(2,21,3,0)
Block(2,21,4,0)
Block(2,21,5,0)
Block(2,21,6,24)
Block(2,21,7,24)
Block(2,21,8,24:2)
Block(2,22,1,24)
Block(2,22,2,0)
Block(2,22,3,0)
Block(2,22,4,0)
Block(2,22,5,24)
Block(2,23,2,24)
Block(2,23,3,24)
Block(2,23,4,24)
Block(3,0,1,24:2)
Block(3,0,2,24:2)
Block(3,0,3,24:2)
Block(3,0,4,24:2)
Block(3,0,5,24:2)
Block(3,1,1,24:2)
Block(3,1,2,24:2)
Block(3,1,3,24:2)
Block(3,1,4,24:2)
Block(3,1,5,24:2)
Block(3,2,-1,159:14)
Block(3,2,0,24:2)
Block(3,2,1,24:2)
Block(3,2,2,24:2)
Block(3,2,3,24:2)
Block(3,2,4,24:2)
Block(3,2,5,24:2)
Block(3,2,6,24:2)
Block(3,2,7,159:14)
Block(3,3,-2,24)
Block(3,3,-1,0)
Block(3,3,0,0)
Block(3,3,1,24:2)
Block(3,3,2,0)
Block(3,3,3,0)
Block(3,3,4,0)
Block(3,3,5,24:2)
Block(3,3,6,0)
Block(3,3,7,0)
Block(3,3,8,24)
Block(3,4,-2,24:2)
Block(3,4,-1,0)
Block(3,4,0,0)
Block(3,4,1,24:2)
Block(3,4,2,0)
Block(3,4,3,0)
Block(3,4,4,0)
Block(3,4,5,24:2)
Block(3,4,6,0)
Block(3,4,7,0)
Block(3,4,8,24:2)
Block(3,5,-2,24:2)
Block(3,5,-1,0)
Block(3,5,0,0)
Block(3,5,1,24:2)
Block(3,5,2,0)
Block(3,5,3,0)
Block(3,5,4,0)
Block(3,5,5,24:2)
Block(3,5,6,0)
Block(3,5,7,0)
Block(3,5,8,24:2)
Block(3,6,-1,24:2)
Block(3,6,0,24:2)
Block(3,6,1,24)
Block(3,6,2,24)
Block(3,6,3,24)
Block(3,6,4,24)
Block(3,6,5,24)
Block(3,6,6,24:2)
Block(3,6,7,24:2)
Block(3,7,2,24)
Block(3,7,3,24)
Block(3,7,4,24)
Block(3,8,2,24)
Block(3,8,3,24)
Block(3,8,4,24)
Block(3,9,2,24)
Block(3,9,3,24)
Block(3,9,4,24)
Block(3,10,2,24)
Block(3,10,3,24)
Block(3,10,4,24)
Block(3,11,2,24)
Block(3,11,3,24)
Block(3,11,4,24)
Block(3,12,2,24)
Block(3,12,3,24)
Block(3,12,4,24)
Block(3,13,2,24)
Block(3,13,3,24)
Block(3,13,4,24)
Block(3,14,-7,24)
Block(3,14,-6,24)
Block(3,14,-5,24)
Block(3,14,-4,24)
Block(3,14,-3,24)
Block(3,14,-2,24)
Block(3,14,-1,24)
Block(3,14,0,24)
Block(3,14,1,24)
Block(3,14,2,24)
Block(3,14,3,159:1)
Block(3,14,4,24)
Block(3,14,5,24)
Block(3,14,6,24)
Block(3,14,7,24)
Block(3,14,8,24)
Block(3,15,-7,24)
Block(3,15,-6,24)
Block(3,15,-5,0)
Block(3,15,-4,0)
Block(3,15,-3,0)
Block(3,15,-2,0)
Block(3,15,-1,0)
Block(3,15,0,0)
Block(3,15,1,24:2)
Block(3,15,2,0)
Block(3,15,3,0)
Block(3,15,4,0)
Block(3,15,5,24:2)
Block(3,15,6,0)
Block(3,15,7,0)
Block(3,15,8,0)
Block(3,16,-7,24)
Block(3,16,-6,24)
Block(3,16,-5,24)
Block(3,16,-4,0)
Block(3,16,-3,0)
Block(3,16,-2,0)
Block(3,16,-1,0)
Block(3,16,0,0)
Block(3,16,1,24:2)
Block(3,16,2,0)
Block(3,16,3,0)
Block(3,16,4,0)
Block(3,16,5,24:2)
Block(3,16,6,0)
Block(3,16,7,0)
Block(3,16,8,0)
Block(3,17,-7,24)
Block(3,17,-6,24)
Block(3,17,-5,24)
Block(3,17,-4,24)
Block(3,17,-3,24)
Block(3,17,-2,0)
Block(3,17,-1,0)
Block(3,17,0,0)
Block(3,17,1,24:2)
Block(3,17,2,0)
Block(3,17,3,0)
Block(3,17,4,0)
Block(3,17,5,24:2)
Block(3,17,6,0)
Block(3,17,7,0)
Block(3,17,8,0)
Block(3,18,-7,24)
Block(3,18,-6,24)
Block(3,18,-5,24)
Block(3,18,-4,24)
Block(3,18,-3,24)
Block(3,18,-2,24)
Block(3,18,-1,24)
Block(3,18,0,24)
Block(3,18,1,24)
Block(3,18,2,24)
Block(3,18,3,24)
Block(3,18,4,24)
Block(3,18,5,24)
Block(3,18,6,24)
Block(3,18,7,24)
Block(3,18,8,24)
Block(3,19,-2,24)
Block(3,19,-1,0)
Block(3,19,0,0)
Block(3,19,1,0)
Block(3,19,2,0)
Block(3,19,3,0)
Block(3,19,4,0)
Block(3,19,5,0)
Block(3,19,6,0)
Block(3,19,7,0)
Block(3,19,8,24)
Block(3,20,-1,24)
Block(3,20,0,0)
Block(3,20,1,0)
Block(3,20,2,0)
Block(3,20,3,0)
Block(3,20,4,0)
Block(3,20,5,0)
Block(3,20,6,0)
Block(3,20,7,24)
Block(3,21,0,24)
Block(3,21,1,0)
Block(3,21,2,0)
Block(3,21,3,0)
Block(3,21,4,0)
Block(3,21,5,0)
Block(3,21,6,24)
Block(3,22,1,24)
Block(3,22,2,24)
Block(3,22,3,24)
Block(3,22,4,24)
Block(3,22,5,24)
Block(4,0,3,24:2)
Block(4,1,3,46)
Block(4,2,-1,159:14)
Block(4,2,0,24:2)
Block(4,2,1,24:2)
Block(4,2,2,24:2)
Block(4,2,3,24:2)
Block(4,2,4,24:2)
Block(4,2,5,24:2)
Block(4,2,6,24:2)
Block(4,2,7,159:14)
Block(4,3,-2,24)
Block(4,3,-1,0)
Block(4,3,0,0)
Block(4,3,1,0)
Block(4,3,2,0)
Block(4,3,3,0)
Block(4,3,4,0)
Block(4,3,5,0)
Block(4,3,6,0)
Block(4,3,7,0)
Block(4,3,8,24)
Block(4,4,-2,24:2)
Block(4,4,-1,0)
Block(4,4,0,0)
Block(4,4,1,0)
Block(4,4,2,0)
Block(4,4,3,0)
Block(4,4,4,0)
Block(4,4,5,0)
Block(4,4,6,0)
Block(4,4,7,0)
Block(4,4,8,24:2)
Block(4,5,-2,24:2)
Block(4,5,-1,0)
Block(4,5,0,0)
Block(4,5,1,0)
Block(4,5,2,0)
Block(4,5,3,0)
Block(4,5,4,0)
Block(4,5,5,0)
Block(4,5,6,0)
Block(4,5,7,0)
Block(4,5,8,24:2)
Block(4,6,-1,24:2)
Block(4,6,0,24:2)
Block(4,6,1,24:2)
Block(4,6,2,24:2)
Block(4,6,3,24:2)
Block(4,6,4,24:2)
Block(4,6,5,24:2)
Block(4,6,6,24:2)
Block(4,6,7,24:2)
Block(4,14,-7,24)
Block(4,14,-6,24)
Block(4,14,-5,24)
Block(4,14,-4,24)
Block(4,14,-3,24)
Block(4,14,-2,24)
Block(4,14,-1,24)
Block(4,14,0,24)
Block(4,14,1,24)
Block(4,14,2,24)
Block(4,14,3,159:1)
Block(4,14,4,24)
Block(4,14,5,24)
Block(4,14,6,24)
Block(4,14,7,24)
Block(4,14,8,24)
Block(4,15,-7,24)
Block(4,15,-6,24)
Block(4,15,-5,0)
Block(4,15,-4,0)
Block(4,15,-3,24:2)
Block(4,15,-2,0)
Block(4,15,-1,0)
Block(4,15,0,0)
Block(4,15,1,0)
Block(4,15,2,0)
Block(4,15,3,0)
Block(4,15,4,0)
Block(4,15,5,0)
Block(4,15,6,0)
Block(4,15,7,0)
Block(4,15,8,0)
Block(4,16,-7,24)
Block(4,16,-6,24)
Block(4,16,-5,24)
Block(4,16,-4,0)
Block(4,16,-3,24:1)
Block(4,16,-2,0)
Block(4,16,-1,0)
Block(4,16,0,0)
Block(4,16,1,0)
Block(4,16,2,0)
Block(4,16,3,0)
Block(4,16,4,0)
Block(4,16,5,0)
Block(4,16,6,0)
Block(4,16,7,0)
Block(4,16,8,0)
Block(4,17,-7,24)
Block(4,17,-6,24)
Block(4,17,-5,24)
Block(4,17,-4,24)
Block(4,17,-3,24)
Block(4,17,-2,0)
Block(4,17,-1,0)
Block(4,17,0,0)
Block(4,17,1,0)
Block(4,17,2,0)
Block(4,17,3,0)
Block(4,17,4,0)
Block(4,17,5,0)
Block(4,17,6,0)
Block(4,17,7,0)
Block(4,17,8,0)
Block(4,18,-7,24)
Block(4,18,-6,24)
Block(4,18,-5,24)
Block(4,18,-4,24)
Block(4,18,-3,24)
Block(4,18,-2,24)
Block(4,18,-1,24)
Block(4,18,0,24)
Block(4,18,1,24)
Block(4,18,2,24)
Block(4,18,3,24)
Block(4,18,4,24)
Block(4,18,5,24)
Block(4,18,6,24)
Block(4,18,7,24)
Block(4,18,8,24)
Block(4,19,-2,24)
Block(4,19,-1,0)
Block(4,19,0,0)
Block(4,19,1,0)
Block(4,19,2,0)
Block(4,19,3,0)
Block(4,19,4,0)
Block(4,19,5,0)
Block(4,19,6,0)
Block(4,19,7,0)
Block(4,19,8,24)
Block(4,20,-1,24)
Block(4,20,0,0)
Block(4,20,1,0)
Block(4,20,2,0)
Block(4,20,3,0)
Block(4,20,4,0)
Block(4,20,5,0)
Block(4,20,6,0)
Block(4,20,7,24)
Block(4,21,0,24)
Block(4,21,1,24)
Block(4,21,2,24)
Block(4,21,3,24)
Block(4,21,4,24)
Block(4,21,5,24)
Block(4,21,6,24)
Block(5,1,3,24)
Block(5,2,-1,159:14)
Block(5,2,0,159:14)
Block(5,2,1,159:14)
Block(5,2,2,159:14)
Block(5,2,3,46)
Block(5,2,4,159:14)
Block(5,2,5,159:14)
Block(5,2,6,159:14)
Block(5,2,7,159:14)
Block(5,3,-2,24)
Block(5,3,-1,0)
Block(5,3,0,0)
Block(5,3,1,0)
Block(5,3,2,0)
Block(5,3,3,146:4,../../nbt/chestDesert.nbt,100)
Block(5,3,4,0)
Block(5,3,5,0)
Block(5,3,6,0)
Block(5,3,7,0)
Block(5,3,8,24)
Block(5,4,-2,24:2)
Block(5,4,-1,0)
Block(5,4,0,0)
Block(5,4,1,0)
Block(5,4,2,0)
Block(5,4,3,0)
Block(5,4,4,0)
Block(5,4,5,0)
Block(5,4,6,0)
Block(5,4,7,0)
Block(5,4,8,24:2)
Block(5,5,-2,24:2)
Block(5,5,-1,0)
Block(5,5,0,0)
Block(5,5,1,0)
Block(5,5,2,0)
Block(5,5,3,0)
Block(5,5,4,0)
Block(5,5,5,0)
Block(5,5,6,0)
Block(5,5,7,0)
Block(5,5,8,24:2)
Block(5,6,-1,24:2)
Block(5,6,0,24:2)
Block(5,6,1,24:2)
Block(5,6,2,24:2)
Block(5,6,3,24:2)
Block(5,6,4,24:2)
Block(5,6,5,24:2)
Block(5,6,6,24:2)
Block(5,6,7,24:2)
Block(5,14,-7,24)
Block(5,14,-6,24)
Block(5,14,-5,24)
Block(5,14,-4,24)
Block(5,14,-3,24)
Block(5,14,-2,24)
Block(5,14,-1,24)
Block(5,14,0,24)
Block(5,14,1,24)
Block(5,14,2,24)
Block(5,14,3,24)
Block(5,14,4,24)
Block(5,14,5,24)
Block(5,14,6,24)
Block(5,14,7,24)
Block(5,14,8,24)
Block(5,15,-7,24)
Block(5,15,-6,24)
Block(5,15,-5,0)
Block(5,15,-4,0)
Block(5,15,-3,0)
Block(5,15,-2,0)
Block(5,15,-1,0)
Block(5,15,0,0)
Block(5,15,1,0)
Block(5,15,2,0)
Block(5,15,3,0)
Block(5,15,4,0)
Block(5,15,5,0)
Block(5,15,6,0)
Block(5,15,7,0)
Block(5,15,8,0)
Block(5,16,-7,24)
Block(5,16,-6,24)
Block(5,16,-5,24)
Block(5,16,-4,0)
Block(5,16,-3,0)
Block(5,16,-2,0)
Block(5,16,-1,0)
Block(5,16,0,0)
Block(5,16,1,0)
Block(5,16,2,0)
Block(5,16,3,0)
Block(5,16,4,0)
Block(5,16,5,0)
Block(5,16,6,0)
Block(5,16,7,0)
Block(5,16,8,0)
Block(5,17,-7,24)
Block(5,17,-6,24)
Block(5,17,-5,24)
Block(5,17,-4,24)
Block(5,17,-3,24)
Block(5,17,-2,0)
Block(5,17,-1,0)
Block(5,17,0,0)
Block(5,17,1,0)
Block(5,17,2,0)
Block(5,17,3,0)
Block(5,17,4,0)
Block(5,17,5,0)
Block(5,17,6,0)
Block(5,17,7,0)
Block(5,17,8,0)
Block(5,18,-7,24)
Block(5,18,-6,24)
Block(5,18,-5,24)
Block(5,18,-4,24)
Block(5,18,-3,24)
Block(5,18,-2,24)
Block(5,18,-1,24)
Block(5,18,0,24)
Block(5,18,1,24)
Block(5,18,2,24)
Block(5,18,3,24)
Block(5,18,4,24)
Block(5,18,5,24)
Block(5,18,6,24)
Block(5,18,7,24)
Block(5,18,8,24)
Block(5,19,-2,24)
Block(5,19,-1,0)
Block(5,19,0,0)
Block(5,19,1,0)
Block(5,19,2,0)
Block(5,19,3,0)
Block(5,19,4,0)
Block(5,19,5,0)
Block(5,19,6,0)
Block(5,19,7,0)
Block(5,19,8,24)
Block(5,20,-1,24)
Block(5,20,0,24)
Block(5,20,1,24)
Block(5,20,2,24)
Block(5,20,3,24)
Block(5,20,4,24)
Block(5,20,5,24)
Block(5,20,6,24)
Block(5,20,7,24)
Block(6,3,-1,24)
Block(6,3,0,24)
Block(6,3,1,24)
Block(6,3,2,24)
Block(6,3,3,24)
Block(6,3,4,24)
Block(6,3,5,24)
Block(6,3,6,24)
Block(6,3,7,24)
Block(6,4,-1,24:2)
Block(6,4,0,24:2)
Block(6,4,1,24:2)
Block(6,4,2,24:1)
Block(6,4,3,24:1)
Block(6,4,4,24:1)
Block(6,4,5,24:2)
Block(6,4,6,24:2)
Block(6,4,7,24:2)
Block(6,5,-1,24:2)
Block(6,5,0,24:2)
Block(6,5,1,24:2)
Block(6,5,2,24:2)
Block(6,5,3,24:2)
Block(6,5,4,24:2)
Block(6,5,5,24:2)
Block(6,5,6,24:2)
Block(6,5,7,24:2)
Block(6,14,-7,24)
Block(6,14,-6,24)
Block(6,14,-5,24)
Block(6,14,-4,24)
Block(6,14,-3,24)
Block(6,14,-2,24)
Block(6,14,-1,24)
Block(6,14,0,24)
Block(6,14,1,24)
Block(6,14,2,24)
Block(6,14,3,24)
Block(6,14,4,24)
Block(6,14,5,24)
Block(6,14,6,24)
Block(6,14,7,24)
Block(6,14,8,24)
Block(6,15,-7,24)
Block(6,15,-6,24)
Block(6,15,-5,0)
Block(6,15,-4,0)
Block(6,15,-3,24:2)
Block(6,15,-2,0)
Block(6,15,-1,0)
Block(6,15,0,0)
Block(6,15,1,0)
Block(6,15,2,0)
Block(6,15,3,0)
Block(6,15,4,0)
Block(6,15,5,0)
Block(6,15,6,0)
Block(6,15,7,0)
Block(6,15,8,0)
Block(6,16,-7,24)
Block(6,16,-6,24)
Block(6,16,-5,24)
Block(6,16,-4,0)
Block(6,16,-3,24:1)
Block(6,16,-2,0)
Block(6,16,-1,0)
Block(6,16,0,0)
Block(6,16,1,0)
Block(6,16,2,0)
Block(6,16,3,0)
Block(6,16,4,0)
Block(6,16,5,0)
Block(6,16,6,0)
Block(6,16,7,0)
Block(6,16,8,0)
Block(6,17,-7,24)
Block(6,17,-6,24)
Block(6,17,-5,24)
Block(6,17,-4,24)
Block(6,17,-3,24)
Block(6,17,-2,0)
Block(6,17,-1,0)
Block(6,17,0,0)
Block(6,17,1,0)
Block(6,17,2,0)
Block(6,17,3,0)
Block(6,17,4,0)
Block(6,17,5,0)
Block(6,17,6,0)
Block(6,17,7,0)
Block(6,17,8,0)
Block(6,18,-7,24)
Block(6,18,-6,24)
Block(6,18,-5,128:1)
Block(6,18,-4,24)
Block(6,18,-3,24)
Block(6,18,-2,24)
Block(6,18,-1,24)
Block(6,18,0,24)
Block(6,18,1,24)
Block(6,18,2,24)
Block(6,18,3,24)
Block(6,18,4,24)
Block(6,18,5,24)
Block(6,18,6,24)
Block(6,18,7,24)
Block(6,18,8,24)
Block(6,19,-2,24)
Block(6,19,-1,24)
Block(6,19,0,24)
Block(6,19,1,24)
Block(6,19,2,24)
Block(6,19,3,24)
Block(6,19,4,24)
Block(6,19,5,24)
Block(6,19,6,24)
Block(6,19,7,24)
Block(6,19,8,24)
Block(7,14,-7,24)
Block(7,14,-6,24)
Block(7,14,-5,24)
Block(7,14,-4,24)
Block(7,14,-3,24)
Block(7,14,-2,24)
Block(7,14,-1,24)
Block(7,14,0,24)
Block(7,14,1,24)
Block(7,14,2,24)
Block(7,14,3,24)
Block(7,14,4,24)
Block(7,14,5,24)
Block(7,14,6,24)
Block(7,14,7,24)
Block(7,14,8,24)
Block(7,15,-7,24)
Block(7,15,-6,24)
Block(7,15,-5,24)
Block(7,15,-4,24)
Block(7,15,-3,24)
Block(7,15,-2,0)
Block(7,15,-1,0)
Block(7,15,0,0)
Block(7,15,1,24)
Block(7,15,2,0)
Block(7,15,3,0)
Block(7,15,4,0)
Block(7,15,5,24)
Block(7,15,6,0)
Block(7,15,7,0)
Block(7,15,8,0)
Block(7,16,-7,24)
Block(7,16,-6,24)
Block(7,16,-5,24)
Block(7,16,-4,24)
Block(7,16,-3,24)
Block(7,16,-2,0)
Block(7,16,-1,0)
Block(7,16,0,0)
Block(7,16,1,24)
Block(7,16,2,0)
Block(7,16,3,0)
Block(7,16,4,0)
Block(7,16,5,24)
Block(7,16,6,0)
Block(7,16,7,0)
Block(7,16,8,0)
Block(7,17,-7,24)
Block(7,17,-6,24)
Block(7,17,-5,128:1)
Block(7,17,-4,24)
Block(7,17,-3,24)
Block(7,17,-2,0)
Block(7,17,-1,0)
Block(7,17,0,0)
Block(7,17,1,24)
Block(7,17,2,0)
Block(7,17,3,0)
Block(7,17,4,0)
Block(7,17,5,24)
Block(7,17,6,0)
Block(7,17,7,0)
Block(7,17,8,0)
Block(7,18,-7,24)
Block(7,18,-6,24)
Block(7,18,-5,0)
Block(7,18,-4,24)
Block(7,18,-3,24)
Block(7,18,-2,24)
Block(7,18,-1,24)
Block(7,18,0,24)
Block(7,18,1,24)
Block(7,18,2,24)
Block(7,18,3,24)
Block(7,18,4,24)
Block(7,18,5,24)
Block(7,18,6,24)
Block(7,18,7,24)
Block(7,18,8,24)
Block(7,19,-7,24)
Block(7,19,-6,24)
Block(7,19,-5,0)
Block(7,19,-4,24)
Block(7,19,-3,24)
Block(7,20,-7,24)
Block(7,20,-6,24)
Block(7,20,-5,0)
Block(7,20,-4,24)
Block(7,20,-3,24)
Block(7,21,-7,24)
Block(7,21,-6,24)
Block(7,21,-5,24)
Block(7,21,-4,24)
Block(7,21,-3,24)
Block(7,22,-7,24)
Block(7,22,-6,24)
Block(7,22,-5,24)
Block(7,22,-4,24)
Block(7,22,-3,24)
Block(7,23,-7,24)
Block(7,23,-6,24)
Block(7,23,-5,24)
Block(7,23,-4,24)
Block(7,23,-3,24)
Block(7,24,-5,128)


#######################################################################
# +-----------------------------------------------------------------+ #
# |                             Entities                            | #
# +-----------------------------------------------------------------+ #
#######################################################################

# Entity() spawns an entity instead of a block. The entity is spawned only once when the BO3 is spawned.
# Entities are persistent by default so they don't de-spawn when no player is near, they are only unloaded.
# Usage: Entity(x,y,z,mobName,groupSize,NameTagOrNBTFileName) or Entity(x,y,z,mobName,groupSize)
# Use /tc entities or /otg entities to get a list of entities that can be used as mobName, this includes entities added by other mods.
# NameTagOrNBTFileName can be either a nametag for the mob or an nbt file (such as mymobinfo.nbt or mymobinfo.txt).
# When using a text file you can use the same mob spawning parameters used with the /summon command to equip the
# entity and give it custom attributes etc. You can copy the DATA part of a summon command including surrounding
# curly braces to a .txt file, for instance for: "/summon Skeleton x y z {DATA}"

#######################################################################
# +-----------------------------------------------------------------+ #
# |                            BO3 checks                           | #
# +-----------------------------------------------------------------+ #
#######################################################################

# Require a condition at a certain location in order for the BO3 to be spawned.
# BlockCheck(x,y,z,BlockName[,BlockName[,...]]) - one of the blocks must be at the location
# BlockCheckNot(x,y,z,BlockName[,BlockName[,...]]) - all the blocks must not be at the location
# LightCheck(x,y,z,minLightLevel,maxLightLevel) - light must be between min and max (inclusive)

# You can use "Solid" as a BlockName for matching all solid blocks or "All" to match all blocks that aren't air.

# Examples:
#   BlockCheck(0,-1,0,GRASS,DIRT)  Require grass or dirt just below the object
#   BlockCheck(0,-1,0,Solid)       Require any solid block just below the object
#   BlockCheck(0,-1,0,WOOL)        Require any type of wool just below the object
#   BlockCheck(0,-1,0,WOOL:0)      Require white wool just below the object
#   BlockCheckNot(0,-1,0,WOOL:0)   Require that there is no white wool below the object
#   LightCheck(0,0,0,0,1)          Require almost complete darkness just below the object

#######################################################################
# +-----------------------------------------------------------------+ #
# |                             Branches                            | #
# +-----------------------------------------------------------------+ #
#######################################################################

# Branches are objects that will spawn when this object spawns when it is used in
# the CustomStructure resource. Branches can also have branches, making complex
# structures possible. See the wiki for more details.

# Regular Branches spawn each branch with an independent chance of spawning.
# Branch(x,y,z,branchName,rotation,chance[,anotherBranchName,rotation,chance[,...]][IndividualChance])
# branchName - name of the object to spawn.
# rotation - NORTH, SOUTH, EAST or WEST.
# IndividualChance - The chance each branch has to spawn, assumed to be 100 when left blank

# WeightedBranch(x,y,z,branchName,rotation,chance[,anotherBranchName,rotation,chance[,...]][MaxChanceOutOf])
# MaxChanceOutOf - The chance all branches have to spawn out of, assumed to be 100 when left blank
Branch(16,0,0,StructureTempleC1R0,NORTH,100)
Branch(0,0,16,StructureTempleC0R1,NORTH,100)
