#######################################################################
# +-----------------------------------------------------------------+ #
# |                            BO3 object                           | #
# +-----------------------------------------------------------------+ #
#######################################################################

# The descriptions in this file are accurate only for TerrainControl and OTG.
# For MCW and OTG+ these descriptions are only accurate if the BO3 is used as a CustomObject.
# MCW and OTG+ completely reimplemented CustomStructure, check the MCW/OTG+ documentation for more information.

# This is the config file of a custom object.
# If you add this object correctly to your BiomeConfigs, it will spawn in the world.

# This is the creator of this BO3 object
Author: DedMaxim99

# A short description of this BO3 object
Description: This BO3 was converted from a schematic using OTGEdit. The author and description information of the schematic could not be found. If you know who the author of the schematic is then please add this information.

# The BO3 version, don't change this! It can be used by external applications to do a version check.
Version: 3

# The settings mode, WriteAll, WriteWithoutComments or WriteDisable. See WorldConfig.
SettingsMode: WriteDisable

#######################################################################
# +-----------------------------------------------------------------+ #
# |                          Main settings                          | #
# +-----------------------------------------------------------------+ #
#######################################################################

# This needs to be set to true to spawn the object in the Tree and Sapling resources.
Tree: false

# The frequency of the BO3 from 1 to 200. Tries this many times to spawn this BO3 when using the CustomObject(...) resource.
# Ignored by Tree(..), Sapling(..) and CustomStructure(..)
Frequency: 40

# The rarity of the BO3 from 0 to 100. Each spawn attempt has rarity% chance to succeed when using the CustomObject(...) resource.
# Ignored by Tree(..), Sapling(..) and CustomStructure(..)
Rarity: 100.0

# If you set this to true, the BO3 will be placed with a random rotation.
RotateRandomly: false

# The spawn height of the BO3 - randomY, highestBlock or highestSolidBlock.
SpawnHeight: randomY

# The height limits for the BO3.
MinHeight: 0

MaxHeight: 80

# Objects can have other objects attached to it: branches. Branches can also
# have branches attached to it, which can also have branches, etc. This is the
# maximum branch depth for this objects.
MaxBranchDepth: 20

# When spawned with the UseWorld keyword, this BO3 should NOT spawn in the following biomes.
# If you writer.write the BO3 name directly in the BiomeConfigs, this will be ignored.
ExcludedBiomes: All

# To optimise this BO3 for faster loading times you can use Notepad++ to find/replace comments and abbreviate things.
# Notepad++ find/replace with regex:
# Find: ^[#;].* replace to nothing removes all lines starting with # 
# Find: ^\s*$ replace to nothing removes most empty lines 
# Notepad++ find/replace without regex:
# *Warning: This will only work for OTG 1.10.2 v21 / OTG 1.11.2 v6 or higher. B( is not recognised by lower versions.
# Find: Block( replace to B(

#######################################################################
# +-----------------------------------------------------------------+ #
# |                      Source block settings                      | #
# +-----------------------------------------------------------------+ #
#######################################################################

# The block(s) the BO3 should spawn in.
SourceBlocks: AIR

# The maximum percentage of the BO3 that can be outside the SourceBlock.
# The BO3 won't be placed on a location with more blocks outside the SourceBlock than this percentage.
MaxPercentageOutsideSourceBlock: 100

# What to do when a block is about to be placed outside the SourceBlock? (dontPlace, placeAnyway)
OutsideSourceBlock: placeAnyway

#######################################################################
# +-----------------------------------------------------------------+ #
# |                              Blocks                             | #
# +-----------------------------------------------------------------+ #
#######################################################################

# All the blocks used in the BO3 are listed here. Possible blocks:
# Block(x,y,z,id[.data][,nbtfile.nbt) or B(x,y,z,id[.data][,nbtfile.nbt)
# RandomBlock(x,y,z,id[:data][,nbtfile.nbt],chance[,id[:data][,nbtfile.nbt],chance[,...]])
# So RandomBlock(0,0,0,CHEST,chest.nbt,50,CHEST,anotherchest.nbt,100) will spawn a chest at
# the BO3 origin, and give it a 50% chance to have the contents of chest.nbt, or, if that
# fails, a 100% percent chance to have the contents of anotherchest.nbt.

Block(-8,2,-3,0)
Block(-8,2,-2,0)
Block(-8,3,-6,0)
Block(-8,3,-5,0)
Block(-8,3,-4,0)
Block(-8,3,-3,0)
Block(-8,3,-2,0)
Block(-8,3,-1,0)
Block(-8,3,4,0)
Block(-8,4,-7,97:2)
Block(-8,4,-6,97:2)
Block(-8,4,-5,97:2)
Block(-8,4,-4,97:2)
Block(-8,4,-3,97:2)
Block(-8,4,-2,97:2)
Block(-8,4,-1,97:2)
Block(-8,4,0,97:2)
Block(-8,4,1,97:2)
Block(-8,4,2,98:1)
Block(-8,4,3,97:2)
Block(-8,4,4,98:1)
Block(-8,4,5,98:1)
Block(-8,4,6,97:2)
Block(-8,4,7,97:2)
Block(-8,5,-7,97:2)
Block(-8,5,-6,97:2)
Block(-8,5,-5,97:2)
Block(-8,5,-4,97:2)
Block(-8,5,-3,97:2)
Block(-8,5,-2,97:2)
Block(-8,5,-1,98:1)
Block(-8,5,0,97:2)
Block(-8,5,1,97:2)
Block(-8,5,2,97:2)
Block(-8,5,3,97:2)
Block(-8,5,4,98:2)
Block(-8,5,5,97:2)
Block(-8,5,6,97:2)
Block(-8,5,7,98:1)
Block(-8,6,-7,97:2)
Block(-8,6,-6,0)
Block(-8,6,-5,0)
Block(-8,6,-4,0)
Block(-8,6,-3,97:2)
Block(-8,6,-2,0)
Block(-8,6,-1,0)
Block(-8,6,0,0)
Block(-8,6,1,0)
Block(-8,6,2,97:2)
Block(-8,6,3,0)
Block(-8,6,4,0)
Block(-8,6,5,0)
Block(-8,6,6,97:2)
Block(-8,6,7,97:2)
Block(-8,7,-7,97:2)
Block(-8,7,-6,0)
Block(-8,7,-5,0)
Block(-8,7,-4,0)
Block(-8,7,-3,97:2)
Block(-8,7,-2,0)
Block(-8,7,-1,0)
Block(-8,7,0,0)
Block(-8,7,1,0)
Block(-8,7,2,97:2)
Block(-8,7,3,0)
Block(-8,7,4,0)
Block(-8,7,5,0)
Block(-8,7,6,97:2)
Block(-8,7,7,98:1)
Block(-8,8,-7,97:2)
Block(-8,8,-6,97:2)
Block(-8,8,-5,98:2)
Block(-8,8,-4,97:2)
Block(-8,8,-3,98:2)
Block(-8,8,-2,98:2)
Block(-8,8,-1,98:1)
Block(-8,8,0,97:2)
Block(-8,8,1,97:2)
Block(-8,8,2,98:1)
Block(-8,8,3,97:2)
Block(-8,8,4,97:2)
Block(-8,8,5,97:2)
Block(-8,8,6,97:2)
Block(-8,8,7,97:2)
Block(-8,8,8,0)
Block(-8,9,-7,0)
Block(-8,9,-6,98:2)
Block(-8,9,-5,131:7)
Block(-8,9,-4,98:2)
Block(-8,9,-3,131:7)
Block(-8,9,-2,97:2)
Block(-8,9,-1,97:2)
Block(-8,9,0,97:2)
Block(-8,9,1,98:2)
Block(-8,9,2,0)
Block(-8,9,3,0)
Block(-8,9,4,0)
Block(-8,9,5,0)
Block(-8,9,6,97:2)
Block(-8,9,7,97:2)
Block(-8,9,8,0)
Block(-8,10,-7,0)
Block(-8,10,-6,97:2)
Block(-8,10,-5,0)
Block(-8,10,-4,98:1)
Block(-8,10,-3,0)
Block(-8,10,-2,97:2)
Block(-8,10,-1,98:2)
Block(-8,10,0,98:1)
Block(-8,10,1,97:2)
Block(-8,10,2,0)
Block(-8,10,3,0)
Block(-8,10,4,0)
Block(-8,10,5,0)
Block(-8,10,6,98:2)
Block(-8,10,7,97:2)
Block(-8,10,8,0)
Block(-8,11,-7,97:2)
Block(-8,11,-6,97:2)
Block(-8,11,-5,98:2)
Block(-8,11,-4,46)
Block(-8,11,-3,97:2)
Block(-8,11,-2,97:2)
Block(-8,11,-1,98:2)
Block(-8,11,0,97:2)
Block(-8,11,1,97:2)
Block(-8,11,2,97:2)
Block(-8,11,3,97:2)
Block(-8,11,4,97:2)
Block(-8,11,5,97:2)
Block(-8,11,6,97:2)
Block(-8,11,7,97:2)
Block(-8,12,-7,97:2)
Block(-8,12,-6,97:2)
Block(-8,12,-5,97:2)
Block(-8,12,-4,98:2)
Block(-8,12,-3,97:2)
Block(-8,12,-2,97:2)
Block(-8,12,-1,98:1)
Block(-8,12,0,97:2)
Block(-8,12,1,98:2)
Block(-8,12,2,98:2)
Block(-8,12,3,98:1)
Block(-8,12,4,97:2)
Block(-8,12,5,0)
Block(-8,12,6,97:2)
Block(-8,12,7,97:2)
Block(-8,13,-7,98:1)
Block(-8,13,-6,98:1)
Block(-8,13,-5,97:2)
Block(-8,13,-4,97:2)
Block(-8,13,-3,98:1)
Block(-8,13,-2,98:1)
Block(-8,13,-1,97:2)
Block(-8,13,0,97:2)
Block(-8,13,1,97:2)
Block(-8,13,2,98:1)
Block(-8,13,3,97:2)
Block(-8,13,4,98:1)
Block(-8,13,5,0)
Block(-8,13,6,97:2)
Block(-8,13,7,98:1)
Block(-8,14,-7,97:2)
Block(-8,14,-6,97:2)
Block(-8,14,-5,97:2)
Block(-8,14,-4,98:2)
Block(-8,14,-3,97:2)
Block(-8,14,-2,98:1)
Block(-8,14,-1,97:2)
Block(-8,14,0,97:2)
Block(-8,14,1,98:2)
Block(-8,14,2,97:2)
Block(-8,14,3,98:1)
Block(-8,14,4,97:2)
Block(-8,14,5,97:2)
Block(-8,14,6,98:2)
Block(-8,14,7,98:2)
Block(-8,15,-7,97:2)
Block(-8,15,-6,98:2)
Block(-8,15,-5,97:2)
Block(-8,15,-4,97:2)
Block(-8,15,-3,97:2)
Block(-8,15,-2,97:2)
Block(-8,15,-1,97:2)
Block(-8,15,0,98:1)
Block(-8,15,1,98:2)
Block(-8,15,2,98:1)
Block(-8,15,3,98:1)
Block(-8,15,4,97:2)
Block(-8,15,5,97:2)
Block(-8,15,6,97:2)
Block(-8,15,7,97:2)
Block(-7,2,-5,0)
Block(-7,2,-4,0)
Block(-7,2,-3,0)
Block(-7,2,-2,0)
Block(-7,3,-7,0)
Block(-7,3,-6,0)
Block(-7,3,-5,0)
Block(-7,3,-4,0)
Block(-7,3,-3,0)
Block(-7,3,-2,0)
Block(-7,3,-1,0)
Block(-7,3,0,0)
Block(-7,4,-7,97:2)
Block(-7,4,-6,97:2)
Block(-7,4,-5,98:1)
Block(-7,4,-4,97:2)
Block(-7,4,-3,97:2)
Block(-7,4,-2,97:2)
Block(-7,4,-1,98:2)
Block(-7,4,0,98:1)
Block(-7,4,1,98:2)
Block(-7,4,2,98:2)
Block(-7,4,3,97:2)
Block(-7,4,4,98:1)
Block(-7,4,5,97:2)
Block(-7,4,6,97:2)
Block(-7,4,7,97:2)
Block(-7,5,-7,97:2)
Block(-7,5,-6,97:2)
Block(-7,5,-5,98:2)
Block(-7,5,-4,98:1)
Block(-7,5,-3,97:2)
Block(-7,5,-2,97:2)
Block(-7,5,-1,97:2)
Block(-7,5,0,97:2)
Block(-7,5,1,97:2)
Block(-7,5,2,97:2)
Block(-7,5,3,98:1)
Block(-7,5,4,97:2)
Block(-7,5,5,97:2)
Block(-7,5,6,97:2)
Block(-7,5,7,97:2)
Block(-7,6,-7,98:2)
Block(-7,6,-6,0)
Block(-7,6,-5,97:2)
Block(-7,6,-4,0)
Block(-7,6,-3,97:2)
Block(-7,6,-2,97:2)
Block(-7,6,-1,97:2)
Block(-7,6,0,97:2)
Block(-7,6,1,97:2)
Block(-7,6,2,97:2)
Block(-7,6,3,0)
Block(-7,6,4,97:2)
Block(-7,6,5,97:2)
Block(-7,6,6,98:1)
Block(-7,6,7,98:1)
Block(-7,7,-7,97:2)
Block(-7,7,-6,0)
Block(-7,7,-5,97:2)
Block(-7,7,-4,0)
Block(-7,7,-3,97:2)
Block(-7,7,-2,98:1)
Block(-7,7,-1,97:2)
Block(-7,7,0,97:2)
Block(-7,7,1,97:2)
Block(-7,7,2,97:2)
Block(-7,7,3,0)
Block(-7,7,4,98:2)
Block(-7,7,5,97:2)
Block(-7,7,6,97:2)
Block(-7,7,7,98:1)
Block(-7,8,-7,97:2)
Block(-7,8,-6,97:2)
Block(-7,8,-5,97:2)
Block(-7,8,-4,97:2)
Block(-7,8,-3,97:2)
Block(-7,8,-2,98:1)
Block(-7,8,-1,97:2)
Block(-7,8,0,97:2)
Block(-7,8,1,97:2)
Block(-7,8,2,97:2)
Block(-7,8,3,98:1)
Block(-7,8,4,97:2)
Block(-7,8,5,97:2)
Block(-7,8,6,97:2)
Block(-7,8,7,98:2)
Block(-7,9,-7,98:1)
Block(-7,9,-6,98:1)
Block(-7,9,-5,132:4)
Block(-7,9,-4,0)
Block(-7,9,-3,132:4)
Block(-7,9,-2,97:2)
Block(-7,9,-1,97:2)
Block(-7,9,0,97:2)
Block(-7,9,1,98:2)
Block(-7,9,2,98:1)
Block(-7,9,3,97:2)
Block(-7,9,4,97:2)
Block(-7,9,5,97:2)
Block(-7,9,6,97:2)
Block(-7,9,7,97:2)
Block(-7,10,-7,97:2)
Block(-7,10,-6,97:2)
Block(-7,10,-5,0)
Block(-7,10,-4,76:1)
Block(-7,10,-3,0)
Block(-7,10,-2,97:2)
Block(-7,10,-1,97:2)
Block(-7,10,0,97:2)
Block(-7,10,1,97:2)
Block(-7,10,2,97:2)
Block(-7,10,3,98:1)
Block(-7,10,4,98:2)
Block(-7,10,5,98:2)
Block(-7,10,6,97:2)
Block(-7,10,7,97:2)
Block(-7,11,-7,97:2)
Block(-7,11,-6,97:2)
Block(-7,11,-5,97:2)
Block(-7,11,-4,98:2)
Block(-7,11,-3,97:2)
Block(-7,11,-2,97:2)
Block(-7,11,-1,97:2)
Block(-7,11,0,97:2)
Block(-7,11,1,97:2)
Block(-7,11,2,98:1)
Block(-7,11,3,97:2)
Block(-7,11,4,98:1)
Block(-7,11,5,97:2)
Block(-7,11,6,97:2)
Block(-7,11,7,97:2)
Block(-7,12,-7,0)
Block(-7,12,-6,0)
Block(-7,12,-5,0)
Block(-7,12,-4,0)
Block(-7,12,-3,0)
Block(-7,12,-2,0)
Block(-7,12,-1,0)
Block(-7,12,0,0)
Block(-7,12,1,0)
Block(-7,12,2,0)
Block(-7,12,3,0)
Block(-7,12,4,0)
Block(-7,12,5,0)
Block(-7,12,6,97:2)
Block(-7,12,7,97:2)
Block(-7,13,-7,0)
Block(-7,13,-6,0)
Block(-7,13,-5,0)
Block(-7,13,-4,0)
Block(-7,13,-3,0)
Block(-7,13,-2,0)
Block(-7,13,-1,0)
Block(-7,13,0,0)
Block(-7,13,1,0)
Block(-7,13,2,0)
Block(-7,13,3,0)
Block(-7,13,4,0)
Block(-7,13,5,0)
Block(-7,13,6,97:2)
Block(-7,13,7,98:2)
Block(-7,14,-7,97:2)
Block(-7,14,-6,98:1)
Block(-7,14,-5,97:2)
Block(-7,14,-4,98:2)
Block(-7,14,-3,97:2)
Block(-7,14,-2,97:2)
Block(-7,14,-1,97:2)
Block(-7,14,0,97:2)
Block(-7,14,1,97:2)
Block(-7,14,2,98:2)
Block(-7,14,3,97:2)
Block(-7,14,4,97:2)
Block(-7,14,5,97:2)
Block(-7,14,6,98:2)
Block(-7,14,7,97:2)
Block(-7,15,-7,97:2)
Block(-7,15,-6,98:1)
Block(-7,15,-5,98:2)
Block(-7,15,-4,98:2)
Block(-7,15,-3,97:2)
Block(-7,15,-2,97:2)
Block(-7,15,-1,98:2)
Block(-7,15,0,98:2)
Block(-7,15,1,98:1)
Block(-7,15,2,97:2)
Block(-7,15,3,98:2)
Block(-7,15,4,97:2)
Block(-7,15,5,97:2)
Block(-7,15,6,97:2)
Block(-7,15,7,97:2)
Block(-6,1,-5,0)
Block(-6,1,-4,0)
Block(-6,1,-3,0)
Block(-6,2,-7,0)
Block(-6,2,-6,0)
Block(-6,2,-5,0)
Block(-6,2,-4,0)
Block(-6,2,-3,0)
Block(-6,2,-2,0)
Block(-6,2,-1,0)
Block(-6,3,-7,0)
Block(-6,3,-6,0)
Block(-6,3,-5,0)
Block(-6,3,-4,0)
Block(-6,3,-3,0)
Block(-6,3,-2,0)
Block(-6,3,-1,0)
Block(-6,3,0,0)
Block(-6,4,-7,98:2)
Block(-6,4,-6,97:2)
Block(-6,4,-5,98:2)
Block(-6,4,-4,97:2)
Block(-6,4,-3,97:2)
Block(-6,4,-2,98:1)
Block(-6,4,-1,97:2)
Block(-6,4,0,98:2)
Block(-6,4,1,97:2)
Block(-6,4,2,97:2)
Block(-6,4,3,98:1)
Block(-6,4,4,97:2)
Block(-6,4,5,98:2)
Block(-6,4,6,97:2)
Block(-6,4,7,97:2)
Block(-6,5,-7,97:2)
Block(-6,5,-6,97:2)
Block(-6,5,-5,97:2)
Block(-6,5,-4,97:2)
Block(-6,5,-3,97:2)
Block(-6,5,-2,97:2)
Block(-6,5,-1,98:2)
Block(-6,5,0,97:2)
Block(-6,5,1,97:2)
Block(-6,5,2,97:2)
Block(-6,5,3,98:1)
Block(-6,5,4,98:1)
Block(-6,5,5,97:2)
Block(-6,5,6,98:2)
Block(-6,5,7,98:2)
Block(-6,6,-7,97:2)
Block(-6,6,-6,0)
Block(-6,6,-5,98:2)
Block(-6,6,-4,0)
Block(-6,6,-3,0)
Block(-6,6,-2,0)
Block(-6,6,-1,0)
Block(-6,6,0,0)
Block(-6,6,1,65:2)
Block(-6,6,2,97:2)
Block(-6,6,3,0)
Block(-6,6,4,0)
Block(-6,6,5,0)
Block(-6,6,6,97:2)
Block(-6,6,7,97:2)
Block(-6,7,-7,97:2)
Block(-6,7,-6,0)
Block(-6,7,-5,97:2)
Block(-6,7,-4,0)
Block(-6,7,-3,0)
Block(-6,7,-2,0)
Block(-6,7,-1,0)
Block(-6,7,0,0)
Block(-6,7,1,65:2)
Block(-6,7,2,98:1)
Block(-6,7,3,0)
Block(-6,7,4,0)
Block(-6,7,5,0)
Block(-6,7,6,97:2)
Block(-6,7,7,97:2)
Block(-6,8,-7,98:2)
Block(-6,8,-6,97:2)
Block(-6,8,-5,97:2)
Block(-6,8,-4,97:2)
Block(-6,8,-3,97:2)
Block(-6,8,-2,97:2)
Block(-6,8,-1,98:1)
Block(-6,8,0,97:2)
Block(-6,8,1,65:2)
Block(-6,8,2,97:2)
Block(-6,8,3,97:2)
Block(-6,8,4,97:2)
Block(-6,8,5,97:2)
Block(-6,8,6,97:2)
Block(-6,8,7,98:1)
Block(-6,9,-7,0)
Block(-6,9,-6,64:1)
Block(-6,9,-5,132:4)
Block(-6,9,-4,146,../../nbt/chestEpic1.nbt,27,146:3,../../nbt/chestEpic2.nbt,27,146:3,../../nbt/chestEpic3.nbt,27,146:3,../../nbt/chestEpic4.nbt,27,146:3,../../nbt/chestEpic5.nbt,100)
Block(-6,9,-3,132:4)
Block(-6,9,-2,64:3)
Block(-6,9,-1,0)
Block(-6,9,0,0)
Block(-6,9,1,0)
Block(-6,9,2,97:2)
Block(-6,9,3,97:2)
Block(-6,9,4,97:2)
Block(-6,9,5,97:2)
Block(-6,9,6,97:2)
Block(-6,9,7,97:2)
Block(-6,10,-7,0)
Block(-6,10,-6,64:8)
Block(-6,10,-5,0)
Block(-6,10,-4,0)
Block(-6,10,-3,0)
Block(-6,10,-2,64:9)
Block(-6,10,-1,0)
Block(-6,10,0,0)
Block(-6,10,1,0)
Block(-6,10,2,97:2)
Block(-6,10,3,97:2)
Block(-6,10,4,97:2)
Block(-6,10,5,97:2)
Block(-6,10,6,97:2)
Block(-6,10,7,98:2)
Block(-6,11,-7,98:2)
Block(-6,11,-6,98:2)
Block(-6,11,-5,97:2)
Block(-6,11,-4,98:1)
Block(-6,11,-3,97:2)
Block(-6,11,-2,98:2)
Block(-6,11,-1,97:2)
Block(-6,11,0,97:2)
Block(-6,11,1,97:2)
Block(-6,11,2,97:2)
Block(-6,11,3,97:2)
Block(-6,11,4,97:2)
Block(-6,11,5,98:1)
Block(-6,11,6,97:2)
Block(-6,11,7,98:2)
Block(-6,12,-7,0)
Block(-6,12,-6,97:2)
Block(-6,12,-5,0)
Block(-6,12,-4,98:1)
Block(-6,12,-3,0)
Block(-6,12,-2,97:2)
Block(-6,12,-1,0)
Block(-6,12,0,97:2)
Block(-6,12,1,0)
Block(-6,12,2,97:2)
Block(-6,12,3,0)
Block(-6,12,4,98:1)
Block(-6,12,5,0)
Block(-6,12,6,98:1)
Block(-6,12,7,98:2)
Block(-6,13,-7,0)
Block(-6,13,-6,97:2)
Block(-6,13,-5,0)
Block(-6,13,-4,98:1)
Block(-6,13,-3,0)
Block(-6,13,-2,97:2)
Block(-6,13,-1,0)
Block(-6,13,0,97:2)
Block(-6,13,1,0)
Block(-6,13,2,98:1)
Block(-6,13,3,0)
Block(-6,13,4,97:2)
Block(-6,13,5,0)
Block(-6,13,6,98:1)
Block(-6,13,7,97:2)
Block(-6,14,-7,97:2)
Block(-6,14,-6,98:1)
Block(-6,14,-5,98:1)
Block(-6,14,-4,97:2)
Block(-6,14,-3,97:2)
Block(-6,14,-2,97:2)
Block(-6,14,-1,98:1)
Block(-6,14,0,98:2)
Block(-6,14,1,97:2)
Block(-6,14,2,98:2)
Block(-6,14,3,97:2)
Block(-6,14,4,98:2)
Block(-6,14,5,97:2)
Block(-6,14,6,97:2)
Block(-6,14,7,97:2)
Block(-6,15,-7,97:2)
Block(-6,15,-6,97:2)
Block(-6,15,-5,98:2)
Block(-6,15,-4,97:2)
Block(-6,15,-3,97:2)
Block(-6,15,-2,97:2)
Block(-6,15,-1,98:1)
Block(-6,15,0,97:2)
Block(-6,15,1,97:2)
Block(-6,15,2,97:2)
Block(-6,15,3,97:2)
Block(-6,15,4,97:2)
Block(-6,15,5,97:2)
Block(-6,15,6,97:2)
Block(-6,15,7,97:2)
Block(-5,1,-7,0)
Block(-5,1,-6,0)
Block(-5,1,-5,0)
Block(-5,1,-4,0)
Block(-5,1,-3,0)
Block(-5,2,-7,0)
Block(-5,2,-6,0)
Block(-5,2,-5,0)
Block(-5,2,-4,0)
Block(-5,2,-3,0)
Block(-5,2,-2,0)
Block(-5,2,-1,0)
Block(-5,2,0,0)
Block(-5,3,-7,0)
Block(-5,3,-6,0)
Block(-5,3,-5,0)
Block(-5,3,-4,0)
Block(-5,3,-3,0)
Block(-5,3,-2,0)
Block(-5,3,-1,0)
Block(-5,3,0,0)
Block(-5,3,1,0)
Block(-5,3,2,0)
Block(-5,4,-7,97:2)
Block(-5,4,-6,97:2)
Block(-5,4,-5,97:2)
Block(-5,4,-4,97:2)
Block(-5,4,-3,97:2)
Block(-5,4,-2,97:2)
Block(-5,4,-1,97:2)
Block(-5,4,0,98:2)
Block(-5,4,1,97:2)
Block(-5,4,2,97:2)
Block(-5,4,3,97:2)
Block(-5,4,4,97:2)
Block(-5,4,5,97:2)
Block(-5,4,6,97:2)
Block(-5,4,7,97:2)
Block(-5,5,-7,98:1)
Block(-5,5,-6,97:2)
Block(-5,5,-5,97:2)
Block(-5,5,-4,97:2)
Block(-5,5,-3,97:2)
Block(-5,5,-2,97:2)
Block(-5,5,-1,98:1)
Block(-5,5,0,97:2)
Block(-5,5,1,97:2)
Block(-5,5,2,97:2)
Block(-5,5,3,98:2)
Block(-5,5,4,97:2)
Block(-5,5,5,98:1)
Block(-5,5,6,97:2)
Block(-5,5,7,98:1)
Block(-5,6,-7,97:2)
Block(-5,6,-6,0)
Block(-5,6,-5,97:2)
Block(-5,6,-4,97:2)
Block(-5,6,-3,0)
Block(-5,6,-2,97:2)
Block(-5,6,-1,0)
Block(-5,6,0,97:2)
Block(-5,6,1,97:2)
Block(-5,6,2,97:2)
Block(-5,6,3,98:1)
Block(-5,6,4,97:2)
Block(-5,6,5,0)
Block(-5,6,6,97:2)
Block(-5,6,7,97:2)
Block(-5,7,-7,97:2)
Block(-5,7,-6,0)
Block(-5,7,-5,97:2)
Block(-5,7,-4,97:2)
Block(-5,7,-3,0)
Block(-5,7,-2,97:2)
Block(-5,7,-1,0)
Block(-5,7,0,98:1)
Block(-5,7,1,97:2)
Block(-5,7,2,98:2)
Block(-5,7,3,97:2)
Block(-5,7,4,97:2)
Block(-5,7,5,0)
Block(-5,7,6,97:2)
Block(-5,7,7,97:2)
Block(-5,8,-7,97:2)
Block(-5,8,-6,98:2)
Block(-5,8,-5,97:2)
Block(-5,8,-4,97:2)
Block(-5,8,-3,97:2)
Block(-5,8,-2,97:2)
Block(-5,8,-1,97:2)
Block(-5,8,0,97:2)
Block(-5,8,1,97:2)
Block(-5,8,2,97:2)
Block(-5,8,3,97:2)
Block(-5,8,4,98:1)
Block(-5,8,5,97:2)
Block(-5,8,6,97:2)
Block(-5,8,7,97:2)
Block(-5,9,-7,0)
Block(-5,9,-6,97:2)
Block(-5,9,-5,132:4)
Block(-5,9,-4,0)
Block(-5,9,-3,132:4)
Block(-5,9,-2,97:2)
Block(-5,9,-1,97:2)
Block(-5,9,0,97:2)
Block(-5,9,1,97:2)
Block(-5,9,2,97:2)
Block(-5,9,3,97:2)
Block(-5,9,4,97:2)
Block(-5,9,5,97:2)
Block(-5,9,6,97:2)
Block(-5,9,7,97:2)
Block(-5,10,-7,0)
Block(-5,10,-6,97:2)
Block(-5,10,-5,0)
Block(-5,10,-4,76:2)
Block(-5,10,-3,0)
Block(-5,10,-2,97:2)
Block(-5,10,-1,97:2)
Block(-5,10,0,97:2)
Block(-5,10,1,97:2)
Block(-5,10,2,97:2)
Block(-5,10,3,97:2)
Block(-5,10,4,98:2)
Block(-5,10,5,97:2)
Block(-5,10,6,98:1)
Block(-5,10,7,98:1)
Block(-5,11,-7,97:2)
Block(-5,11,-6,97:2)
Block(-5,11,-5,97:2)
Block(-5,11,-4,97:2)
Block(-5,11,-3,97:2)
Block(-5,11,-2,97:2)
Block(-5,11,-1,97:2)
Block(-5,11,0,98:2)
Block(-5,11,1,97:2)
Block(-5,11,2,97:2)
Block(-5,11,3,98:1)
Block(-5,11,4,97:2)
Block(-5,11,5,98:1)
Block(-5,11,6,97:2)
Block(-5,11,7,97:2)
Block(-5,12,-7,0)
Block(-5,12,-6,98:1)
Block(-5,12,-5,0)
Block(-5,12,-4,97:2)
Block(-5,12,-3,0)
Block(-5,12,-2,0)
Block(-5,12,-1,0)
Block(-5,12,0,97:2)
Block(-5,12,1,0)
Block(-5,12,2,97:2)
Block(-5,12,3,0)
Block(-5,12,4,98:1)
Block(-5,12,5,0)
Block(-5,12,6,98:1)
Block(-5,12,7,97:2)
Block(-5,13,-7,0)
Block(-5,13,-6,98:2)
Block(-5,13,-5,0)
Block(-5,13,-4,98:2)
Block(-5,13,-3,0)
Block(-5,13,-2,0)
Block(-5,13,-1,0)
Block(-5,13,0,97:2)
Block(-5,13,1,0)
Block(-5,13,2,98:1)
Block(-5,13,3,0)
Block(-5,13,4,97:2)
Block(-5,13,5,0)
Block(-5,13,6,97:2)
Block(-5,13,7,97:2)
Block(-5,14,-7,97:2)
Block(-5,14,-6,97:2)
Block(-5,14,-5,97:2)
Block(-5,14,-4,98:2)
Block(-5,14,-3,97:2)
Block(-5,14,-2,98:1)
Block(-5,14,-1,97:2)
Block(-5,14,0,97:2)
Block(-5,14,1,98:2)
Block(-5,14,2,97:2)
Block(-5,14,3,97:2)
Block(-5,14,4,97:2)
Block(-5,14,5,97:2)
Block(-5,14,6,97:2)
Block(-5,14,7,98:2)
Block(-5,15,-7,98:2)
Block(-5,15,-6,97:2)
Block(-5,15,-5,97:2)
Block(-5,15,-4,98:2)
Block(-5,15,-3,98:2)
Block(-5,15,-2,97:2)
Block(-5,15,-1,98:1)
Block(-5,15,0,97:2)
Block(-5,15,1,97:2)
Block(-5,15,2,97:2)
Block(-5,15,3,97:2)
Block(-5,15,4,97:2)
Block(-5,15,5,97:2)
Block(-5,15,6,97:2)
Block(-5,15,7,97:2)
Block(-4,1,-7,0)
Block(-4,1,-6,0)
Block(-4,1,-5,0)
Block(-4,2,-7,0)
Block(-4,2,-6,0)
Block(-4,2,-5,0)
Block(-4,2,-4,0)
Block(-4,2,-3,0)
Block(-4,2,-2,0)
Block(-4,2,-1,0)
Block(-4,2,0,0)
Block(-4,2,1,0)
Block(-4,3,-7,0)
Block(-4,3,-6,0)
Block(-4,3,-5,0)
Block(-4,3,-4,0)
Block(-4,3,-3,0)
Block(-4,3,-2,0)
Block(-4,3,-1,0)
Block(-4,3,0,0)
Block(-4,3,1,0)
Block(-4,3,2,0)
Block(-4,4,-7,98:2)
Block(-4,4,-6,97:2)
Block(-4,4,-5,97:2)
Block(-4,4,-4,97:2)
Block(-4,4,-3,97:2)
Block(-4,4,-2,97:2)
Block(-4,4,-1,98:1)
Block(-4,4,0,97:2)
Block(-4,4,1,97:2)
Block(-4,4,2,97:2)
Block(-4,4,3,97:2)
Block(-4,4,4,97:2)
Block(-4,4,5,98:1)
Block(-4,4,6,97:2)
Block(-4,4,7,97:2)
Block(-4,5,-7,97:2)
Block(-4,5,-6,97:2)
Block(-4,5,-5,97:2)
Block(-4,5,-4,97:2)
Block(-4,5,-3,97:2)
Block(-4,5,-2,98:1)
Block(-4,5,-1,98:1)
Block(-4,5,0,97:2)
Block(-4,5,1,97:2)
Block(-4,5,2,98:2)
Block(-4,5,3,97:2)
Block(-4,5,4,97:2)
Block(-4,5,5,97:2)
Block(-4,5,6,98:1)
Block(-4,5,7,97:2)
Block(-4,6,-7,0)
Block(-4,6,-6,0)
Block(-4,6,-5,97:2)
Block(-4,6,-4,0)
Block(-4,6,-3,0)
Block(-4,6,-2,97:2)
Block(-4,6,-1,0)
Block(-4,6,0,97:2)
Block(-4,6,1,0)
Block(-4,6,2,98:2)
Block(-4,6,3,0)
Block(-4,6,4,0)
Block(-4,6,5,0)
Block(-4,6,6,97:2)
Block(-4,6,7,97:2)
Block(-4,7,-7,0)
Block(-4,7,-6,0)
Block(-4,7,-5,97:2)
Block(-4,7,-4,0)
Block(-4,7,-3,0)
Block(-4,7,-2,97:2)
Block(-4,7,-1,0)
Block(-4,7,0,98:2)
Block(-4,7,1,0)
Block(-4,7,2,97:2)
Block(-4,7,3,0)
Block(-4,7,4,0)
Block(-4,7,5,0)
Block(-4,7,6,97:2)
Block(-4,7,7,97:2)
Block(-4,8,-7,98:2)
Block(-4,8,-6,97:2)
Block(-4,8,-5,98:2)
Block(-4,8,-4,97:2)
Block(-4,8,-3,97:2)
Block(-4,8,-2,98:2)
Block(-4,8,-1,97:2)
Block(-4,8,0,97:2)
Block(-4,8,1,97:2)
Block(-4,8,2,98:1)
Block(-4,8,3,98:1)
Block(-4,8,4,98:2)
Block(-4,8,5,97:2)
Block(-4,8,6,97:2)
Block(-4,8,7,97:2)
Block(-4,9,-7,0)
Block(-4,9,-6,97:2)
Block(-4,9,-5,131:5)
Block(-4,9,-4,98:1)
Block(-4,9,-3,131:5)
Block(-4,9,-2,97:2)
Block(-4,9,-1,97:2)
Block(-4,9,0,97:2)
Block(-4,9,1,97:2)
Block(-4,9,2,0)
Block(-4,9,3,0)
Block(-4,9,4,0)
Block(-4,9,5,0)
Block(-4,9,6,97:2)
Block(-4,9,7,97:2)
Block(-4,10,-7,0)
Block(-4,10,-6,98:2)
Block(-4,10,-5,0)
Block(-4,10,-4,97:2)
Block(-4,10,-3,0)
Block(-4,10,-2,97:2)
Block(-4,10,-1,98:1)
Block(-4,10,0,97:2)
Block(-4,10,1,97:2)
Block(-4,10,2,0)
Block(-4,10,3,0)
Block(-4,10,4,0)
Block(-4,10,5,0)
Block(-4,10,6,97:2)
Block(-4,10,7,97:2)
Block(-4,11,-7,97:2)
Block(-4,11,-6,97:2)
Block(-4,11,-5,97:2)
Block(-4,11,-4,46)
Block(-4,11,-3,97:2)
Block(-4,11,-2,97:2)
Block(-4,11,-1,98:1)
Block(-4,11,0,97:2)
Block(-4,11,1,97:2)
Block(-4,11,2,97:2)
Block(-4,11,3,97:2)
Block(-4,11,4,97:2)
Block(-4,11,5,97:2)
Block(-4,11,6,97:2)
Block(-4,11,7,97:2)
Block(-4,12,-7,0)
Block(-4,12,-6,0)
Block(-4,12,-5,0)
Block(-4,12,-4,97:2)
Block(-4,12,-3,97:2)
Block(-4,12,-2,98:1)
Block(-4,12,-1,98:2)
Block(-4,12,0,98:1)
Block(-4,12,1,98:1)
Block(-4,12,2,97:2)
Block(-4,12,3,0)
Block(-4,12,4,97:2)
Block(-4,12,5,0)
Block(-4,12,6,97:2)
Block(-4,12,7,97:2)
Block(-4,13,-7,0)
Block(-4,13,-6,0)
Block(-4,13,-5,0)
Block(-4,13,-4,97:2)
Block(-4,13,-3,98:1)
Block(-4,13,-2,97:2)
Block(-4,13,-1,98:1)
Block(-4,13,0,97:2)
Block(-4,13,1,97:2)
Block(-4,13,2,97:2)
Block(-4,13,3,0)
Block(-4,13,4,97:2)
Block(-4,13,5,0)
Block(-4,13,6,97:2)
Block(-4,13,7,98:1)
Block(-4,14,-7,98:2)
Block(-4,14,-6,98:2)
Block(-4,14,-5,98:2)
Block(-4,14,-4,97:2)
Block(-4,14,-3,97:2)
Block(-4,14,-2,98:2)
Block(-4,14,-1,98:2)
Block(-4,14,0,98:2)
Block(-4,14,1,98:2)
Block(-4,14,2,97:2)
Block(-4,14,3,97:2)
Block(-4,14,4,97:2)
Block(-4,14,5,97:2)
Block(-4,14,6,97:2)
Block(-4,14,7,97:2)
Block(-4,15,-7,97:2)
Block(-4,15,-6,97:2)
Block(-4,15,-5,98:2)
Block(-4,15,-4,97:2)
Block(-4,15,-3,97:2)
Block(-4,15,-2,97:2)
Block(-4,15,-1,97:2)
Block(-4,15,0,97:2)
Block(-4,15,1,98:2)
Block(-4,15,2,97:2)
Block(-4,15,3,97:2)
Block(-4,15,4,97:2)
Block(-4,15,5,97:2)
Block(-4,15,6,98:1)
Block(-4,15,7,98:1)
Block(-3,2,-7,0)
Block(-3,2,-6,0)
Block(-3,2,-5,0)
Block(-3,3,-7,0)
Block(-3,3,-6,0)
Block(-3,3,-5,0)
Block(-3,3,-4,0)
Block(-3,3,-3,0)
Block(-3,3,-2,0)
Block(-3,3,-1,0)
Block(-3,3,0,0)
Block(-3,3,1,0)
Block(-3,4,-7,98:1)
Block(-3,4,-6,97:2)
Block(-3,4,-5,97:2)
Block(-3,4,-4,97:2)
Block(-3,4,-3,97:2)
Block(-3,4,-2,98:1)
Block(-3,4,-1,97:2)
Block(-3,4,0,97:2)
Block(-3,4,1,97:2)
Block(-3,4,2,97:2)
Block(-3,4,3,97:2)
Block(-3,4,4,97:2)
Block(-3,4,5,97:2)
Block(-3,4,6,97:2)
Block(-3,4,7,98:1)
Block(-3,5,-7,97:2)
Block(-3,5,-6,97:2)
Block(-3,5,-5,97:2)
Block(-3,5,-4,98:1)
RandomBlock(-3,5,-3,46,20,97:2,100)
RandomBlock(-3,5,-2,46,20,97:2,100)
Block(-3,5,-1,97:2)
Block(-3,5,0,97:2)
Block(-3,5,1,97:2)
Block(-3,5,2,97:2)
Block(-3,5,3,97:2)
Block(-3,5,4,98:1)
Block(-3,5,5,97:2)
Block(-3,5,6,97:2)
Block(-3,5,7,97:2)
Block(-3,6,-7,97:2)
Block(-3,6,-6,98:2)
Block(-3,6,-5,97:2)
Block(-3,6,-4,0)
Block(-3,6,-3,97:2)
Block(-3,6,-2,97:2)
Block(-3,6,-1,0)
Block(-3,6,0,97:2)
Block(-3,6,1,0)
Block(-3,6,2,97:2)
Block(-3,6,3,0)
Block(-3,6,4,97:2)
Block(-3,6,5,97:2)
Block(-3,6,6,97:2)
Block(-3,6,7,97:2)
Block(-3,7,-7,97:2)
Block(-3,7,-6,97:2)
Block(-3,7,-5,98:2)
Block(-3,7,-4,0)
Block(-3,7,-3,98:2)
Block(-3,7,-2,97:2)
Block(-3,7,-1,0)
Block(-3,7,0,97:2)
Block(-3,7,1,0)
Block(-3,7,2,97:2)
Block(-3,7,3,0)
Block(-3,7,4,97:2)
Block(-3,7,5,97:2)
Block(-3,7,6,97:2)
Block(-3,7,7,97:2)
Block(-3,8,-7,97:2)
Block(-3,8,-6,98:2)
Block(-3,8,-5,46)
Block(-3,8,-4,97:2)
Block(-3,8,-3,46)
Block(-3,8,-2,97:2)
Block(-3,8,-1,97:2)
Block(-3,8,0,97:2)
Block(-3,8,1,97:2)
Block(-3,8,2,97:2)
Block(-3,8,3,97:2)
Block(-3,8,4,98:2)
Block(-3,8,5,98:2)
Block(-3,8,6,97:2)
Block(-3,8,7,97:2)
Block(-3,9,-7,0)
Block(-3,9,-6,97:2)
RandomBlock(-3,9,-5,46,20,97:2,100)
Block(-3,9,-4,46)
Block(-3,9,-3,46)
RandomBlock(-3,9,-2,46,20,97:2,100)
RandomBlock(-3,9,-1,46,20,97:2,100)
RandomBlock(-3,9,0,46,20,97:2,100)
Block(-3,9,1,46)
Block(-3,9,2,146:3,../../nbt/chestEpic1.nbt,27,146:3,../../nbt/chestEpic2.nbt,27,146:3,../../nbt/chestEpic3.nbt,27,146:3,../../nbt/chestEpic4.nbt,27,146:3,../../nbt/chestEpic5.nbt,100)
Block(-3,9,3,0)
Block(-3,9,4,0)
Block(-3,9,5,0)
Block(-3,9,6,97:2)
Block(-3,9,7,98:2)
Block(-3,10,-7,0)
Block(-3,10,-6,97:2)
Block(-3,10,-5,46)
Block(-3,10,-4,46)
Block(-3,10,-3,46)
Block(-3,10,-2,97:2)
Block(-3,10,-1,97:2)
Block(-3,10,0,98:1)
Block(-3,10,1,97:2)
Block(-3,10,2,0)
Block(-3,10,3,0)
Block(-3,10,4,0)
Block(-3,10,5,0)
Block(-3,10,6,98:1)
Block(-3,10,7,97:2)
Block(-3,11,-7,97:2)
Block(-3,11,-6,97:2)
Block(-3,11,-5,46)
RandomBlock(-3,11,-4,46,20,97:2,100)
RandomBlock(-3,11,-3,46,20,97:2,100)
Block(-3,11,-2,98:1)
Block(-3,11,-1,97:2)
Block(-3,11,0,97:2)
Block(-3,11,1,97:2)
Block(-3,11,2,98:1)
Block(-3,11,3,97:2)
Block(-3,11,4,97:2)
Block(-3,11,5,98:2)
Block(-3,11,6,97:2)
Block(-3,11,7,97:2)
Block(-3,12,-7,0)
Block(-3,12,-6,97:2)
Block(-3,12,-5,97:2)
Block(-3,12,-4,97:2)
Block(-3,12,-3,97:2)
Block(-3,12,-2,0)
Block(-3,12,-1,0)
Block(-3,12,0,0)
Block(-3,12,1,97:2)
Block(-3,12,2,97:2)
Block(-3,12,3,0)
Block(-3,12,4,98:2)
Block(-3,12,5,0)
Block(-3,12,6,98:2)
Block(-3,12,7,97:2)
Block(-3,13,-7,0)
Block(-3,13,-6,97:2)
Block(-3,13,-5,97:2)
Block(-3,13,-4,97:2)
Block(-3,13,-3,97:2)
Block(-3,13,-2,0)
Block(-3,13,-1,0)
Block(-3,13,0,0)
Block(-3,13,1,97:2)
Block(-3,13,2,97:2)
Block(-3,13,3,0)
Block(-3,13,4,97:2)
Block(-3,13,5,0)
Block(-3,13,6,97:2)
Block(-3,13,7,97:2)
Block(-3,14,-7,98:1)
Block(-3,14,-6,97:2)
Block(-3,14,-5,98:1)
Block(-3,14,-4,97:2)
Block(-3,14,-3,97:2)
Block(-3,14,-2,98:1)
Block(-3,14,-1,97:2)
Block(-3,14,0,97:2)
Block(-3,14,1,98:1)
Block(-3,14,2,98:2)
Block(-3,14,3,97:2)
Block(-3,14,4,97:2)
Block(-3,14,5,97:2)
Block(-3,14,6,97:2)
Block(-3,14,7,97:2)
Block(-3,15,-7,97:2)
Block(-3,15,-6,97:2)
Block(-3,15,-5,98:1)
Block(-3,15,-4,97:2)
Block(-3,15,-3,97:2)
Block(-3,15,-2,97:2)
Block(-3,15,-1,97:2)
Block(-3,15,0,97:2)
Block(-3,15,1,97:2)
Block(-3,15,2,97:2)
Block(-3,15,3,97:2)
Block(-3,15,4,97:2)
Block(-3,15,5,97:2)
Block(-3,15,6,97:2)
Block(-3,15,7,97:2)
Block(-2,3,-7,0)
Block(-2,3,-3,0)
Block(-2,3,-1,0)
Block(-2,3,0,0)
Block(-2,3,1,0)
Block(-2,4,-7,97:2)
Block(-2,4,-6,97:2)
Block(-2,4,-5,97:2)
Block(-2,4,-4,97:2)
Block(-2,4,-3,97:2)
Block(-2,4,-2,97:2)
Block(-2,4,-1,97:2)
Block(-2,4,0,97:2)
Block(-2,4,1,97:2)
Block(-2,4,2,97:2)
Block(-2,4,3,97:2)
Block(-2,4,4,98:2)
Block(-2,4,5,97:2)
Block(-2,4,6,97:2)
Block(-2,4,7,97:2)
Block(-2,5,-7,97:2)
Block(-2,5,-6,98:1)
Block(-2,5,-5,97:2)
Block(-2,5,-4,98:2)
Block(-2,5,-3,98:2)
Block(-2,5,-2,46)
Block(-2,5,-1,98:2)
Block(-2,5,0,97:2)
Block(-2,5,1,97:2)
Block(-2,5,2,98:1)
Block(-2,5,3,98:1)
Block(-2,5,4,97:2)
Block(-2,5,5,98:1)
Block(-2,5,6,97:2)
Block(-2,5,7,97:2)
Block(-2,6,-7,131:4)
Block(-2,6,-6,132:4)
Block(-2,6,-5,132:4)
Block(-2,6,-4,132:4)
Block(-2,6,-3,131:6)
Block(-2,6,-2,97:2)
Block(-2,6,-1,0)
Block(-2,6,0,97:2)
Block(-2,6,1,0)
Block(-2,6,2,98:2)
Block(-2,6,3,0)
Block(-2,6,4,0)
Block(-2,6,5,0)
Block(-2,6,6,97:2)
Block(-2,6,7,98:1)
Block(-2,7,-7,0)
Block(-2,7,-6,0)
Block(-2,7,-5,0)
Block(-2,7,-4,0)
Block(-2,7,-3,0)
Block(-2,7,-2,97:2)
Block(-2,7,-1,0)
Block(-2,7,0,97:2)
Block(-2,7,1,0)
Block(-2,7,2,97:2)
Block(-2,7,3,0)
Block(-2,7,4,0)
Block(-2,7,5,0)
Block(-2,7,6,97:2)
Block(-2,7,7,97:2)
Block(-2,8,-7,97:2)
Block(-2,8,-6,97:2)
Block(-2,8,-5,97:2)
Block(-2,8,-4,97:2)
Block(-2,8,-3,97:2)
Block(-2,8,-2,97:2)
Block(-2,8,-1,97:2)
Block(-2,8,0,97:2)
Block(-2,8,1,97:2)
Block(-2,8,2,98:2)
Block(-2,8,3,97:2)
Block(-2,8,4,98:1)
Block(-2,8,5,97:2)
Block(-2,8,6,97:2)
Block(-2,8,7,98:1)
Block(-2,9,-7,0)
Block(-2,9,-6,98:2)
Block(-2,9,-5,97:2)
Block(-2,9,-4,97:2)
Block(-2,9,-3,98:1)
Block(-2,9,-2,98:1)
Block(-2,9,-1,98:1)
Block(-2,9,0,97:2)
Block(-2,9,1,97:2)
Block(-2,9,2,0)
Block(-2,9,3,0)
Block(-2,9,4,0)
Block(-2,9,5,0)
Block(-2,9,6,97:2)
Block(-2,9,7,97:2)
Block(-2,10,-7,0)
Block(-2,10,-6,97:2)
Block(-2,10,-5,98:1)
Block(-2,10,-4,97:2)
Block(-2,10,-3,98:1)
Block(-2,10,-2,97:2)
Block(-2,10,-1,97:2)
Block(-2,10,0,98:1)
Block(-2,10,1,97:2)
Block(-2,10,2,0)
Block(-2,10,3,0)
Block(-2,10,4,0)
Block(-2,10,5,0)
Block(-2,10,6,97:2)
Block(-2,10,7,97:2)
Block(-2,11,-7,98:1)
Block(-2,11,-6,97:2)
Block(-2,11,-5,97:2)
Block(-2,11,-4,97:2)
Block(-2,11,-3,97:2)
Block(-2,11,-2,98:2)
Block(-2,11,-1,98:1)
Block(-2,11,0,97:2)
Block(-2,11,1,97:2)
Block(-2,11,2,98:2)
Block(-2,11,3,97:2)
Block(-2,11,4,97:2)
Block(-2,11,5,97:2)
Block(-2,11,6,97:2)
Block(-2,11,7,97:2)
Block(-2,12,-7,0)
Block(-2,12,-6,97:2)
Block(-2,12,-5,0)
Block(-2,12,-4,0)
Block(-2,12,-3,0)
Block(-2,12,-2,0)
Block(-2,12,-1,97:2)
Block(-2,12,0,0)
Block(-2,12,1,0)
Block(-2,12,2,0)
Block(-2,12,3,0)
Block(-2,12,4,97:2)
Block(-2,12,5,0)
Block(-2,12,6,97:2)
Block(-2,12,7,97:2)
Block(-2,13,-7,0)
Block(-2,13,-6,97:2)
Block(-2,13,-5,0)
Block(-2,13,-4,0)
Block(-2,13,-3,0)
Block(-2,13,-2,0)
Block(-2,13,-1,98:2)
Block(-2,13,0,0)
Block(-2,13,1,0)
Block(-2,13,2,0)
Block(-2,13,3,0)
Block(-2,13,4,97:2)
Block(-2,13,5,0)
Block(-2,13,6,97:2)
Block(-2,13,7,97:2)
Block(-2,14,-7,98:2)
Block(-2,14,-6,97:2)
Block(-2,14,-5,97:2)
Block(-2,14,-4,97:2)
Block(-2,14,-3,97:2)
Block(-2,14,-2,97:2)
Block(-2,14,-1,97:2)
Block(-2,14,0,97:2)
Block(-2,14,1,98:1)
Block(-2,14,2,97:2)
Block(-2,14,3,97:2)
Block(-2,14,4,97:2)
Block(-2,14,5,98:1)
Block(-2,14,6,97:2)
Block(-2,14,7,97:2)
Block(-2,15,-7,97:2)
Block(-2,15,-6,97:2)
Block(-2,15,-5,98:1)
Block(-2,15,-4,97:2)
Block(-2,15,-3,98:2)
Block(-2,15,-2,97:2)
Block(-2,15,-1,97:2)
Block(-2,15,0,98:1)
Block(-2,15,1,97:2)
Block(-2,15,2,97:2)
Block(-2,15,3,97:2)
Block(-2,15,4,97:2)
Block(-2,15,5,97:2)
Block(-2,15,6,97:2)
Block(-2,15,7,97:2)
Block(-1,4,-7,97:2)
Block(-1,4,-6,97:2)
Block(-1,4,-5,97:2)
Block(-1,4,-4,97:2)
Block(-1,4,-3,98:2)
Block(-1,4,-2,97:2)
Block(-1,4,-1,97:2)
Block(-1,4,0,98:1)
Block(-1,4,1,98:2)
Block(-1,4,2,97:2)
Block(-1,4,3,97:2)
Block(-1,4,4,97:2)
Block(-1,4,5,98:2)
Block(-1,4,6,98:2)
Block(-1,4,7,97:2)
Block(-1,5,-7,97:2)
Block(-1,5,-6,97:2)
Block(-1,5,-5,97:2)
Block(-1,5,-4,97:2)
Block(-1,5,-3,97:2)
Block(-1,5,-2,97:2)
Block(-1,5,-1,98:2)
Block(-1,5,0,97:2)
Block(-1,5,1,97:2)
Block(-1,5,2,98:2)
Block(-1,5,3,97:2)
Block(-1,5,4,98:2)
Block(-1,5,5,98:2)
Block(-1,5,6,97:2)
Block(-1,5,7,97:2)
Block(-1,6,-7,97:2)
Block(-1,6,-6,97:2)
Block(-1,6,-5,97:2)
Block(-1,6,-4,0)
Block(-1,6,-3,97:2)
Block(-1,6,-2,97:2)
Block(-1,6,-1,0)
Block(-1,6,0,98:2)
Block(-1,6,1,0)
Block(-1,6,2,97:2)
Block(-1,6,3,97:2)
Block(-1,6,4,97:2)
Block(-1,6,5,0)
Block(-1,6,6,98:1)
Block(-1,6,7,97:2)
Block(-1,7,-7,97:2)
Block(-1,7,-6,97:2)
Block(-1,7,-5,97:2)
Block(-1,7,-4,0)
Block(-1,7,-3,97:2)
Block(-1,7,-2,97:2)
Block(-1,7,-1,0)
Block(-1,7,0,97:2)
Block(-1,7,1,0)
Block(-1,7,2,97:2)
Block(-1,7,3,97:2)
Block(-1,7,4,97:2)
Block(-1,7,5,0)
Block(-1,7,6,97:2)
Block(-1,7,7,97:2)
Block(-1,8,-7,98:1)
Block(-1,8,-6,97:2)
Block(-1,8,-5,98:1)
Block(-1,8,-4,97:2)
Block(-1,8,-3,98:2)
Block(-1,8,-2,97:2)
Block(-1,8,-1,97:2)
Block(-1,8,0,97:2)
Block(-1,8,1,97:2)
Block(-1,8,2,98:1)
Block(-1,8,3,98:1)
Block(-1,8,4,98:2)
Block(-1,8,5,97:2)
Block(-1,8,6,98:1)
Block(-1,8,7,98:2)
Block(-1,9,-7,0)
Block(-1,9,-6,0)
Block(-1,9,-5,65:2)
Block(-1,9,-4,97:2)
Block(-1,9,-3,97:2)
Block(-1,9,-2,0)
Block(-1,9,-1,0)
Block(-1,9,0,0)
Block(-1,9,1,97:2)
Block(-1,9,2,98:1)
Block(-1,9,3,0)
Block(-1,9,4,0)
Block(-1,9,5,0)
Block(-1,9,6,97:2)
Block(-1,9,7,97:2)
Block(-1,10,-7,0)
Block(-1,10,-6,0)
Block(-1,10,-5,65:2)
Block(-1,10,-4,97:2)
Block(-1,10,-3,97:2)
Block(-1,10,-2,0)
Block(-1,10,-1,0)
Block(-1,10,0,0)
Block(-1,10,1,98:1)
Block(-1,10,2,97:2)
Block(-1,10,3,0)
Block(-1,10,4,0)
Block(-1,10,5,0)
Block(-1,10,6,97:2)
Block(-1,10,7,98:2)
Block(-1,11,-7,98:1)
Block(-1,11,-6,97:2)
Block(-1,11,-5,65:2)
Block(-1,11,-4,97:2)
Block(-1,11,-3,97:2)
Block(-1,11,-2,97:2)
Block(-1,11,-1,97:2)
Block(-1,11,0,98:2)
Block(-1,11,1,97:2)
Block(-1,11,2,98:1)
Block(-1,11,3,98:2)
Block(-1,11,4,98:1)
Block(-1,11,5,97:2)
Block(-1,11,6,97:2)
Block(-1,11,7,97:2)
Block(-1,12,-7,0)
Block(-1,12,-6,97:2)
Block(-1,12,-5,0)
Block(-1,12,-4,97:2)
Block(-1,12,-3,97:2)
Block(-1,12,-2,0)
Block(-1,12,-1,0)
Block(-1,12,0,0)
Block(-1,12,1,98:2)
Block(-1,12,2,97:2)
Block(-1,12,3,0)
Block(-1,12,4,97:2)
Block(-1,12,5,0)
Block(-1,12,6,97:2)
Block(-1,12,7,97:2)
Block(-1,13,-7,0)
Block(-1,13,-6,97:2)
Block(-1,13,-5,0)
Block(-1,13,-4,97:2)
Block(-1,13,-3,98:2)
Block(-1,13,-2,0)
Block(-1,13,-1,0)
Block(-1,13,0,0)
Block(-1,13,1,98:2)
Block(-1,13,2,98:1)
Block(-1,13,3,0)
Block(-1,13,4,97:2)
Block(-1,13,5,0)
Block(-1,13,6,97:2)
Block(-1,13,7,98:2)
Block(-1,14,-7,97:2)
Block(-1,14,-6,98:2)
Block(-1,14,-5,97:2)
Block(-1,14,-4,98:1)
Block(-1,14,-3,98:1)
Block(-1,14,-2,97:2)
Block(-1,14,-1,97:2)
Block(-1,14,0,97:2)
Block(-1,14,1,97:2)
Block(-1,14,2,97:2)
Block(-1,14,3,98:2)
Block(-1,14,4,98:2)
Block(-1,14,5,98:2)
Block(-1,14,6,97:2)
Block(-1,14,7,97:2)
Block(-1,15,-7,97:2)
Block(-1,15,-6,98:1)
Block(-1,15,-5,98:2)
Block(-1,15,-4,98:2)
Block(-1,15,-3,98:2)
Block(-1,15,-2,97:2)
Block(-1,15,-1,97:2)
Block(-1,15,0,97:2)
Block(-1,15,1,98:1)
Block(-1,15,2,97:2)
Block(-1,15,3,98:1)
Block(-1,15,4,97:2)
Block(-1,15,5,97:2)
Block(-1,15,6,97:2)
Block(-1,15,7,98:2)
Block(0,2,-7,0)
Block(0,3,-7,0)
Block(0,4,-7,98:1)
Block(0,4,-6,97:2)
Block(0,4,-5,98:1)
Block(0,4,-4,98:2)
Block(0,4,-3,97:2)
Block(0,4,-2,98:2)
Block(0,4,-1,97:2)
Block(0,4,0,98:2)
Block(0,4,1,98:2)
Block(0,4,2,98:1)
Block(0,4,3,97:2)
Block(0,4,4,97:2)
Block(0,4,5,98:1)
Block(0,4,6,97:2)
Block(0,4,7,98:2)
Block(0,5,-7,97:2)
Block(0,5,-6,98:1)
Block(0,5,-5,97:2)
Block(0,5,-4,98:2)
Block(0,5,-3,97:2)
Block(0,5,-2,97:2)
Block(0,5,-1,97:2)
Block(0,5,0,97:2)
Block(0,5,1,97:2)
Block(0,5,2,97:2)
Block(0,5,3,98:2)
Block(0,5,4,97:2)
Block(0,5,5,97:2)
Block(0,5,6,97:2)
Block(0,5,7,97:2)
Block(0,6,-7,0)
Block(0,6,-6,0)
Block(0,6,-5,0)
Block(0,6,-4,0)
Block(0,6,-3,0)
Block(0,6,-2,0)
Block(0,6,-1,0)
Block(0,6,0,97:2)
Block(0,6,1,0)
Block(0,6,2,98:1)
Block(0,6,3,0)
Block(0,6,4,0)
Block(0,6,5,0)
Block(0,6,6,97:2)
Block(0,6,7,97:2)
Block(0,7,-7,0)
Block(0,7,-6,0)
Block(0,7,-5,0)
Block(0,7,-4,0)
Block(0,7,-3,0)
Block(0,7,-2,0)
Block(0,7,-1,0)
Block(0,7,0,97:2)
Block(0,7,1,0)
Block(0,7,2,97:2)
Block(0,7,3,0)
Block(0,7,4,0)
Block(0,7,5,0)
Block(0,7,6,97:2)
Block(0,7,7,97:2)
Block(0,8,-7,97:2)
Block(0,8,-6,98:1)
Block(0,8,-5,97:2)
Block(0,8,-4,98:2)
Block(0,8,-3,98:2)
Block(0,8,-2,97:2)
Block(0,8,-1,97:2)
Block(0,8,0,97:2)
Block(0,8,1,97:2)
Block(0,8,2,98:2)
Block(0,8,3,97:2)
Block(0,8,4,97:2)
Block(0,8,5,97:2)
Block(0,8,6,97:2)
Block(0,8,7,97:2)
Block(0,9,-7,97:2)
Block(0,9,-6,97:2)
Block(0,9,-5,0)
Block(0,9,-4,97:2)
Block(0,9,-3,0)
Block(0,9,-2,0)
Block(0,9,-1,97:2)
Block(0,9,0,0)
Block(0,9,1,0)
Block(0,9,2,97:2)
Block(0,9,3,97:2)
Block(0,9,4,97:2)
Block(0,9,5,0)
Block(0,9,6,98:2)
Block(0,9,7,97:2)
Block(0,10,-7,97:2)
Block(0,10,-6,97:2)
Block(0,10,-5,0)
Block(0,10,-4,97:2)
Block(0,10,-3,0)
Block(0,10,-2,0)
Block(0,10,-1,97:2)
Block(0,10,0,0)
Block(0,10,1,0)
Block(0,10,2,98:2)
Block(0,10,3,97:2)
Block(0,10,4,97:2)
Block(0,10,5,0)
Block(0,10,6,97:2)
Block(0,10,7,97:2)
Block(0,11,-7,98:2)
Block(0,11,-6,98:2)
Block(0,11,-5,98:2)
Block(0,11,-4,97:2)
Block(0,11,-3,98:2)
Block(0,11,-2,97:2)
Block(0,11,-1,98:2)
Block(0,11,0,97:2)
Block(0,11,1,97:2)
Block(0,11,2,98:1)
Block(0,11,3,98:2)
Block(0,11,4,97:2)
Block(0,11,5,98:1)
Block(0,11,6,97:2)
Block(0,11,7,97:2)
Block(0,12,-7,0)
Block(0,12,-6,97:2)
Block(0,12,-5,97:2)
Block(0,12,-4,97:2)
Block(0,12,-3,98:2)
Block(0,12,-2,97:2)
Block(0,12,-1,97:2)
Block(0,12,0,97:2)
Block(0,12,1,97:2)
Block(0,12,2,97:2)
Block(0,12,3,0)
Block(0,12,4,97:2)
Block(0,12,5,0)
Block(0,12,6,98:1)
Block(0,12,7,97:2)
Block(0,13,-7,0)
Block(0,13,-6,97:2)
Block(0,13,-5,97:2)
Block(0,13,-4,97:2)
Block(0,13,-3,98:1)
Block(0,13,-2,97:2)
Block(0,13,-1,97:2)
Block(0,13,0,97:2)
Block(0,13,1,97:2)
Block(0,13,2,98:2)
Block(0,13,3,0)
Block(0,13,4,97:2)
Block(0,13,5,0)
Block(0,13,6,97:2)
Block(0,13,7,97:2)
Block(0,14,-7,97:2)
Block(0,14,-6,97:2)
Block(0,14,-5,97:2)
Block(0,14,-4,97:2)
Block(0,14,-3,97:2)
Block(0,14,-2,98:2)
Block(0,14,-1,97:2)
Block(0,14,0,97:2)
Block(0,14,1,98:1)
Block(0,14,2,98:1)
Block(0,14,3,97:2)
Block(0,14,4,97:2)
Block(0,14,5,97:2)
Block(0,14,6,98:2)
Block(0,14,7,97:2)
Block(0,15,-7,97:2)
Block(0,15,-6,98:2)
Block(0,15,-5,97:2)
Block(0,15,-4,97:2)
Block(0,15,-3,98:1)
Block(0,15,-2,97:2)
Block(0,15,-1,97:2)
Block(0,15,0,97:2)
Block(0,15,1,97:2)
Block(0,15,2,97:2)
Block(0,15,3,97:2)
Block(0,15,4,98:1)
Block(0,15,5,97:2)
Block(0,15,6,98:2)
Block(0,15,7,97:2)
Block(1,2,-7,0)
Block(1,2,-6,0)
Block(1,3,-7,0)
Block(1,3,-6,0)
Block(1,3,-5,0)
Block(1,4,-7,97:2)
Block(1,4,-6,97:2)
Block(1,4,-5,98:2)
Block(1,4,-4,97:2)
Block(1,4,-3,98:1)
Block(1,4,-2,97:2)
Block(1,4,-1,98:1)
Block(1,4,0,97:2)
Block(1,4,1,97:2)
Block(1,4,2,98:1)
Block(1,4,3,97:2)
Block(1,4,4,98:2)
Block(1,4,5,97:2)
Block(1,4,6,97:2)
Block(1,4,7,97:2)
Block(1,5,-7,97:2)
Block(1,5,-6,97:2)
Block(1,5,-5,97:2)
Block(1,5,-4,98:2)
Block(1,5,-3,97:2)
Block(1,5,-2,98:1)
Block(1,5,-1,97:2)
Block(1,5,0,97:2)
Block(1,5,1,97:2)
Block(1,5,2,97:2)
Block(1,5,3,98:2)
Block(1,5,4,97:2)
Block(1,5,5,98:2)
Block(1,5,6,98:2)
Block(1,5,7,97:2)
Block(1,6,-7,97:2)
Block(1,6,-6,97:2)
Block(1,6,-5,98:1)
Block(1,6,-4,98:1)
Block(1,6,-3,97:2)
Block(1,6,-2,98:1)
Block(1,6,-1,0)
Block(1,6,0,97:2)
Block(1,6,1,0)
Block(1,6,2,97:2)
Block(1,6,3,0)
Block(1,6,4,97:2)
Block(1,6,5,97:2)
Block(1,6,6,97:2)
Block(1,6,7,98:1)
Block(1,7,-7,97:2)
Block(1,7,-6,97:2)
Block(1,7,-5,98:1)
Block(1,7,-4,97:2)
Block(1,7,-3,97:2)
Block(1,7,-2,97:2)
Block(1,7,-1,0)
Block(1,7,0,97:2)
Block(1,7,1,0)
Block(1,7,2,98:1)
Block(1,7,3,0)
Block(1,7,4,97:2)
Block(1,7,5,98:2)
Block(1,7,6,97:2)
Block(1,7,7,97:2)
Block(1,8,-7,98:1)
Block(1,8,-6,97:2)
Block(1,8,-5,97:2)
Block(1,8,-4,98:1)
Block(1,8,-3,97:2)
Block(1,8,-2,97:2)
Block(1,8,-1,97:2)
Block(1,8,0,98:2)
Block(1,8,1,97:2)
Block(1,8,2,97:2)
Block(1,8,3,97:2)
Block(1,8,4,98:1)
Block(1,8,5,97:2)
Block(1,8,6,98:1)
Block(1,8,7,97:2)
Block(1,9,-7,0)
Block(1,9,-6,97:2)
Block(1,9,-5,0)
Block(1,9,-4,0)
Block(1,9,-3,0)
Block(1,9,-2,97:2)
Block(1,9,-1,97:2)
Block(1,9,0,97:2)
Block(1,9,1,0)
Block(1,9,2,97:2)
Block(1,9,3,0)
Block(1,9,4,0)
Block(1,9,5,0)
Block(1,9,6,97:2)
Block(1,9,7,97:2)
Block(1,10,-7,0)
Block(1,10,-6,97:2)
Block(1,10,-5,0)
Block(1,10,-4,0)
Block(1,10,-3,0)
Block(1,10,-2,97:2)
Block(1,10,-1,98:2)
Block(1,10,0,97:2)
Block(1,10,1,0)
Block(1,10,2,97:2)
Block(1,10,3,0)
Block(1,10,4,0)
Block(1,10,5,0)
Block(1,10,6,97:2)
Block(1,10,7,97:2)
Block(1,11,-7,97:2)
Block(1,11,-6,97:2)
Block(1,11,-5,97:2)
Block(1,11,-4,98:2)
Block(1,11,-3,97:2)
Block(1,11,-2,97:2)
Block(1,11,-1,97:2)
Block(1,11,0,97:2)
Block(1,11,1,98:2)
Block(1,11,2,97:2)
Block(1,11,3,98:1)
Block(1,11,4,98:2)
Block(1,11,5,97:2)
Block(1,11,6,97:2)
Block(1,11,7,97:2)
Block(1,12,-7,0)
Block(1,12,-6,0)
Block(1,12,-5,0)
Block(1,12,-4,0)
Block(1,12,-3,0)
Block(1,12,-2,0)
Block(1,12,-1,0)
Block(1,12,0,0)
Block(1,12,1,0)
Block(1,12,2,97:2)
Block(1,12,3,0)
Block(1,12,4,98:1)
Block(1,12,5,97:2)
Block(1,12,6,97:2)
Block(1,12,7,98:1)
Block(1,13,-7,0)
Block(1,13,-6,0)
Block(1,13,-5,0)
Block(1,13,-4,0)
Block(1,13,-3,0)
Block(1,13,-2,0)
Block(1,13,-1,0)
Block(1,13,0,0)
Block(1,13,1,0)
Block(1,13,2,97:2)
Block(1,13,3,0)
Block(1,13,4,98:1)
Block(1,13,5,97:2)
Block(1,13,6,97:2)
Block(1,13,7,97:2)
Block(1,14,-7,97:2)
Block(1,14,-6,98:2)
Block(1,14,-5,98:1)
Block(1,14,-4,97:2)
Block(1,14,-3,97:2)
Block(1,14,-2,97:2)
Block(1,14,-1,98:1)
Block(1,14,0,97:2)
Block(1,14,1,98:2)
Block(1,14,2,97:2)
Block(1,14,3,97:2)
Block(1,14,4,97:2)
Block(1,14,5,98:2)
Block(1,14,6,98:1)
Block(1,14,7,97:2)
Block(1,15,-7,98:1)
Block(1,15,-6,97:2)
Block(1,15,-5,97:2)
Block(1,15,-4,98:1)
Block(1,15,-3,97:2)
Block(1,15,-2,97:2)
Block(1,15,-1,97:2)
Block(1,15,0,98:2)
Block(1,15,1,97:2)
Block(1,15,2,97:2)
Block(1,15,3,98:2)
Block(1,15,4,97:2)
Block(1,15,5,97:2)
Block(1,15,6,97:2)
Block(1,15,7,97:2)
Block(2,1,-7,0)
Block(2,1,-6,0)
Block(2,1,-5,0)
Block(2,2,-7,0)
Block(2,2,-6,0)
Block(2,2,-5,0)
Block(2,3,-7,0)
Block(2,3,-6,0)
Block(2,3,-5,0)
Block(2,3,-4,0)
Block(2,3,-3,0)
Block(2,4,-7,97:2)
Block(2,4,-6,97:2)
Block(2,4,-5,97:2)
Block(2,4,-4,97:2)
Block(2,4,-3,97:2)
Block(2,4,-2,97:2)
Block(2,4,-1,97:2)
Block(2,4,0,97:2)
Block(2,4,1,97:2)
Block(2,4,2,97:2)
Block(2,4,3,98:1)
Block(2,4,4,97:2)
Block(2,4,5,97:2)
Block(2,4,6,98:2)
Block(2,4,7,97:2)
Block(2,5,-7,98:2)
Block(2,5,-6,97:2)
Block(2,5,-5,97:2)
Block(2,5,-4,97:2)
Block(2,5,-3,98:2)
Block(2,5,-2,97:2)
Block(2,5,-1,97:2)
Block(2,5,0,98:2)
Block(2,5,1,97:2)
Block(2,5,2,97:2)
Block(2,5,3,97:2)
Block(2,5,4,98:2)
Block(2,5,5,97:2)
Block(2,5,6,97:2)
Block(2,5,7,97:2)
Block(2,6,-7,0)
Block(2,6,-6,0)
Block(2,6,-5,0)
Block(2,6,-4,0)
Block(2,6,-3,0)
Block(2,6,-2,0)
Block(2,6,-1,0)
Block(2,6,0,0)
Block(2,6,1,0)
Block(2,6,2,97:2)
Block(2,6,3,0)
Block(2,6,4,0)
Block(2,6,5,0)
Block(2,6,6,97:2)
Block(2,6,7,97:2)
Block(2,7,-7,0)
Block(2,7,-6,0)
Block(2,7,-5,0)
Block(2,7,-4,0)
Block(2,7,-3,0)
Block(2,7,-2,0)
Block(2,7,-1,0)
Block(2,7,0,0)
Block(2,7,1,0)
Block(2,7,2,97:2)
Block(2,7,3,0)
Block(2,7,4,0)
Block(2,7,5,0)
Block(2,7,6,98:2)
Block(2,7,7,97:2)
Block(2,8,-7,98:1)
Block(2,8,-6,98:2)
Block(2,8,-5,97:2)
Block(2,8,-4,97:2)
Block(2,8,-3,97:2)
Block(2,8,-2,97:2)
Block(2,8,-1,97:2)
Block(2,8,0,97:2)
Block(2,8,1,97:2)
Block(2,8,2,97:2)
Block(2,8,3,97:2)
Block(2,8,4,97:2)
Block(2,8,5,97:2)
Block(2,8,6,97:2)
Block(2,8,7,97:2)
Block(2,9,-7,0)
Block(2,9,-6,97:2)
Block(2,9,-5,0)
Block(2,9,-4,98:1)
Block(2,9,-3,97:2)
Block(2,9,-2,97:2)
Block(2,9,-1,97:2)
Block(2,9,0,98:1)
Block(2,9,1,0)
Block(2,9,2,98:2)
Block(2,9,3,0)
Block(2,9,4,98:2)
Block(2,9,5,97:2)
Block(2,9,6,97:2)
Block(2,9,7,97:2)
Block(2,10,-7,0)
Block(2,10,-6,97:2)
Block(2,10,-5,0)
Block(2,10,-4,97:2)
Block(2,10,-3,97:2)
Block(2,10,-2,97:2)
Block(2,10,-1,97:2)
Block(2,10,0,97:2)
Block(2,10,1,0)
Block(2,10,2,97:2)
Block(2,10,3,0)
Block(2,10,4,97:2)
Block(2,10,5,98:2)
Block(2,10,6,97:2)
Block(2,10,7,97:2)
Block(2,11,-7,97:2)
Block(2,11,-6,97:2)
Block(2,11,-5,97:2)
Block(2,11,-4,97:2)
Block(2,11,-3,98:2)
Block(2,11,-2,98:2)
Block(2,11,-1,97:2)
Block(2,11,0,98:1)
Block(2,11,1,97:2)
Block(2,11,2,97:2)
Block(2,11,3,97:2)
Block(2,11,4,97:2)
Block(2,11,5,97:2)
Block(2,11,6,98:2)
Block(2,11,7,97:2)
Block(2,12,-7,97:2)
Block(2,12,-6,97:2)
Block(2,12,-5,97:2)
Block(2,12,-4,97:2)
Block(2,12,-3,98:1)
Block(2,12,-2,97:2)
Block(2,12,-1,98:2)
Block(2,12,0,98:2)
Block(2,12,1,0)
Block(2,12,2,98:2)
Block(2,12,3,0)
Block(2,12,4,0)
Block(2,12,5,0)
Block(2,12,6,97:2)
Block(2,12,7,97:2)
Block(2,13,-7,97:2)
Block(2,13,-6,98:2)
Block(2,13,-5,97:2)
Block(2,13,-4,97:2)
Block(2,13,-3,97:2)
Block(2,13,-2,98:2)
Block(2,13,-1,97:2)
Block(2,13,0,97:2)
Block(2,13,1,0)
Block(2,13,2,98:2)
Block(2,13,3,0)
Block(2,13,4,0)
Block(2,13,5,0)
Block(2,13,6,97:2)
Block(2,13,7,98:1)
Block(2,14,-7,97:2)
Block(2,14,-6,97:2)
Block(2,14,-5,97:2)
Block(2,14,-4,97:2)
Block(2,14,-3,97:2)
Block(2,14,-2,97:2)
Block(2,14,-1,97:2)
Block(2,14,0,98:2)
Block(2,14,1,97:2)
Block(2,14,2,97:2)
Block(2,14,3,97:2)
Block(2,14,4,97:2)
Block(2,14,5,97:2)
Block(2,14,6,97:2)
Block(2,14,7,97:2)
Block(2,15,-7,97:2)
Block(2,15,-6,97:2)
Block(2,15,-5,98:1)
Block(2,15,-4,98:1)
Block(2,15,-3,97:2)
Block(2,15,-2,97:2)
Block(2,15,-1,97:2)
Block(2,15,0,97:2)
Block(2,15,1,98:1)
Block(2,15,2,97:2)
Block(2,15,3,97:2)
Block(2,15,4,97:2)
Block(2,15,5,98:2)
Block(2,15,6,98:2)
Block(2,15,7,97:2)
Block(3,0,-7,0)
Block(3,1,-7,0)
Block(3,1,-6,0)
Block(3,1,-5,0)
Block(3,2,-7,0)
Block(3,2,-6,0)
Block(3,2,-5,0)
Block(3,2,-4,0)
Block(3,2,-3,0)
Block(3,3,-7,0)
Block(3,3,-6,0)
Block(3,3,-5,0)
Block(3,3,-4,0)
Block(3,3,-3,0)
Block(3,3,-2,0)
Block(3,4,-7,97:2)
Block(3,4,-6,97:2)
Block(3,4,-5,97:2)
Block(3,4,-4,97:2)
Block(3,4,-3,98:1)
Block(3,4,-2,98:1)
Block(3,4,-1,98:2)
Block(3,4,0,97:2)
Block(3,4,1,97:2)
Block(3,4,2,97:2)
Block(3,4,3,97:2)
Block(3,4,4,97:2)
Block(3,4,5,97:2)
Block(3,4,6,97:2)
Block(3,4,7,98:1)
Block(3,5,-7,97:2)
Block(3,5,-6,97:2)
Block(3,5,-5,98:1)
Block(3,5,-4,98:1)
Block(3,5,-3,97:2)
Block(3,5,-2,97:2)
Block(3,5,-1,97:2)
Block(3,5,0,97:2)
Block(3,5,1,97:2)
Block(3,5,2,97:2)
Block(3,5,3,97:2)
Block(3,5,4,97:2)
Block(3,5,5,97:2)
Block(3,5,6,97:2)
Block(3,5,7,97:2)
Block(3,6,-7,97:2)
Block(3,6,-6,98:1)
Block(3,6,-5,97:2)
Block(3,6,-4,98:2)
Block(3,6,-3,97:2)
Block(3,6,-2,97:2)
Block(3,6,-1,97:2)
Block(3,6,0,97:2)
Block(3,6,1,98:2)
Block(3,6,2,97:2)
Block(3,6,3,97:2)
Block(3,6,4,97:2)
Block(3,6,5,65:4)
Block(3,6,6,97:2)
Block(3,6,7,97:2)
Block(3,7,-7,97:2)
Block(3,7,-6,97:2)
Block(3,7,-5,97:2)
Block(3,7,-4,97:2)
Block(3,7,-3,97:2)
Block(3,7,-2,98:1)
Block(3,7,-1,98:2)
Block(3,7,0,98:1)
Block(3,7,1,97:2)
Block(3,7,2,97:2)
Block(3,7,3,98:2)
Block(3,7,4,97:2)
Block(3,7,5,65:4)
Block(3,7,6,97:2)
Block(3,7,7,97:2)
Block(3,8,-7,97:2)
Block(3,8,-6,97:2)
Block(3,8,-5,97:2)
Block(3,8,-4,98:1)
Block(3,8,-3,97:2)
Block(3,8,-2,97:2)
Block(3,8,-1,97:2)
Block(3,8,0,97:2)
Block(3,8,1,98:1)
Block(3,8,2,98:1)
Block(3,8,3,97:2)
Block(3,8,4,98:1)
Block(3,8,5,65:4)
Block(3,8,6,97:2)
Block(3,8,7,97:2)
Block(3,9,-7,132:4)
Block(3,9,-6,132:4)
Block(3,9,-5,132:4)
Block(3,9,-4,132:4)
Block(3,9,-3,131:6)
Block(3,9,-2,97:2)
Block(3,9,-1,97:2)
Block(3,9,0,98:2)
Block(3,9,1,0)
Block(3,9,2,0)
Block(3,9,3,0)
Block(3,9,4,98:2)
Block(3,9,5,65:4)
Block(3,9,6,98:2)
Block(3,9,7,97:2)
Block(3,10,-7,0)
Block(3,10,-6,0)
Block(3,10,-5,0)
Block(3,10,-4,0)
Block(3,10,-3,0)
Block(3,10,-2,23:2,../../nbt/dispenserArrows.nbt,100)
Block(3,10,-1,97:2)
Block(3,10,0,97:2)
Block(3,10,1,0)
Block(3,10,2,0)
Block(3,10,3,0)
Block(3,10,4,97:2)
Block(3,10,5,65:4)
Block(3,10,6,97:2)
Block(3,10,7,98:1)
Block(3,11,-7,97:2)
Block(3,11,-6,97:2)
Block(3,11,-5,98:1)
Block(3,11,-4,98:2)
Block(3,11,-3,98:2)
Block(3,11,-2,98:2)
Block(3,11,-1,97:2)
Block(3,11,0,97:2)
Block(3,11,1,97:2)
Block(3,11,2,98:1)
Block(3,11,3,98:2)
Block(3,11,4,98:2)
Block(3,11,5,65:4)
Block(3,11,6,97:2)
Block(3,11,7,98:1)
Block(3,12,-7,0)
Block(3,12,-6,0)
Block(3,12,-5,0)
Block(3,12,-4,0)
Block(3,12,-3,0)
Block(3,12,-2,0)
Block(3,12,-1,0)
Block(3,12,0,0)
Block(3,12,1,0)
Block(3,12,2,97:2)
Block(3,12,3,0)
Block(3,12,4,97:2)
Block(3,12,5,0)
Block(3,12,6,97:2)
Block(3,12,7,97:2)
Block(3,13,-7,0)
Block(3,13,-6,0)
Block(3,13,-5,0)
Block(3,13,-4,0)
Block(3,13,-3,0)
Block(3,13,-2,0)
Block(3,13,-1,0)
Block(3,13,0,0)
Block(3,13,1,0)
Block(3,13,2,98:2)
Block(3,13,3,0)
Block(3,13,4,98:2)
Block(3,13,5,0)
Block(3,13,6,97:2)
Block(3,13,7,97:2)
Block(3,14,-7,98:2)
Block(3,14,-6,98:1)
Block(3,14,-5,98:1)
Block(3,14,-4,97:2)
Block(3,14,-3,97:2)
Block(3,14,-2,97:2)
Block(3,14,-1,97:2)
Block(3,14,0,97:2)
Block(3,14,1,97:2)
Block(3,14,2,97:2)
Block(3,14,3,98:1)
Block(3,14,4,97:2)
Block(3,14,5,98:1)
Block(3,14,6,98:2)
Block(3,14,7,97:2)
Block(3,15,-7,98:2)
Block(3,15,-6,98:1)
Block(3,15,-5,98:2)
Block(3,15,-4,98:1)
Block(3,15,-3,98:2)
Block(3,15,-2,97:2)
Block(3,15,-1,97:2)
Block(3,15,0,97:2)
Block(3,15,1,98:1)
Block(3,15,2,97:2)
Block(3,15,3,97:2)
Block(3,15,4,97:2)
Block(3,15,5,97:2)
Block(3,15,6,97:2)
Block(3,15,7,97:2)
Block(4,0,-7,0)
Block(4,1,-7,0)
Block(4,1,-6,0)
Block(4,1,-5,0)
Block(4,2,-7,0)
Block(4,2,-6,0)
Block(4,2,-5,0)
Block(4,2,-4,0)
Block(4,2,-3,0)
Block(4,3,-7,0)
Block(4,3,-6,0)
Block(4,3,-5,0)
Block(4,3,-4,0)
Block(4,3,-3,0)
Block(4,3,-2,0)
Block(4,4,-7,97:2)
Block(4,4,-6,97:2)
Block(4,4,-5,98:2)
Block(4,4,-4,98:2)
Block(4,4,-3,97:2)
Block(4,4,-2,98:1)
Block(4,4,-1,97:2)
Block(4,4,0,97:2)
Block(4,4,1,97:2)
Block(4,4,2,97:2)
Block(4,4,3,97:2)
Block(4,4,4,97:2)
Block(4,4,5,97:2)
Block(4,4,6,97:2)
Block(4,4,7,97:2)
Block(4,5,-7,97:2)
Block(4,5,-6,97:2)
Block(4,5,-5,97:2)
Block(4,5,-4,97:2)
Block(4,5,-3,97:2)
Block(4,5,-2,97:2)
Block(4,5,-1,97:2)
Block(4,5,0,97:2)
Block(4,5,1,97:2)
Block(4,5,2,97:2)
Block(4,5,3,97:2)
Block(4,5,4,97:2)
Block(4,5,5,97:2)
Block(4,5,6,98:1)
Block(4,5,7,97:2)
Block(4,6,-7,97:2)
Block(4,6,-6,97:2)
Block(4,6,-5,97:2)
Block(4,6,-4,98:2)
Block(4,6,-3,97:2)
Block(4,6,-2,97:2)
Block(4,6,-1,97:2)
Block(4,6,0,97:2)
Block(4,6,1,97:2)
Block(4,6,2,97:2)
Block(4,6,3,97:2)
Block(4,6,4,97:2)
Block(4,6,5,97:2)
Block(4,6,6,97:2)
Block(4,6,7,97:2)
Block(4,7,-7,98:1)
Block(4,7,-6,97:2)
Block(4,7,-5,98:2)
Block(4,7,-4,98:2)
Block(4,7,-3,97:2)
Block(4,7,-2,97:2)
Block(4,7,-1,98:1)
Block(4,7,0,97:2)
Block(4,7,1,97:2)
Block(4,7,2,97:2)
Block(4,7,3,97:2)
Block(4,7,4,97:2)
Block(4,7,5,97:2)
Block(4,7,6,97:2)
Block(4,7,7,97:2)
Block(4,8,-7,98:2)
Block(4,8,-6,98:1)
Block(4,8,-5,97:2)
Block(4,8,-4,97:2)
Block(4,8,-3,97:2)
Block(4,8,-2,98:1)
Block(4,8,-1,98:2)
Block(4,8,0,97:2)
Block(4,8,1,97:2)
Block(4,8,2,97:2)
Block(4,8,3,97:2)
Block(4,8,4,97:2)
Block(4,8,5,97:2)
Block(4,8,6,97:2)
Block(4,8,7,97:2)
Block(4,9,-7,97:2)
Block(4,9,-6,97:2)
Block(4,9,-5,98:2)
Block(4,9,-4,98:2)
Block(4,9,-3,97:2)
Block(4,9,-2,97:2)
Block(4,9,-1,97:2)
Block(4,9,0,97:2)
Block(4,9,1,98:1)
Block(4,9,2,97:2)
Block(4,9,3,97:2)
Block(4,9,4,97:2)
Block(4,9,5,97:2)
Block(4,9,6,97:2)
Block(4,9,7,97:2)
Block(4,10,-7,97:2)
Block(4,10,-6,97:2)
Block(4,10,-5,97:2)
Block(4,10,-4,97:2)
Block(4,10,-3,97:2)
Block(4,10,-2,98:1)
Block(4,10,-1,97:2)
Block(4,10,0,97:2)
Block(4,10,1,97:2)
Block(4,10,2,98:1)
Block(4,10,3,97:2)
Block(4,10,4,97:2)
Block(4,10,5,97:2)
Block(4,10,6,98:2)
Block(4,10,7,97:2)
Block(4,11,-7,97:2)
Block(4,11,-6,97:2)
Block(4,11,-5,97:2)
Block(4,11,-4,97:2)
Block(4,11,-3,97:2)
Block(4,11,-2,97:2)
Block(4,11,-1,98:1)
Block(4,11,0,98:1)
Block(4,11,1,98:2)
Block(4,11,2,97:2)
Block(4,11,3,98:1)
Block(4,11,4,98:2)
Block(4,11,5,98:2)
Block(4,11,6,97:2)
Block(4,11,7,97:2)
Block(4,12,-7,98:2)
Block(4,12,-6,98:1)
Block(4,12,-5,97:2)
Block(4,12,-4,98:1)
Block(4,12,-3,97:2)
Block(4,12,-2,97:2)
Block(4,12,-1,97:2)
Block(4,12,0,97:2)
Block(4,12,1,97:2)
Block(4,12,2,98:1)
Block(4,12,3,97:2)
Block(4,12,4,97:2)
Block(4,12,5,97:2)
Block(4,12,6,98:2)
Block(4,12,7,97:2)
Block(4,13,-7,98:1)
Block(4,13,-6,97:2)
Block(4,13,-5,98:1)
Block(4,13,-4,97:2)
Block(4,13,-3,98:2)
Block(4,13,-2,97:2)
Block(4,13,-1,97:2)
Block(4,13,0,98:2)
Block(4,13,1,98:1)
Block(4,13,2,98:1)
Block(4,13,3,97:2)
Block(4,13,4,97:2)
Block(4,13,5,97:2)
Block(4,13,6,97:2)
Block(4,13,7,97:2)
Block(4,14,-7,98:1)
Block(4,14,-6,98:1)
Block(4,14,-5,97:2)
Block(4,14,-4,97:2)
Block(4,14,-3,97:2)
Block(4,14,-2,97:2)
Block(4,14,-1,97:2)
Block(4,14,0,98:2)
Block(4,14,1,97:2)
Block(4,14,2,97:2)
Block(4,14,3,97:2)
Block(4,14,4,97:2)
Block(4,14,5,98:2)
Block(4,14,6,97:2)
Block(4,14,7,98:2)
Block(4,15,-7,97:2)
Block(4,15,-6,97:2)
Block(4,15,-5,97:2)
Block(4,15,-4,97:2)
Block(4,15,-3,97:2)
Block(4,15,-2,98:1)
Block(4,15,-1,97:2)
Block(4,15,0,97:2)
Block(4,15,1,97:2)
Block(4,15,2,97:2)
Block(4,15,3,98:1)
Block(4,15,4,97:2)
Block(4,15,5,98:2)
Block(4,15,6,97:2)
Block(4,15,7,97:2)
Block(5,1,-7,0)
Block(5,1,-6,0)
Block(5,2,-7,0)
Block(5,2,-6,0)
Block(5,2,-5,0)
Block(5,2,-4,0)
Block(5,2,-3,0)
Block(5,3,-7,0)
Block(5,3,-6,0)
Block(5,3,-5,0)
Block(5,3,-4,0)
Block(5,3,-3,0)
Block(5,3,-2,0)
Block(5,4,-7,97:2)
Block(5,4,-6,97:2)
Block(5,4,-5,97:2)
Block(5,4,-4,97:2)
Block(5,4,-3,97:2)
Block(5,4,-2,97:2)
Block(5,4,-1,97:2)
Block(5,4,0,97:2)
Block(5,4,1,97:2)
Block(5,4,2,97:2)
Block(5,4,3,97:2)
Block(5,4,4,97:2)
Block(5,4,5,97:2)
Block(5,4,6,97:2)
Block(5,4,7,97:2)
Block(5,5,-7,98:2)
Block(5,5,-6,98:2)
Block(5,5,-5,97:2)
Block(5,5,-4,98:2)
Block(5,5,-3,97:2)
Block(5,5,-2,97:2)
Block(5,5,-1,97:2)
Block(5,5,0,97:2)
Block(5,5,1,98:1)
Block(5,5,2,97:2)
Block(5,5,3,97:2)
Block(5,5,4,97:2)
Block(5,5,5,97:2)
Block(5,5,6,97:2)
Block(5,5,7,97:2)
Block(5,6,-7,97:2)
Block(5,6,-6,97:2)
Block(5,6,-5,97:2)
Block(5,6,-4,97:2)
Block(5,6,-3,97:2)
Block(5,6,-2,97:2)
Block(5,6,-1,98:1)
Block(5,6,0,97:2)
Block(5,6,1,97:2)
Block(5,6,2,97:2)
Block(5,6,3,97:2)
Block(5,6,4,97:2)
Block(5,6,5,97:2)
Block(5,6,6,97:2)
Block(5,6,7,97:2)
Block(5,7,-7,98:1)
Block(5,7,-6,97:2)
Block(5,7,-5,97:2)
Block(5,7,-4,97:2)
Block(5,7,-3,98:1)
Block(5,7,-2,98:2)
Block(5,7,-1,97:2)
Block(5,7,0,97:2)
Block(5,7,1,97:2)
Block(5,7,2,97:2)
Block(5,7,3,97:2)
Block(5,7,4,97:2)
Block(5,7,5,98:2)
Block(5,7,6,97:2)
Block(5,7,7,98:1)
Block(5,8,-7,97:2)
Block(5,8,-6,97:2)
Block(5,8,-5,97:2)
Block(5,8,-4,98:2)
Block(5,8,-3,97:2)
Block(5,8,-2,97:2)
Block(5,8,-1,97:2)
Block(5,8,0,97:2)
Block(5,8,1,97:2)
Block(5,8,2,97:2)
Block(5,8,3,97:2)
Block(5,8,4,97:2)
Block(5,8,5,98:1)
Block(5,8,6,98:1)
Block(5,8,7,97:2)
Block(5,9,-7,98:1)
Block(5,9,-6,97:2)
Block(5,9,-5,98:1)
Block(5,9,-4,98:2)
Block(5,9,-3,97:2)
Block(5,9,-2,97:2)
Block(5,9,-1,97:2)
Block(5,9,0,97:2)
Block(5,9,1,97:2)
Block(5,9,2,98:2)
Block(5,9,3,98:1)
Block(5,9,4,97:2)
Block(5,9,5,97:2)
Block(5,9,6,97:2)
Block(5,9,7,97:2)
Block(5,10,-7,97:2)
Block(5,10,-6,97:2)
Block(5,10,-5,98:2)
Block(5,10,-4,98:2)
Block(5,10,-3,97:2)
Block(5,10,-2,97:2)
Block(5,10,-1,98:1)
Block(5,10,0,97:2)
Block(5,10,1,97:2)
Block(5,10,2,98:1)
Block(5,10,3,97:2)
Block(5,10,4,98:2)
Block(5,10,5,97:2)
Block(5,10,6,97:2)
Block(5,10,7,97:2)
Block(5,11,-7,98:1)
Block(5,11,-6,97:2)
Block(5,11,-5,97:2)
Block(5,11,-4,97:2)
Block(5,11,-3,98:1)
Block(5,11,-2,98:2)
Block(5,11,-1,97:2)
Block(5,11,0,97:2)
Block(5,11,1,98:2)
Block(5,11,2,97:2)
Block(5,11,3,98:1)
Block(5,11,4,98:2)
Block(5,11,5,97:2)
Block(5,11,6,98:1)
Block(5,11,7,97:2)
Block(5,12,-7,98:1)
Block(5,12,-6,97:2)
Block(5,12,-5,97:2)
Block(5,12,-4,97:2)
Block(5,12,-3,97:2)
Block(5,12,-2,97:2)
Block(5,12,-1,97:2)
Block(5,12,0,97:2)
Block(5,12,1,98:1)
Block(5,12,2,97:2)
Block(5,12,3,97:2)
Block(5,12,4,97:2)
Block(5,12,5,98:2)
Block(5,12,6,98:2)
Block(5,12,7,97:2)
Block(5,13,-7,97:2)
Block(5,13,-6,97:2)
Block(5,13,-5,97:2)
Block(5,13,-4,97:2)
Block(5,13,-3,98:2)
Block(5,13,-2,97:2)
Block(5,13,-1,97:2)
Block(5,13,0,97:2)
Block(5,13,1,98:1)
Block(5,13,2,97:2)
Block(5,13,3,98:1)
Block(5,13,4,97:2)
Block(5,13,5,97:2)
Block(5,13,6,97:2)
Block(5,13,7,97:2)
Block(5,14,-7,97:2)
Block(5,14,-6,97:2)
Block(5,14,-5,97:2)
Block(5,14,-4,98:1)
Block(5,14,-3,97:2)
Block(5,14,-2,97:2)
Block(5,14,-1,98:1)
Block(5,14,0,98:1)
Block(5,14,1,97:2)
Block(5,14,2,97:2)
Block(5,14,3,98:1)
Block(5,14,4,98:1)
Block(5,14,5,97:2)
Block(5,14,6,97:2)
Block(5,14,7,97:2)
Block(5,15,-7,97:2)
Block(5,15,-6,97:2)
Block(5,15,-5,98:1)
Block(5,15,-4,97:2)
Block(5,15,-3,97:2)
Block(5,15,-2,97:2)
Block(5,15,-1,97:2)
Block(5,15,0,98:1)
Block(5,15,1,97:2)
Block(5,15,2,98:1)
Block(5,15,3,97:2)
Block(5,15,4,97:2)
Block(5,15,5,98:1)
Block(5,15,6,97:2)
Block(5,15,7,97:2)
Block(6,2,-7,0)
Block(6,2,-6,0)
Block(6,2,-5,0)
Block(6,2,-4,0)
Block(6,3,-7,0)
Block(6,3,-6,0)
Block(6,3,-5,0)
Block(6,3,-4,0)
Block(6,3,-3,0)
Block(6,4,-7,0)
Block(6,4,-6,0)
Block(6,4,-5,0)
Block(6,4,-4,0)
Block(6,4,-3,0)
Block(6,5,-7,0)
Block(6,5,-6,0)
Block(6,5,-5,0)
Block(6,5,-4,0)
Block(6,5,-3,0)
Block(6,6,-7,0)
Block(6,6,-6,0)
Block(6,6,-5,0)
Block(6,7,-7,0)
Block(6,7,-6,0)
Block(6,7,-5,0)
Block(6,7,-4,0)
Block(6,8,-7,0)
Block(6,8,-6,0)
Block(6,8,-5,0)
Block(6,8,-4,0)
Block(6,9,-7,0)
Block(6,9,-6,0)
Block(6,9,-5,0)
Block(6,9,-4,0)
Block(6,10,-7,0)
Block(6,10,-6,0)
Block(6,10,-5,0)
Block(7,2,-7,0)
Block(7,3,-7,0)
Block(7,7,-7,0)
Block(7,7,-6,0)
Block(7,7,-5,0)
Block(7,8,-7,0)
Block(7,8,-6,0)
Block(7,8,-5,0)
Block(7,9,-7,0)
Block(7,9,-6,0)
Block(7,9,-5,0)


#######################################################################
# +-----------------------------------------------------------------+ #
# |                             Entities                            | #
# +-----------------------------------------------------------------+ #
#######################################################################

# Entity() spawns an entity instead of a block. The entity is spawned only once when the BO3 is spawned.
# Entities are persistent by default so they don't de-spawn when no player is near, they are only unloaded.
# Usage: Entity(x,y,z,mobName,groupSize,NameTagOrNBTFileName) or Entity(x,y,z,mobName,groupSize)
# Use /tc entities or /otg entities to get a list of entities that can be used as mobName, this includes entities added by other mods.
# NameTagOrNBTFileName can be either a nametag for the mob or an nbt file (such as mymobinfo.nbt or mymobinfo.txt).
# When using a text file you can use the same mob spawning parameters used with the /summon command to equip the
# entity and give it custom attributes etc. You can copy the DATA part of a summon command including surrounding
# curly braces to a .txt file, for instance for: "/summon Skeleton x y z {DATA}"

#######################################################################
# +-----------------------------------------------------------------+ #
# |                            BO3 checks                           | #
# +-----------------------------------------------------------------+ #
#######################################################################

# Require a condition at a certain location in order for the BO3 to be spawned.
# BlockCheck(x,y,z,BlockName[,BlockName[,...]]) - one of the blocks must be at the location
# BlockCheckNot(x,y,z,BlockName[,BlockName[,...]]) - all the blocks must not be at the location
# LightCheck(x,y,z,minLightLevel,maxLightLevel) - light must be between min and max (inclusive)

# You can use "Solid" as a BlockName for matching all solid blocks or "All" to match all blocks that aren't air.

# Examples:
#   BlockCheck(0,-1,0,GRASS,DIRT)  Require grass or dirt just below the object
#   BlockCheck(0,-1,0,Solid)       Require any solid block just below the object
#   BlockCheck(0,-1,0,WOOL)        Require any type of wool just below the object
#   BlockCheck(0,-1,0,WOOL:0)      Require white wool just below the object
#   BlockCheckNot(0,-1,0,WOOL:0)   Require that there is no white wool below the object
#   LightCheck(0,0,0,0,1)          Require almost complete darkness just below the object

#######################################################################
# +-----------------------------------------------------------------+ #
# |                             Branches                            | #
# +-----------------------------------------------------------------+ #
#######################################################################

# Branches are objects that will spawn when this object spawns when it is used in
# the CustomStructure resource. Branches can also have branches, making complex
# structures possible. See the wiki for more details.

# Regular Branches spawn each branch with an independent chance of spawning.
# Branch(x,y,z,branchName,rotation,chance[,anotherBranchName,rotation,chance[,...]][IndividualChance])
# branchName - name of the object to spawn.
# rotation - NORTH, SOUTH, EAST or WEST.
# IndividualChance - The chance each branch has to spawn, assumed to be 100 when left blank

# WeightedBranch(x,y,z,branchName,rotation,chance[,anotherBranchName,rotation,chance[,...]][MaxChanceOutOf])
# MaxChanceOutOf - The chance all branches have to spawn out of, assumed to be 100 when left blank
Branch(16,0,0,CaveMazeC2R2,NORTH,100)
