#######################################################################
# +-----------------------------------------------------------------+ #
# |                            BO3 object                           | #
# +-----------------------------------------------------------------+ #
#######################################################################

# The descriptions in this file are accurate only for TerrainControl and OTG.
# For MCW and OTG+ these descriptions are only accurate if the BO3 is used as a CustomObject.
# MCW and OTG+ completely reimplemented CustomStructure, check the MCW/OTG+ documentation for more information.

# This is the config file of a custom object.
# If you add this object correctly to your BiomeConfigs, it will spawn in the world.

# This is the creator of this BO3 object
Author: DedMaxim99

# A short description of this BO3 object
Description: This BO3 was converted from a schematic using OTGEdit. The author and description information of the schematic could not be found. If you know who the author of the schematic is then please add this information.

# The BO3 version, don't change this! It can be used by external applications to do a version check.
Version: 3

# The settings mode, WriteAll, WriteWithoutComments or WriteDisable. See WorldConfig.
SettingsMode: WriteDisable

#######################################################################
# +-----------------------------------------------------------------+ #
# |                          Main settings                          | #
# +-----------------------------------------------------------------+ #
#######################################################################

# This needs to be set to true to spawn the object in the Tree and Sapling resources.
Tree: false

# The frequency of the BO3 from 1 to 200. Tries this many times to spawn this BO3 when using the CustomObject(...) resource.
# Ignored by Tree(..), Sapling(..) and CustomStructure(..)
Frequency: 40

# The rarity of the BO3 from 0 to 100. Each spawn attempt has rarity% chance to succeed when using the CustomObject(...) resource.
# Ignored by Tree(..), Sapling(..) and CustomStructure(..)
Rarity: 100.0

# If you set this to true, the BO3 will be placed with a random rotation.
RotateRandomly: false

# The spawn height of the BO3 - randomY, highestBlock or highestSolidBlock.
SpawnHeight: randomY

# The height limits for the BO3.
MinHeight: 92

MaxHeight: 94

# Objects can have other objects attached to it: branches. Branches can also
# have branches attached to it, which can also have branches, etc. This is the
# maximum branch depth for this objects.
MaxBranchDepth: 20

# When spawned with the UseWorld keyword, this BO3 should NOT spawn in the following biomes.
# If you writer.write the BO3 name directly in the BiomeConfigs, this will be ignored.
ExcludedBiomes: All

# To optimise this BO3 for faster loading times you can use Notepad++ to find/replace comments and abbreviate things.
# Notepad++ find/replace with regex:
# Find: ^[#;].* replace to nothing removes all lines starting with # 
# Find: ^\s*$ replace to nothing removes most empty lines 
# Notepad++ find/replace without regex:
# *Warning: This will only work for OTG 1.10.2 v21 / OTG 1.11.2 v6 or higher. B( is not recognised by lower versions.
# Find: Block( replace to B(

#######################################################################
# +-----------------------------------------------------------------+ #
# |                      Source block settings                      | #
# +-----------------------------------------------------------------+ #
#######################################################################

# The block(s) the BO3 should spawn in.
SourceBlocks: AIR

# The maximum percentage of the BO3 that can be outside the SourceBlock.
# The BO3 won't be placed on a location with more blocks outside the SourceBlock than this percentage.
MaxPercentageOutsideSourceBlock: 100

# What to do when a block is about to be placed outside the SourceBlock? (dontPlace, placeAnyway)
OutsideSourceBlock: placeAnyway

#######################################################################
# +-----------------------------------------------------------------+ #
# |                              Blocks                             | #
# +-----------------------------------------------------------------+ #
#######################################################################

# All the blocks used in the BO3 are listed here. Possible blocks:
# Block(x,y,z,id[.data][,nbtfile.nbt) or B(x,y,z,id[.data][,nbtfile.nbt)
# RandomBlock(x,y,z,id[:data][,nbtfile.nbt],chance[,id[:data][,nbtfile.nbt],chance[,...]])
# So RandomBlock(0,0,0,CHEST,chest.nbt,50,CHEST,anotherchest.nbt,100) will spawn a chest at
# the BO3 origin, and give it a 50% chance to have the contents of chest.nbt, or, if that
# fails, a 100% percent chance to have the contents of anotherchest.nbt.

Block(-8,0,-3,168:1)
Block(-8,0,-2,168:1)
Block(-8,0,-1,168:1)
Block(-8,0,0,168:1)
Block(-8,0,6,168:1)
Block(-8,0,7,168:1)
Block(-8,0,8,168:1)
Block(-8,1,-3,168:1)
Block(-8,1,-2,168:1)
Block(-8,1,-1,168:1)
Block(-8,1,0,168:1)
Block(-8,1,6,168:1)
Block(-8,1,7,168:1)
Block(-8,1,8,168:1)
Block(-8,2,-3,168:1)
Block(-8,2,-2,168:1)
Block(-8,2,-1,168:1)
Block(-8,2,0,168:1)
Block(-8,2,6,168:1)
Block(-8,2,7,168:1)
Block(-8,2,8,168:1)
Block(-8,3,-3,168:1)
Block(-8,3,-2,168:1)
Block(-8,3,-1,168:1)
Block(-8,3,0,168:1)
Block(-8,3,6,168:1)
Block(-8,3,7,168:1)
Block(-8,3,8,168:1)
Block(-8,4,-3,168:1)
Block(-8,4,-2,168:1)
Block(-8,4,-1,168:1)
Block(-8,4,0,168:1)
Block(-8,4,6,168:1)
Block(-8,4,7,168:1)
Block(-8,4,8,168:1)
Block(-8,5,-3,168:1)
Block(-8,5,-2,168:1)
Block(-8,5,-1,168:1)
Block(-8,5,0,168:1)
Block(-8,5,6,168:1)
Block(-8,5,7,168:1)
Block(-8,5,8,168:1)
Block(-8,6,-3,168:1)
Block(-8,6,-2,168:1)
Block(-8,6,-1,168:1)
Block(-8,6,0,168:1)
Block(-8,6,6,168:1)
Block(-8,6,7,168:1)
Block(-8,6,8,168:1)
Block(-8,7,-3,168:1)
Block(-8,7,-2,168:1)
Block(-8,7,-1,168:1)
Block(-8,7,0,168:1)
Block(-8,7,6,168:1)
Block(-8,7,7,168:1)
Block(-8,7,8,168:1)
Block(-8,8,-3,168:1)
Block(-8,8,-2,168:1)
Block(-8,8,-1,168:1)
Block(-8,8,0,168:1)
Block(-8,8,6,168:1)
Block(-8,8,7,168:1)
Block(-8,8,8,168:1)
Block(-8,9,-3,168:1)
Block(-8,9,-2,168:1)
Block(-8,9,-1,168:1)
Block(-8,9,0,168:1)
Block(-8,9,6,168:1)
Block(-8,9,7,168:1)
Block(-8,9,8,168:1)
Block(-8,10,-3,168:1)
Block(-8,10,-2,168:1)
Block(-8,10,-1,168:1)
Block(-8,10,0,168:1)
Block(-8,10,6,168:1)
Block(-8,10,7,168:1)
Block(-8,10,8,168:1)
Block(-8,11,-7,168)
Block(-8,11,-6,168)
Block(-8,11,-5,168)
Block(-8,11,-4,168)
Block(-8,11,-3,168:1)
Block(-8,11,-2,168:1)
Block(-8,11,-1,168:1)
Block(-8,11,0,168:1)
Block(-8,11,1,168)
Block(-8,11,2,168)
Block(-8,11,3,168)
Block(-8,11,4,168)
Block(-8,11,5,168)
Block(-8,11,6,168:1)
Block(-8,11,7,168:1)
Block(-8,11,8,168:1)
Block(-8,12,-7,168:1)
Block(-8,12,-6,168:1)
Block(-8,12,-5,168:1)
Block(-8,12,-4,168:1)
Block(-8,12,-3,168:1)
Block(-8,12,-2,168:1)
Block(-8,12,-1,168:1)
Block(-8,12,0,168:1)
Block(-8,12,1,168:1)
Block(-8,12,2,168:1)
Block(-8,12,3,168:1)
Block(-8,12,4,168:1)
Block(-8,12,5,168:1)
Block(-8,12,6,168:1)
Block(-8,12,7,168:1)
Block(-8,12,8,168:1)
Block(-7,0,-3,168:1)
Block(-7,0,-2,168:1)
Block(-7,0,-1,168:1)
Block(-7,0,0,168:1)
Block(-7,0,6,168:1)
Block(-7,0,7,168:1)
Block(-7,0,8,168:1)
Block(-7,1,-3,168:1)
Block(-7,1,-2,168:1)
Block(-7,1,-1,168:1)
Block(-7,1,0,168:1)
Block(-7,1,6,168:1)
Block(-7,1,7,168:1)
Block(-7,1,8,168:1)
Block(-7,2,-3,168:1)
Block(-7,2,-2,168:1)
Block(-7,2,-1,168:1)
Block(-7,2,0,168:1)
Block(-7,2,6,168:1)
Block(-7,2,7,168:1)
Block(-7,2,8,168:1)
Block(-7,3,-3,168:1)
Block(-7,3,-2,168:1)
Block(-7,3,-1,168:1)
Block(-7,3,0,168:1)
Block(-7,3,6,168:1)
Block(-7,3,7,168:1)
Block(-7,3,8,168:1)
Block(-7,4,-3,168:1)
Block(-7,4,-2,168:1)
Block(-7,4,-1,168:1)
Block(-7,4,0,168:1)
Block(-7,4,6,168:1)
Block(-7,4,7,168:1)
Block(-7,4,8,168:1)
Block(-7,5,-3,168:1)
Block(-7,5,-2,168:1)
Block(-7,5,-1,168:1)
Block(-7,5,0,168:1)
Block(-7,5,6,168:1)
Block(-7,5,7,168:1)
Block(-7,5,8,168:1)
Block(-7,6,-3,168:1)
Block(-7,6,-2,168:1)
Block(-7,6,-1,168:1)
Block(-7,6,0,168:1)
Block(-7,6,6,168:1)
Block(-7,6,7,168:1)
Block(-7,6,8,168:1)
Block(-7,7,-3,168:1)
Block(-7,7,-2,168:1)
Block(-7,7,-1,168:1)
Block(-7,7,0,168:1)
Block(-7,7,6,168:1)
Block(-7,7,7,168:1)
Block(-7,7,8,168:1)
Block(-7,8,-3,168:1)
Block(-7,8,-2,168:1)
Block(-7,8,-1,168:1)
Block(-7,8,0,168:1)
Block(-7,8,6,168:1)
Block(-7,8,7,168:1)
Block(-7,8,8,168:1)
Block(-7,9,-3,168:1)
Block(-7,9,-2,168:1)
Block(-7,9,-1,168:1)
Block(-7,9,0,168:1)
Block(-7,9,6,168:1)
Block(-7,9,7,168:1)
Block(-7,9,8,168:1)
Block(-7,10,-3,168:1)
Block(-7,10,-2,168:1)
Block(-7,10,-1,168:1)
Block(-7,10,0,168:1)
Block(-7,10,6,168:1)
Block(-7,10,7,168:1)
Block(-7,10,8,168:1)
Block(-7,11,-7,168)
Block(-7,11,-6,168)
Block(-7,11,-5,168)
Block(-7,11,-4,168)
Block(-7,11,-3,168:1)
Block(-7,11,-2,168:1)
Block(-7,11,-1,168:1)
Block(-7,11,0,168:1)
Block(-7,11,1,168)
Block(-7,11,2,168)
Block(-7,11,3,168)
Block(-7,11,4,168)
Block(-7,11,5,168)
Block(-7,11,6,168:1)
Block(-7,11,7,168:1)
Block(-7,11,8,168:1)
Block(-7,13,-7,168:1)
Block(-7,13,-6,168:1)
Block(-7,13,-5,168:1)
Block(-7,13,-4,168:1)
Block(-7,13,-3,168:1)
Block(-7,13,-2,168:1)
Block(-7,13,-1,168:1)
Block(-7,13,0,168:1)
Block(-7,13,1,168:1)
Block(-7,13,2,168:1)
Block(-7,13,3,168:1)
Block(-7,13,4,168:1)
Block(-7,13,5,168:1)
Block(-7,13,6,168:1)
Block(-7,13,7,168:1)
Block(-7,13,8,168:1)
Block(-6,0,-3,168:1)
Block(-6,0,-2,168:1)
Block(-6,0,-1,168:1)
Block(-6,0,0,168:1)
Block(-6,0,6,168:1)
Block(-6,0,7,168:1)
Block(-6,0,8,168:1)
Block(-6,1,-3,168:1)
Block(-6,1,-2,168:1)
Block(-6,1,-1,168:1)
Block(-6,1,0,168:1)
Block(-6,1,6,168:1)
Block(-6,1,7,168:1)
Block(-6,1,8,168:1)
Block(-6,2,-3,168:1)
Block(-6,2,-2,168:1)
Block(-6,2,-1,168:1)
Block(-6,2,0,168:1)
Block(-6,2,6,168:1)
Block(-6,2,7,168:1)
Block(-6,2,8,168:1)
Block(-6,3,-3,168:1)
Block(-6,3,-2,168:1)
Block(-6,3,-1,168:1)
Block(-6,3,0,168:1)
Block(-6,3,6,168:1)
Block(-6,3,7,168:1)
Block(-6,3,8,168:1)
Block(-6,4,-3,168:1)
Block(-6,4,-2,168:1)
Block(-6,4,-1,168:1)
Block(-6,4,0,168:1)
Block(-6,4,6,168:1)
Block(-6,4,7,168:1)
Block(-6,4,8,168:1)
Block(-6,5,-3,168:1)
Block(-6,5,-2,168:1)
Block(-6,5,-1,168:1)
Block(-6,5,0,168:1)
Block(-6,5,6,168:1)
Block(-6,5,7,168:1)
Block(-6,5,8,168:1)
Block(-6,6,-3,168:1)
Block(-6,6,-2,168:1)
Block(-6,6,-1,168:1)
Block(-6,6,0,168:1)
Block(-6,6,6,168:1)
Block(-6,6,7,168:1)
Block(-6,6,8,168:1)
Block(-6,7,-3,168:1)
Block(-6,7,-2,168:1)
Block(-6,7,-1,168:1)
Block(-6,7,0,168:1)
Block(-6,7,6,168:1)
Block(-6,7,7,168:1)
Block(-6,7,8,168:1)
Block(-6,8,-3,168:1)
Block(-6,8,-2,168:1)
Block(-6,8,-1,168:1)
Block(-6,8,0,168:1)
Block(-6,8,6,168:1)
Block(-6,8,7,168:1)
Block(-6,8,8,168:1)
Block(-6,9,-3,168:1)
Block(-6,9,-2,168:1)
Block(-6,9,-1,168:1)
Block(-6,9,0,168:1)
Block(-6,9,6,168:1)
Block(-6,9,7,168:1)
Block(-6,9,8,168:1)
Block(-6,10,-3,168:1)
Block(-6,10,-2,168:1)
Block(-6,10,-1,168:1)
Block(-6,10,0,168:1)
Block(-6,10,6,168:1)
Block(-6,10,7,168:1)
Block(-6,10,8,168:1)
Block(-6,11,-7,168)
Block(-6,11,-6,168)
Block(-6,11,-5,168)
Block(-6,11,-4,168)
Block(-6,11,-3,168:1)
Block(-6,11,-2,168:1)
Block(-6,11,-1,168:1)
Block(-6,11,0,168:1)
Block(-6,11,1,168)
Block(-6,11,2,168)
Block(-6,11,3,168)
Block(-6,11,4,168)
Block(-6,11,5,168)
Block(-6,11,6,168:1)
Block(-6,11,7,168:1)
Block(-6,11,8,168:1)
Block(-6,14,-7,168:1)
Block(-6,14,-6,168:1)
Block(-6,14,-5,168:1)
Block(-6,14,-4,168:1)
Block(-6,14,-3,168:1)
Block(-6,14,-2,168:1)
Block(-6,14,-1,168:1)
Block(-6,14,0,168:1)
Block(-6,14,1,168:1)
Block(-6,14,2,168:1)
Block(-6,14,3,168:1)
Block(-6,14,4,168:1)
Block(-6,14,5,168:1)
Block(-6,14,6,168:1)
Block(-6,14,7,168:1)
Block(-6,14,8,168:1)
Block(-5,0,-3,168:1)
Block(-5,0,-2,168:1)
Block(-5,0,-1,168:1)
Block(-5,0,0,168:1)
Block(-5,0,6,168:1)
Block(-5,0,7,168:1)
Block(-5,0,8,168:1)
Block(-5,1,-3,168:1)
Block(-5,1,-2,168:1)
Block(-5,1,-1,168:1)
Block(-5,1,0,168:1)
Block(-5,1,6,168:1)
Block(-5,1,7,168:1)
Block(-5,1,8,168:1)
Block(-5,2,-3,168:1)
Block(-5,2,-2,168:1)
Block(-5,2,-1,168:1)
Block(-5,2,0,168:1)
Block(-5,2,6,168:1)
Block(-5,2,7,168:1)
Block(-5,2,8,168:1)
Block(-5,3,-3,168:1)
Block(-5,3,-2,168:1)
Block(-5,3,-1,168:1)
Block(-5,3,0,168:1)
Block(-5,3,6,168:1)
Block(-5,3,7,168:1)
Block(-5,3,8,168:1)
Block(-5,4,-3,168:1)
Block(-5,4,-2,168:1)
Block(-5,4,-1,168:1)
Block(-5,4,0,168:1)
Block(-5,4,6,168:1)
Block(-5,4,7,168:1)
Block(-5,4,8,168:1)
Block(-5,5,-3,168:1)
Block(-5,5,-2,168:1)
Block(-5,5,-1,168:1)
Block(-5,5,0,168:1)
Block(-5,5,6,168:1)
Block(-5,5,7,168:1)
Block(-5,5,8,168:1)
Block(-5,6,-3,168:1)
Block(-5,6,-2,168:1)
Block(-5,6,-1,168:1)
Block(-5,6,0,168:1)
Block(-5,6,6,168:1)
Block(-5,6,7,168:1)
Block(-5,6,8,168:1)
Block(-5,7,-3,168:1)
Block(-5,7,-2,168:1)
Block(-5,7,-1,168:1)
Block(-5,7,0,168:1)
Block(-5,7,6,168:1)
Block(-5,7,7,168:1)
Block(-5,7,8,168:1)
Block(-5,8,-3,168:1)
Block(-5,8,-2,168:1)
Block(-5,8,-1,168:1)
Block(-5,8,0,168:1)
Block(-5,8,6,168:1)
Block(-5,8,7,168:1)
Block(-5,8,8,168:1)
Block(-5,9,-3,168:1)
Block(-5,9,-2,168:1)
Block(-5,9,-1,168:1)
Block(-5,9,0,168:1)
Block(-5,9,6,168:1)
Block(-5,9,7,168:1)
Block(-5,9,8,168:1)
Block(-5,10,-3,168:1)
Block(-5,10,-2,168:1)
Block(-5,10,-1,168:1)
Block(-5,10,0,168:1)
Block(-5,10,6,168:1)
Block(-5,10,7,168:1)
Block(-5,10,8,168:1)
Block(-5,11,-7,168)
Block(-5,11,-6,168)
Block(-5,11,-5,168)
Block(-5,11,-4,168)
Block(-5,11,-3,168:1)
Block(-5,11,-2,168:1)
Block(-5,11,-1,168:1)
Block(-5,11,0,168:1)
Block(-5,11,1,168)
Block(-5,11,2,168)
Block(-5,11,3,168)
Block(-5,11,4,168)
Block(-5,11,5,168)
Block(-5,11,6,168:1)
Block(-5,11,7,168:1)
Block(-5,11,8,168:1)
Block(-5,15,-7,168:1)
Block(-5,15,-6,168:1)
Block(-5,15,-5,168:1)
Block(-5,15,-4,168:1)
Block(-5,15,-3,168:1)
Block(-5,15,-2,168:1)
Block(-5,15,-1,168:1)
Block(-5,15,0,168:1)
Block(-5,15,1,168:1)
Block(-5,15,2,168:1)
Block(-5,15,3,168:1)
Block(-5,15,4,168:1)
Block(-5,15,5,168:1)
Block(-5,15,6,168:1)
Block(-5,15,7,168:1)
Block(-5,15,8,168:1)
Block(-4,11,-7,168)
Block(-4,11,-6,168)
Block(-4,11,-5,168)
Block(-4,11,-4,168)
Block(-4,11,-3,168)
Block(-4,11,-2,168)
Block(-4,11,-1,168)
Block(-4,11,0,168)
Block(-4,11,1,168)
Block(-4,11,2,168)
Block(-4,11,3,168)
Block(-4,11,4,168)
Block(-4,11,5,168)
Block(-4,11,6,168)
Block(-4,11,7,168)
Block(-4,11,8,168)
Block(-4,15,-7,168)
Block(-4,15,-6,168)
Block(-4,15,-5,168)
Block(-4,15,-4,168)
Block(-4,15,-3,168)
Block(-4,15,-2,168)
Block(-4,15,-1,168)
Block(-4,15,0,168)
Block(-4,15,1,168)
Block(-4,15,2,168)
Block(-4,15,3,168)
Block(-4,15,4,168)
Block(-4,15,5,168)
Block(-4,15,6,168)
Block(-4,15,7,168)
Block(-4,15,8,168)
Block(-3,11,-7,168)
Block(-3,11,-6,168)
Block(-3,11,-5,168)
Block(-3,11,-4,168)
Block(-3,11,-3,168)
Block(-3,11,-2,168)
Block(-3,11,-1,168)
Block(-3,11,0,168)
Block(-3,11,1,168)
Block(-3,11,2,168)
Block(-3,11,3,168)
Block(-3,11,4,168)
Block(-3,11,5,168)
Block(-3,11,6,168)
Block(-3,11,7,168)
Block(-3,11,8,168)
Block(-3,12,-1,168:1)
Block(-3,13,-1,169)
Block(-3,14,-1,168:1)
Block(-3,15,-7,168)
Block(-3,15,-6,168)
Block(-3,15,-5,168)
Block(-3,15,-4,168)
Block(-3,15,-3,168)
Block(-3,15,-2,168)
Block(-3,15,-1,168)
Block(-3,15,0,168)
Block(-3,15,1,168)
Block(-3,15,2,168)
Block(-3,15,3,168)
Block(-3,15,4,168)
Block(-3,15,5,168)
Block(-3,15,6,168)
Block(-3,15,7,168)
Block(-3,15,8,168)
Block(-3,16,-5,168:1)
Block(-3,16,-2,168:1)
Block(-3,16,1,168:1)
Block(-3,16,4,168:1)
Block(-3,16,7,168:1)
Block(-2,11,-7,168)
Block(-2,11,-6,168)
Block(-2,11,-5,168)
Block(-2,11,-4,168)
Block(-2,11,-3,168)
Block(-2,11,-2,168)
Block(-2,11,-1,168)
Block(-2,11,0,168)
Block(-2,11,1,168)
Block(-2,11,2,168)
Block(-2,11,3,168)
Block(-2,11,4,168)
Block(-2,11,5,168)
Block(-2,11,6,168)
Block(-2,11,7,168)
Block(-2,11,8,168)
Block(-2,15,-7,168)
Block(-2,15,-6,168)
Block(-2,15,-5,168)
Block(-2,15,-4,168)
Block(-2,15,-3,168)
Block(-2,15,-2,168)
Block(-2,15,-1,168)
Block(-2,15,0,168)
Block(-2,15,1,168)
Block(-2,15,2,168)
Block(-2,15,3,168)
Block(-2,15,4,168)
Block(-2,15,5,168)
Block(-2,15,6,168)
Block(-2,15,7,168)
Block(-2,15,8,168)
Block(-1,11,-7,168)
Block(-1,11,-6,168)
Block(-1,11,-5,168)
Block(-1,11,-4,168)
Block(-1,11,-3,168)
Block(-1,11,-2,168)
Block(-1,11,-1,168)
Block(-1,11,0,168)
Block(-1,11,1,168)
Block(-1,11,2,168)
Block(-1,11,3,168)
Block(-1,11,4,168)
Block(-1,11,5,168)
Block(-1,11,6,168)
Block(-1,11,7,168)
Block(-1,11,8,168)
Block(-1,12,-4,168:1)
Block(-1,12,-3,168:1)
Block(-1,12,-2,168:1)
Block(-1,12,-1,168:1)
Block(-1,12,0,168:1)
Block(-1,12,1,168:1)
Block(-1,12,2,168:1)
Block(-1,12,3,168:1)
Block(-1,12,4,168:1)
Block(-1,12,5,168:1)
Block(-1,12,6,168:1)
Block(-1,12,7,168:1)
Block(-1,12,8,168:1)
Block(-1,13,-4,168:1)
Block(-1,13,-3,168:1)
Block(-1,13,-2,168:1)
Block(-1,13,-1,168:1)
Block(-1,13,0,168:1)
Block(-1,13,1,168:1)
Block(-1,13,2,168:1)
Block(-1,13,3,168:1)
Block(-1,13,4,168:1)
Block(-1,13,5,168:1)
Block(-1,13,6,168:1)
Block(-1,13,7,168:1)
Block(-1,13,8,168:1)
Block(-1,14,-4,168:1)
Block(-1,14,-3,168:1)
Block(-1,14,-2,168:1)
Block(-1,14,-1,168:1)
Block(-1,14,0,168:1)
Block(-1,14,1,168:1)
Block(-1,14,2,168:1)
Block(-1,14,3,168:1)
Block(-1,14,4,168:1)
Block(-1,14,5,168:1)
Block(-1,14,6,168:1)
Block(-1,14,7,168:1)
Block(-1,14,8,168:1)
Block(-1,15,-4,168:1)
Block(-1,15,-3,168:1)
Block(-1,15,-2,168:1)
Block(-1,15,-1,169)
Block(-1,15,0,168:1)
Block(-1,15,1,168:1)
Block(-1,15,2,169)
Block(-1,15,3,168:1)
Block(-1,15,4,168:1)
Block(-1,15,5,169)
Block(-1,15,6,168:1)
Block(-1,15,7,168:1)
Block(-1,15,8,169)
Block(-1,16,-7,168:1)
Block(-1,16,-6,168:1)
Block(-1,16,-5,168:1)
Block(-1,16,-4,168:1)
Block(-1,16,-3,168:1)
Block(-1,16,-2,168:1)
Block(-1,16,-1,168:1)
Block(-1,16,0,168:1)
Block(-1,16,1,168:1)
Block(-1,16,2,168:1)
Block(-1,16,3,168:1)
Block(-1,16,4,168:1)
Block(-1,16,5,168:1)
Block(-1,16,6,168:1)
Block(-1,16,7,168:1)
Block(-1,16,8,168:1)
Block(0,11,-7,168)
Block(0,11,-6,168)
Block(0,11,-5,168)
Block(0,11,-4,168)
Block(0,11,-3,168)
Block(0,11,-2,168)
Block(0,11,-1,168)
Block(0,11,0,168)
Block(0,11,1,168)
Block(0,11,2,168)
Block(0,11,3,168)
Block(0,11,4,168)
Block(0,11,5,168)
Block(0,11,6,168)
Block(0,11,7,168)
Block(0,11,8,168)
Block(0,12,-4,168:1)
Block(0,12,-3,168:1)
Block(0,12,-2,168:1)
Block(0,12,-1,168:1)
Block(0,12,0,168:1)
Block(0,12,1,168:1)
Block(0,12,2,168:1)
Block(0,12,3,168:1)
Block(0,12,4,168:1)
Block(0,12,5,168:1)
Block(0,12,6,168:1)
Block(0,12,7,168:1)
Block(0,12,8,168:1)
Block(0,13,-4,168:1)
Block(0,13,-3,168:1)
Block(0,13,-2,168:1)
Block(0,13,-1,168:1)
Block(0,13,0,168:1)
Block(0,13,1,168:1)
Block(0,13,2,168:1)
Block(0,13,3,168:1)
Block(0,13,4,168:1)
Block(0,13,5,168:1)
Block(0,13,6,168:1)
Block(0,13,7,168:1)
Block(0,13,8,168:1)
Block(0,14,-4,168:1)
Block(0,15,-4,168:1)
Block(0,16,-4,168:1)
Block(0,17,-7,168:1)
Block(0,17,-6,168:1)
Block(0,17,-5,168:1)
Block(0,17,-4,168:1)
Block(0,17,-3,168:1)
Block(0,17,-2,168:1)
Block(0,17,-1,168:1)
Block(0,17,0,168:1)
Block(0,17,1,168:1)
Block(0,17,2,168:1)
Block(0,17,3,168:1)
Block(0,17,4,168:1)
Block(0,17,5,168:1)
Block(0,17,6,168:1)
Block(0,17,7,168:1)
Block(0,17,8,168:1)
Block(1,11,-7,168)
Block(1,11,-6,168)
Block(1,11,-5,168)
Block(1,11,-4,168)
Block(1,11,-3,168)
Block(1,11,-2,168)
Block(1,11,-1,168)
Block(1,11,0,168)
Block(1,11,1,168)
Block(1,11,2,168)
Block(1,11,3,168)
Block(1,11,4,168)
Block(1,11,5,168)
Block(1,11,6,168)
Block(1,11,7,168)
Block(1,11,8,168)
Block(1,12,-7,168:1)
Block(1,12,-6,168:1)
Block(1,12,-5,168:1)
Block(1,12,-4,168:1)
Block(1,12,-3,168:1)
Block(1,12,-2,168:1)
Block(1,12,-1,168:1)
Block(1,12,0,168:1)
Block(1,12,1,168:1)
Block(1,12,2,168:1)
Block(1,12,3,168:1)
Block(1,12,4,168:1)
Block(1,12,5,168:2)
Block(1,12,6,168:2)
Block(1,12,7,168:2)
Block(1,12,8,168:1)
Block(1,13,-7,168)
Block(1,13,-6,168)
Block(1,13,-5,168)
Block(1,13,-4,168)
Block(1,13,-3,168:1)
Block(1,13,-2,168:1)
Block(1,13,-1,168:1)
Block(1,14,-7,168:1)
Block(1,14,-6,168:1)
Block(1,14,-5,168:1)
Block(1,14,-4,168:1)
Block(1,15,-7,168)
Block(1,15,-6,168)
Block(1,15,-5,168)
Block(1,15,-4,168)
Block(1,16,-7,168:1)
Block(1,16,-6,168:1)
Block(1,16,-5,168:1)
Block(1,16,-4,168:1)
Block(1,17,-7,168)
Block(1,17,-6,168)
Block(1,17,-5,168)
Block(1,17,-4,168:1)
Block(1,18,-7,168:1)
Block(1,18,-6,168:1)
Block(1,18,-5,168:1)
Block(1,18,-4,168:1)
Block(1,18,-3,168:1)
Block(1,18,-2,168:1)
Block(1,18,-1,168:1)
Block(1,18,0,168:1)
Block(1,18,1,168:1)
Block(1,18,2,168:1)
Block(1,18,3,168:1)
Block(1,18,4,168:1)
Block(1,18,5,168:1)
Block(1,18,6,168:1)
Block(1,18,7,168:1)
Block(1,18,8,168:1)
Block(2,11,-7,168)
Block(2,11,-6,168)
Block(2,11,-5,168)
Block(2,11,-4,168)
Block(2,11,-3,168)
Block(2,11,-2,168)
Block(2,11,-1,168)
Block(2,11,0,168)
Block(2,11,1,168)
Block(2,11,2,168)
Block(2,11,3,168)
Block(2,11,4,168)
Block(2,11,5,168)
Block(2,11,6,168)
Block(2,11,7,168)
Block(2,11,8,168)
Block(2,12,-6,168:1)
Block(2,12,-5,168:1)
Block(2,12,-4,168:1)
Block(2,12,-3,168:1)
Block(2,12,-2,168:1)
Block(2,12,-1,168:1)
Block(2,12,0,168:1)
Block(2,12,1,168:1)
Block(2,12,2,168:1)
Block(2,12,3,168:1)
Block(2,12,4,168:1)
Block(2,12,5,168:1)
Block(2,12,6,168:1)
Block(2,12,7,168:1)
Block(2,12,8,168:1)
Block(2,13,-4,168)
Block(2,13,-3,168:1)
Block(2,13,-2,168:1)
Block(2,13,-1,168:1)
Block(2,14,-6,168:1)
Block(2,14,-5,168:1)
Block(2,14,-4,168:1)
Block(2,14,-3,168:1)
Block(2,14,-2,168:1)
Block(2,15,-7,168)
Block(2,15,-6,168)
Block(2,15,-5,168)
Block(2,15,-4,168)
Block(2,16,-4,168:1)
Block(2,17,-4,168)
Block(2,18,-4,168:1)
Block(2,19,-7,168:1)
Block(2,19,-6,168:1)
Block(2,19,-5,168:1)
Block(2,19,-4,168:1)
Block(2,19,-3,168:1)
Block(2,19,-2,168:1)
Block(2,19,-1,168:1)
Block(2,19,0,168:1)
Block(2,19,1,168:1)
Block(2,19,2,168:1)
Block(2,19,3,168:1)
Block(2,19,4,168:1)
Block(2,19,5,168:1)
Block(2,19,6,168:1)
Block(2,19,7,168:1)
Block(2,19,8,168:1)
Block(3,11,-7,168)
Block(3,11,-6,168)
Block(3,11,-5,168)
Block(3,11,-4,168)
Block(3,11,-3,168)
Block(3,11,-2,168)
Block(3,11,-1,168)
Block(3,11,0,168)
Block(3,11,1,168)
Block(3,11,2,168)
Block(3,11,3,168)
Block(3,11,4,168)
Block(3,11,5,168)
Block(3,11,6,168)
Block(3,11,7,168)
Block(3,11,8,168)
Block(3,12,-4,168:1)
Block(3,12,-3,168:1)
Block(3,12,-2,168:1)
Block(3,12,-1,168:1)
Block(3,12,0,168:1)
Block(3,12,1,168:1)
Block(3,12,2,168:1)
Block(3,12,3,168:1)
Block(3,12,4,168:1)
Block(3,12,5,169)
Block(3,12,6,168:1)
Block(3,12,7,169)
Block(3,12,8,168:1)
Block(3,13,-4,168)
Block(3,13,-3,168:1)
Block(3,13,-2,168:1)
Block(3,13,-1,168:1)
Block(3,13,6,168)
Block(3,14,-4,168:1)
Block(3,14,-3,168:1)
Block(3,14,-2,168:1)
Block(3,14,6,168)
Block(3,15,-7,168)
Block(3,15,-6,168)
Block(3,15,-5,168)
Block(3,15,-4,168)
Block(3,15,-3,168:1)
Block(3,15,6,168)
Block(3,16,-6,168:1)
Block(3,16,6,168)
Block(3,17,-6,169)
Block(3,17,6,168)
Block(3,18,-6,168:1)
Block(3,18,6,168)
Block(3,19,-7,168)
Block(3,19,-6,168)
Block(3,19,-5,168)
Block(3,19,-4,168)
Block(3,19,-3,168)
Block(3,19,-2,168)
Block(3,19,-1,168)
Block(3,19,0,168)
Block(3,19,1,168)
Block(3,19,2,168)
Block(3,19,3,168)
Block(3,19,4,168)
Block(3,19,5,168)
Block(3,19,6,168)
Block(3,19,7,168)
Block(3,19,8,168:1)
Block(4,11,-7,168)
Block(4,11,-6,168)
Block(4,11,-5,168)
Block(4,11,-4,168)
Block(4,11,-3,168)
Block(4,11,-2,168)
Block(4,11,-1,168)
Block(4,11,0,168)
Block(4,11,1,168)
Block(4,11,2,168)
Block(4,11,3,168)
Block(4,11,4,168)
Block(4,11,5,168)
Block(4,11,6,168)
Block(4,11,7,168)
Block(4,11,8,168)
Block(4,12,-4,168:1)
Block(4,12,-3,168:1)
Block(4,12,-2,168:1)
Block(4,12,-1,168:1)
Block(4,12,0,168:1)
Block(4,12,1,168:1)
Block(4,12,2,168:1)
Block(4,12,3,168:1)
Block(4,12,4,168:1)
Block(4,12,5,168:1)
Block(4,12,6,168:1)
Block(4,12,7,168:1)
Block(4,12,8,168:1)
Block(4,13,-4,168)
Block(4,13,-3,168:1)
Block(4,13,-2,168:1)
Block(4,13,-1,168:1)
Block(4,13,5,168)
Block(4,13,6,168)
Block(4,13,7,168)
Block(4,14,-4,168:1)
Block(4,14,-3,168:1)
Block(4,14,-2,168:1)
Block(4,14,5,168)
Block(4,14,6,168)
Block(4,14,7,168)
Block(4,15,-7,168)
Block(4,15,-6,168)
Block(4,15,-5,168)
Block(4,15,-4,168)
Block(4,15,-3,168:1)
Block(4,15,5,168)
Block(4,15,6,168)
Block(4,15,7,168)
Block(4,16,-7,168:1)
Block(4,16,5,168)
Block(4,16,6,168)
Block(4,16,7,168)
Block(4,17,-7,168)
Block(4,17,5,168)
Block(4,17,6,168)
Block(4,17,7,168)
Block(4,18,-7,168:1)
Block(4,18,5,168)
Block(4,18,6,168)
Block(4,18,7,168)
Block(4,19,-7,168)
Block(4,19,-6,168)
Block(4,19,-5,168)
Block(4,19,-4,168)
Block(4,19,-3,168)
Block(4,19,-2,168)
Block(4,19,-1,168)
Block(4,19,0,168)
Block(4,19,1,168)
Block(4,19,2,168)
Block(4,19,3,168)
Block(4,19,4,168)
Block(4,19,5,168)
Block(4,19,6,168)
Block(4,19,7,168)
Block(4,19,8,168:1)
Block(4,20,-6,168:1)
Block(4,20,-3,168:1)
Block(4,20,0,168:1)
Block(4,20,3,168:1)
Block(4,20,6,168:1)
Block(5,11,-7,168)
Block(5,11,-6,168)
Block(5,11,-5,168)
Block(5,11,-4,168)
Block(5,11,-3,168)
Block(5,11,-2,168)
Block(5,11,-1,168)
Block(5,11,0,168)
Block(5,11,1,168)
Block(5,11,2,168)
Block(5,11,3,168)
Block(5,11,4,168)
Block(5,11,5,168)
Block(5,11,6,168)
Block(5,11,7,168)
Block(5,11,8,168)
Block(5,12,-4,168:1)
Block(5,12,-3,168:1)
Block(5,12,-2,168:1)
Block(5,12,-1,168:1)
Block(5,12,0,168:1)
Block(5,12,1,168:1)
Block(5,12,2,168:1)
Block(5,12,3,168:1)
Block(5,12,4,168:1)
Block(5,12,5,169)
Block(5,12,6,168:1)
Block(5,12,7,169)
Block(5,12,8,168:1)
Block(5,13,-4,168)
Block(5,13,-3,168:1)
Block(5,13,-2,168:1)
Block(5,13,-1,168:1)
Block(5,13,6,168)
Block(5,14,-4,168:1)
Block(5,14,-3,168:1)
Block(5,14,-2,168:1)
Block(5,14,6,168)
Block(5,15,-7,168)
Block(5,15,-6,168)
Block(5,15,-5,168)
Block(5,15,-4,168)
Block(5,15,-3,168:1)
Block(5,15,6,168)
Block(5,16,6,168)
Block(5,17,6,168)
Block(5,18,6,168)
Block(5,19,-7,168)
Block(5,19,-6,168)
Block(5,19,-5,168)
Block(5,19,-4,168)
Block(5,19,-3,168)
Block(5,19,-2,168)
Block(5,19,-1,168)
Block(5,19,0,168)
Block(5,19,1,168)
Block(5,19,2,168)
Block(5,19,3,168)
Block(5,19,4,168)
Block(5,19,5,168)
Block(5,19,6,168)
Block(5,19,7,168)
Block(5,19,8,168:1)
Block(6,11,-7,168)
Block(6,11,-6,168)
Block(6,11,-5,168)
Block(6,11,-4,168)
Block(6,11,-3,168)
Block(6,11,-2,168)
Block(6,11,-1,168)
Block(6,11,0,168)
Block(6,11,1,168)
Block(6,11,2,168)
Block(6,11,3,168)
Block(6,11,4,168)
Block(6,11,5,168)
Block(6,11,6,168)
Block(6,11,7,168)
Block(6,11,8,168)
Block(6,12,-4,168:1)
Block(6,12,-3,168:1)
Block(6,12,-2,168:1)
Block(6,12,-1,168:1)
Block(6,12,0,168:1)
Block(6,12,1,168:1)
Block(6,12,2,168:1)
Block(6,12,3,168:1)
Block(6,12,4,168:1)
Block(6,12,5,168:1)
Block(6,12,6,168:1)
Block(6,12,7,168:1)
Block(6,12,8,168:1)
Block(6,13,-4,168)
Block(6,13,-3,168:1)
Block(6,13,-2,168:1)
Block(6,13,-1,168:1)
Block(6,14,-4,168:1)
Block(6,14,-3,168:1)
Block(6,14,-2,168:1)
Block(6,15,-7,168)
Block(6,15,-6,168)
Block(6,15,-5,168)
Block(6,15,-4,168)
Block(6,16,-6,168:1)
Block(6,17,-6,169)
Block(6,18,-6,168:1)
Block(6,19,-7,168)
Block(6,19,-6,168)
Block(6,19,-5,168)
Block(6,19,-3,168:1)
Block(6,19,-2,168:1)
Block(6,19,-1,168:1)
Block(6,19,0,168:1)
Block(6,19,1,168:1)
Block(6,19,2,168:1)
Block(6,19,3,168:1)
Block(6,19,4,168:1)
Block(6,19,5,168:1)
Block(6,19,6,168:1)
Block(6,19,7,168:1)
Block(6,19,8,168:1)
Block(6,20,-7,168:1)
Block(6,20,-6,168:1)
Block(6,20,-5,168:1)
Block(6,20,-4,168:1)
Block(6,20,-3,168:1)
Block(7,11,-7,168)
Block(7,11,-6,168)
Block(7,11,-5,168)
Block(7,11,-4,168)
Block(7,11,-3,168)
Block(7,11,-2,168)
Block(7,11,-1,168)
Block(7,11,0,168)
Block(7,11,1,168)
Block(7,11,2,168)
Block(7,11,3,168)
Block(7,11,4,168)
Block(7,11,5,168)
Block(7,11,6,168)
Block(7,11,7,168)
Block(7,11,8,168)
Block(7,12,-6,168:1)
Block(7,12,-5,168:1)
Block(7,12,-4,168:1)
Block(7,12,-3,168:1)
Block(7,12,-2,168:1)
Block(7,12,-1,168:1)
Block(7,12,0,168:1)
Block(7,12,1,168:1)
Block(7,12,2,168:1)
Block(7,12,3,168:1)
Block(7,12,4,168:1)
Block(7,12,5,168:2)
Block(7,12,6,168:2)
Block(7,12,7,168:2)
Block(7,12,8,168:1)
Block(7,13,-4,168)
Block(7,13,-3,168:1)
Block(7,13,-2,168:1)
Block(7,13,-1,168:1)
Block(7,14,-6,168:1)
Block(7,14,-5,168:1)
Block(7,14,-4,168:1)
Block(7,15,-7,168)
Block(7,15,-6,168)
Block(7,15,-5,168)
Block(7,15,-4,168)
Block(7,16,-4,168:1)
Block(7,17,-4,168)
Block(7,18,-4,168:1)
Block(7,18,-3,168)
Block(7,18,-2,168:1)
Block(7,18,-1,168:1)
Block(7,18,0,168:1)
Block(7,18,1,168:1)
Block(7,18,2,168:1)
Block(7,18,3,168:1)
Block(7,18,4,168:1)
Block(7,18,5,168:1)
Block(7,18,6,168:1)
Block(7,18,7,168:1)
Block(7,18,8,168:1)
Block(7,19,-7,168)
Block(7,19,-6,168)
Block(7,19,-5,168)
Block(7,19,-3,168)
Block(7,20,-3,168)
Block(7,21,-7,168:1)
Block(7,21,-6,168:1)
Block(7,21,-5,168:1)
Block(7,21,-4,168:1)
Block(7,21,-3,168:1)


#######################################################################
# +-----------------------------------------------------------------+ #
# |                             Entities                            | #
# +-----------------------------------------------------------------+ #
#######################################################################

# Entity() spawns an entity instead of a block. The entity is spawned only once when the BO3 is spawned.
# Entities are persistent by default so they don't de-spawn when no player is near, they are only unloaded.
# Usage: Entity(x,y,z,mobName,groupSize,NameTagOrNBTFileName) or Entity(x,y,z,mobName,groupSize)
# Use /tc entities or /otg entities to get a list of entities that can be used as mobName, this includes entities added by other mods.
# NameTagOrNBTFileName can be either a nametag for the mob or an nbt file (such as mymobinfo.nbt or mymobinfo.txt).
# When using a text file you can use the same mob spawning parameters used with the /summon command to equip the
# entity and give it custom attributes etc. You can copy the DATA part of a summon command including surrounding
# curly braces to a .txt file, for instance for: "/summon Skeleton x y z {DATA}"
Entity(-4,13,6,minecraft:guardian,1)
Entity(1,14,5,minecraft:guardian,1)
Entity(1,19,8,minecraft:guardian,1)
Entity(5,17,-3,minecraft:guardian,1)
Entity(5,20,-2,minecraft:guardian,1)

#######################################################################
# +-----------------------------------------------------------------+ #
# |                            BO3 checks                           | #
# +-----------------------------------------------------------------+ #
#######################################################################

# Require a condition at a certain location in order for the BO3 to be spawned.
# BlockCheck(x,y,z,BlockName[,BlockName[,...]]) - one of the blocks must be at the location
# BlockCheckNot(x,y,z,BlockName[,BlockName[,...]]) - all the blocks must not be at the location
# LightCheck(x,y,z,minLightLevel,maxLightLevel) - light must be between min and max (inclusive)

# You can use "Solid" as a BlockName for matching all solid blocks or "All" to match all blocks that aren't air.

# Examples:
#   BlockCheck(0,-1,0,GRASS,DIRT)  Require grass or dirt just below the object
#   BlockCheck(0,-1,0,Solid)       Require any solid block just below the object
#   BlockCheck(0,-1,0,WOOL)        Require any type of wool just below the object
#   BlockCheck(0,-1,0,WOOL:0)      Require white wool just below the object
#   BlockCheckNot(0,-1,0,WOOL:0)   Require that there is no white wool below the object
#   LightCheck(0,0,0,0,1)          Require almost complete darkness just below the object

#######################################################################
# +-----------------------------------------------------------------+ #
# |                             Branches                            | #
# +-----------------------------------------------------------------+ #
#######################################################################

# Branches are objects that will spawn when this object spawns when it is used in
# the CustomStructure resource. Branches can also have branches, making complex
# structures possible. See the wiki for more details.

# Regular Branches spawn each branch with an independent chance of spawning.
# Branch(x,y,z,branchName,rotation,chance[,anotherBranchName,rotation,chance[,...]][IndividualChance])
# branchName - name of the object to spawn.
# rotation - NORTH, SOUTH, EAST or WEST.
# IndividualChance - The chance each branch has to spawn, assumed to be 100 when left blank

# WeightedBranch(x,y,z,branchName,rotation,chance[,anotherBranchName,rotation,chance[,...]][MaxChanceOutOf])
# MaxChanceOutOf - The chance all branches have to spawn out of, assumed to be 100 when left blank
Branch(16,0,0,monumentC1R2,NORTH,100)
Branch(0,0,16,monumentC0R3,NORTH,100)
