#######################################################################
# +-----------------------------------------------------------------+ #
# |                            BO3 object                           | #
# +-----------------------------------------------------------------+ #
#######################################################################

# The descriptions in this file are accurate only for TerrainControl and OTG.
# For MCW and OTG+ these descriptions are only accurate if the BO3 is used as a CustomObject.
# MCW and OTG+ completely reimplemented CustomStructure, check the MCW/OTG+ documentation for more information.

# This is the config file of a custom object.
# If you add this object correctly to your BiomeConfigs, it will spawn in the world.

# This is the creator of this BO3 object
Author: DedMaxim99

# A short description of this BO3 object
Description: This BO3 was converted from a schematic using OTGEdit. The author and description information of the schematic could not be found. If you know who the author of the schematic is then please add this information.

# The BO3 version, don't change this! It can be used by external applications to do a version check.
Version: 3

# The settings mode, WriteAll, WriteWithoutComments or WriteDisable. See WorldConfig.
SettingsMode: WriteDisable

#######################################################################
# +-----------------------------------------------------------------+ #
# |                          Main settings                          | #
# +-----------------------------------------------------------------+ #
#######################################################################

# This needs to be set to true to spawn the object in the Tree and Sapling resources.
Tree: false

# The frequency of the BO3 from 1 to 200. Tries this many times to spawn this BO3 when using the CustomObject(...) resource.
# Ignored by Tree(..), Sapling(..) and CustomStructure(..)
Frequency: 40

# The rarity of the BO3 from 0 to 100. Each spawn attempt has rarity% chance to succeed when using the CustomObject(...) resource.
# Ignored by Tree(..), Sapling(..) and CustomStructure(..)
Rarity: 100.0

# If you set this to true, the BO3 will be placed with a random rotation.
RotateRandomly: false

# The spawn height of the BO3 - randomY, highestBlock or highestSolidBlock.
SpawnHeight: randomY

# The height limits for the BO3.
MinHeight: 92

MaxHeight: 94

# Objects can have other objects attached to it: branches. Branches can also
# have branches attached to it, which can also have branches, etc. This is the
# maximum branch depth for this objects.
MaxBranchDepth: 20

# When spawned with the UseWorld keyword, this BO3 should NOT spawn in the following biomes.
# If you writer.write the BO3 name directly in the BiomeConfigs, this will be ignored.
ExcludedBiomes: All

# To optimise this BO3 for faster loading times you can use Notepad++ to find/replace comments and abbreviate things.
# Notepad++ find/replace with regex:
# Find: ^[#;].* replace to nothing removes all lines starting with # 
# Find: ^\s*$ replace to nothing removes most empty lines 
# Notepad++ find/replace without regex:
# *Warning: This will only work for OTG 1.10.2 v21 / OTG 1.11.2 v6 or higher. B( is not recognised by lower versions.
# Find: Block( replace to B(

#######################################################################
# +-----------------------------------------------------------------+ #
# |                      Source block settings                      | #
# +-----------------------------------------------------------------+ #
#######################################################################

# The block(s) the BO3 should spawn in.
SourceBlocks: AIR

# The maximum percentage of the BO3 that can be outside the SourceBlock.
# The BO3 won't be placed on a location with more blocks outside the SourceBlock than this percentage.
MaxPercentageOutsideSourceBlock: 100

# What to do when a block is about to be placed outside the SourceBlock? (dontPlace, placeAnyway)
OutsideSourceBlock: placeAnyway

#######################################################################
# +-----------------------------------------------------------------+ #
# |                              Blocks                             | #
# +-----------------------------------------------------------------+ #
#######################################################################

# All the blocks used in the BO3 are listed here. Possible blocks:
# Block(x,y,z,id[.data][,nbtfile.nbt) or B(x,y,z,id[.data][,nbtfile.nbt)
# RandomBlock(x,y,z,id[:data][,nbtfile.nbt],chance[,id[:data][,nbtfile.nbt],chance[,...]])
# So RandomBlock(0,0,0,CHEST,chest.nbt,50,CHEST,anotherchest.nbt,100) will spawn a chest at
# the BO3 origin, and give it a 50% chance to have the contents of chest.nbt, or, if that
# fails, a 100% percent chance to have the contents of anotherchest.nbt.

Block(-8,0,-7,168:1)
Block(-8,0,-6,168:1)
Block(-8,0,-5,168:1)
Block(-8,0,-4,168:1)
Block(-8,1,-7,168:1)
Block(-8,1,-6,168:1)
Block(-8,1,-5,168:1)
Block(-8,1,-4,168:1)
Block(-8,2,-7,168:1)
Block(-8,2,-6,168:1)
Block(-8,2,-5,168:1)
Block(-8,2,-4,168:1)
Block(-8,3,-7,168:1)
Block(-8,3,-6,168:1)
Block(-8,3,-5,168:1)
Block(-8,3,-4,168:1)
Block(-8,4,-7,168:1)
Block(-8,4,-6,168:1)
Block(-8,4,-5,168:1)
Block(-8,4,-4,168:1)
Block(-8,5,-7,168:1)
Block(-8,5,-6,168:1)
Block(-8,5,-5,168:1)
Block(-8,5,-4,168:1)
Block(-8,6,-7,168:1)
Block(-8,6,-6,168:1)
Block(-8,6,-5,168:1)
Block(-8,6,-4,168:1)
Block(-8,7,-7,168:1)
Block(-8,7,-6,168:1)
Block(-8,7,-5,168:1)
Block(-8,7,-4,168:1)
Block(-8,8,-7,168:1)
Block(-8,8,-6,168:1)
Block(-8,8,-5,168:1)
Block(-8,8,-4,168:1)
Block(-8,9,-7,168:1)
Block(-8,9,-6,168:1)
Block(-8,9,-5,168:1)
Block(-8,9,-4,168:1)
Block(-8,10,-7,168:1)
Block(-8,10,-6,168:1)
Block(-8,10,-5,168:1)
Block(-8,10,-4,168:1)
Block(-8,11,-7,168:1)
Block(-8,11,-6,168:1)
Block(-8,11,-5,168:1)
Block(-8,11,-4,168:1)
Block(-8,11,-3,168)
Block(-8,11,-2,168)
Block(-8,11,-1,168)
Block(-8,11,0,168)
Block(-8,11,1,168)
Block(-8,11,2,168)
Block(-8,11,3,168)
Block(-8,11,4,168)
Block(-8,11,5,168)
Block(-8,11,6,168)
Block(-8,11,7,168)
Block(-8,11,8,168)
Block(-8,12,-7,168:1)
Block(-8,12,-3,168:1)
Block(-8,12,-2,168:1)
Block(-8,12,-1,168:1)
Block(-8,12,0,168:1)
Block(-8,12,1,168:1)
Block(-8,12,2,168:1)
Block(-8,12,3,168:1)
Block(-8,12,4,168:1)
Block(-8,12,5,168:1)
Block(-8,12,6,168:1)
Block(-8,12,7,168:1)
Block(-8,12,8,168:1)
Block(-8,13,-6,168:1)
Block(-8,13,-3,168)
Block(-8,13,-2,168)
Block(-8,13,-1,168)
Block(-8,13,0,168)
Block(-8,13,1,168)
Block(-8,13,2,168)
Block(-8,13,3,168)
Block(-8,13,4,168)
Block(-8,13,5,168)
Block(-8,13,6,168)
Block(-8,13,7,168)
Block(-8,13,8,168)
Block(-8,14,-5,168:1)
Block(-8,14,-3,168:1)
Block(-8,14,-2,168:1)
Block(-8,14,-1,168:1)
Block(-8,14,0,168:1)
Block(-8,14,1,168:1)
Block(-8,14,2,168:1)
Block(-8,14,3,168:1)
Block(-8,14,4,168:1)
Block(-8,14,5,168:1)
Block(-8,14,6,168:1)
Block(-8,14,7,168:1)
Block(-8,14,8,168:1)
Block(-8,15,-4,168:1)
Block(-8,15,-3,168)
Block(-8,15,-2,168)
Block(-8,15,-1,168)
Block(-8,15,0,168)
Block(-8,15,1,168)
Block(-8,15,2,168)
Block(-8,15,3,168)
Block(-8,15,4,168)
Block(-8,15,5,168:1)
Block(-8,15,6,168:1)
Block(-8,15,7,168:1)
Block(-8,15,8,168:1)
Block(-8,16,-4,168)
Block(-8,16,-3,168:1)
Block(-8,16,-2,168:1)
Block(-8,16,-1,168:1)
Block(-8,16,0,168:1)
Block(-8,16,1,168:1)
Block(-8,16,2,168:1)
Block(-8,16,3,168:1)
Block(-8,16,4,168:1)
Block(-8,16,5,168:1)
Block(-8,16,6,168:1)
Block(-8,16,7,168:1)
Block(-8,16,8,168:1)
Block(-8,17,-4,168)
Block(-8,17,-3,168:1)
Block(-8,17,-2,168)
Block(-8,17,-1,168)
Block(-8,17,0,168)
Block(-8,17,1,168)
Block(-8,17,2,168)
Block(-8,17,3,168)
Block(-8,17,4,168:1)
Block(-8,17,5,168)
Block(-8,17,6,168)
Block(-8,17,7,168)
Block(-8,17,8,168)
Block(-8,18,-4,168:1)
Block(-8,18,-3,168:1)
Block(-8,18,-2,168:1)
Block(-8,18,-1,168:1)
Block(-8,18,0,168:1)
Block(-8,18,1,168:1)
Block(-8,18,2,168:1)
Block(-8,18,3,168:1)
Block(-8,18,4,168:1)
Block(-8,18,5,168:1)
Block(-8,18,6,168:1)
Block(-8,18,7,168:1)
Block(-8,18,8,168:1)
Block(-7,11,-7,168)
Block(-7,11,-6,168)
Block(-7,11,-5,168)
Block(-7,11,-4,168)
Block(-7,11,-3,168)
Block(-7,11,-2,168)
Block(-7,11,-1,168)
Block(-7,11,0,168)
Block(-7,11,1,168)
Block(-7,11,2,168)
Block(-7,11,3,168)
Block(-7,11,4,168)
Block(-7,11,5,168)
Block(-7,11,6,168)
Block(-7,11,7,168)
Block(-7,11,8,168)
Block(-7,12,-7,168:1)
Block(-7,13,-6,168:1)
Block(-7,14,-5,168:1)
Block(-7,15,-4,168:1)
Block(-7,16,-4,168)
Block(-7,17,-4,168:1)
Block(-7,17,-3,168:1)
Block(-7,17,-2,168:1)
Block(-7,17,-1,168:1)
Block(-7,17,0,168:1)
Block(-7,17,1,168:1)
Block(-7,17,2,168:1)
Block(-7,17,3,168:1)
Block(-7,17,4,168:1)
Block(-7,17,5,168:1)
Block(-7,17,6,168:1)
Block(-7,17,7,168:1)
Block(-7,17,8,168:1)
Block(-6,11,-7,168)
Block(-6,11,-6,168)
Block(-6,11,-5,168)
Block(-6,11,-4,168)
Block(-6,11,-3,168)
Block(-6,11,-2,168)
Block(-6,11,-1,168)
Block(-6,11,0,168)
Block(-6,11,1,168)
Block(-6,11,2,168)
Block(-6,11,3,168)
Block(-6,11,4,168)
Block(-6,11,5,168)
Block(-6,11,6,168)
Block(-6,11,7,168)
Block(-6,11,8,168)
Block(-6,12,-7,168:1)
Block(-6,13,-6,168:1)
Block(-6,14,-5,168:1)
Block(-6,15,-4,168:1)
Block(-6,16,-4,168:1)
Block(-6,16,-3,168:1)
Block(-6,16,-2,168:1)
Block(-6,16,-1,168:1)
Block(-6,16,0,168:1)
Block(-6,16,1,168:1)
Block(-6,16,2,168:1)
Block(-6,16,3,168:1)
Block(-6,16,4,168:1)
Block(-6,16,5,168:1)
Block(-6,16,6,168:1)
Block(-6,16,7,168:1)
Block(-6,16,8,168:1)
Block(-5,11,-7,168)
Block(-5,11,-6,168)
Block(-5,11,-5,168)
Block(-5,11,-4,168)
Block(-5,11,-3,168)
Block(-5,11,-2,168)
Block(-5,11,-1,168)
Block(-5,11,0,168)
Block(-5,11,1,168)
Block(-5,11,2,168)
Block(-5,11,3,168)
Block(-5,11,4,168)
Block(-5,11,5,168)
Block(-5,11,6,168)
Block(-5,11,7,168)
Block(-5,11,8,168)
Block(-5,12,-7,168:1)
Block(-5,12,-2,168)
Block(-5,13,-6,168:1)
Block(-5,13,-2,168)
Block(-5,14,-5,168:1)
Block(-5,14,-2,168)
Block(-5,15,-4,168:1)
Block(-5,15,-3,168)
Block(-5,15,-2,168)
Block(-5,15,-1,168)
Block(-5,15,0,168)
Block(-5,15,1,168)
Block(-5,15,2,168)
Block(-5,15,3,168)
Block(-5,15,4,168)
Block(-5,15,5,168)
Block(-5,15,6,168)
Block(-5,15,7,168)
Block(-5,15,8,168)
Block(-4,11,-7,168)
Block(-4,11,-6,168)
Block(-4,11,-5,168)
Block(-4,11,-4,168)
Block(-4,11,-3,168)
Block(-4,11,-2,168)
Block(-4,11,-1,168)
Block(-4,11,0,168)
Block(-4,11,1,168)
Block(-4,11,2,168)
Block(-4,11,3,168)
Block(-4,11,4,168)
Block(-4,11,5,168)
Block(-4,11,6,168)
Block(-4,11,7,168)
Block(-4,11,8,168)
Block(-4,12,-7,168:1)
Block(-4,12,-3,168)
Block(-4,12,-2,168)
Block(-4,12,-1,168)
Block(-4,13,-6,168:1)
Block(-4,13,-3,168)
Block(-4,13,-2,168)
Block(-4,13,-1,168)
Block(-4,14,-5,168:1)
Block(-4,14,-3,168)
Block(-4,14,-2,168)
Block(-4,14,-1,168)
Block(-4,15,-4,168:1)
Block(-4,15,-3,168)
Block(-4,15,-2,168)
Block(-4,15,-1,168)
Block(-4,15,1,168)
Block(-4,15,2,168)
Block(-4,15,4,168)
Block(-4,15,5,168)
Block(-4,15,7,168)
Block(-4,15,8,168)
Block(-4,16,-2,168:1)
Block(-4,16,0,168:1)
Block(-4,16,3,168:1)
Block(-4,16,6,168:1)
Block(-3,11,-7,168)
Block(-3,11,-6,168)
Block(-3,11,-5,168)
Block(-3,11,-4,168)
Block(-3,11,-3,168)
Block(-3,11,-2,168)
Block(-3,11,-1,168)
Block(-3,11,0,168)
Block(-3,11,1,168)
Block(-3,11,2,168)
Block(-3,11,3,168)
Block(-3,11,4,168)
Block(-3,11,5,168)
Block(-3,11,6,168)
Block(-3,11,7,168)
Block(-3,11,8,168)
Block(-3,12,-7,168:1)
Block(-3,12,-2,168)
Block(-3,13,-6,168:1)
Block(-3,13,-2,168)
Block(-3,14,-5,168:1)
Block(-3,14,-2,168)
Block(-3,15,-4,168:1)
Block(-3,15,-3,168)
Block(-3,15,-2,168)
Block(-3,15,-1,168)
Block(-3,15,0,168)
Block(-3,15,1,168)
Block(-3,15,2,168)
Block(-3,15,3,168)
Block(-3,15,4,168)
Block(-3,15,5,168)
Block(-3,15,6,168)
Block(-3,15,7,168)
Block(-3,15,8,168)
Block(-2,0,-7,168:1)
Block(-2,0,-6,168:1)
Block(-2,0,-5,168:1)
Block(-2,0,-4,168:1)
Block(-2,0,2,168:1)
Block(-2,0,3,168:1)
Block(-2,0,4,168:1)
Block(-2,0,5,168:1)
Block(-2,1,-7,168:1)
Block(-2,1,-6,168:1)
Block(-2,1,-5,168:1)
Block(-2,1,-4,168:1)
Block(-2,1,2,168:1)
Block(-2,1,3,168:1)
Block(-2,1,4,168:1)
Block(-2,1,5,168:1)
Block(-2,2,-7,168:1)
Block(-2,2,-6,168:1)
Block(-2,2,-5,168:1)
Block(-2,2,-4,168:1)
Block(-2,2,2,168:1)
Block(-2,2,3,168:1)
Block(-2,2,4,168:1)
Block(-2,2,5,168:1)
Block(-2,3,-7,168:1)
Block(-2,3,-6,168:1)
Block(-2,3,-5,168:1)
Block(-2,3,-4,168:1)
Block(-2,3,2,168:1)
Block(-2,3,3,168:1)
Block(-2,3,4,168:1)
Block(-2,3,5,168:1)
Block(-2,4,-7,168:1)
Block(-2,4,-6,168:1)
Block(-2,4,-5,168:1)
Block(-2,4,-4,168:1)
Block(-2,4,2,168:1)
Block(-2,4,3,168:1)
Block(-2,4,4,168:1)
Block(-2,4,5,168:1)
Block(-2,5,-7,168:1)
Block(-2,5,-6,168:1)
Block(-2,5,-5,168:1)
Block(-2,5,-4,168:1)
Block(-2,5,2,168:1)
Block(-2,5,3,168:1)
Block(-2,5,4,168:1)
Block(-2,5,5,168:1)
Block(-2,6,-7,168:1)
Block(-2,6,-6,168:1)
Block(-2,6,-5,168:1)
Block(-2,6,-4,168:1)
Block(-2,6,2,168:1)
Block(-2,6,3,168:1)
Block(-2,6,4,168:1)
Block(-2,6,5,168:1)
Block(-2,7,-7,168:1)
Block(-2,7,-6,168:1)
Block(-2,7,-5,168:1)
Block(-2,7,-4,168:1)
Block(-2,7,2,168:1)
Block(-2,7,3,168:1)
Block(-2,7,4,168:1)
Block(-2,7,5,168:1)
Block(-2,8,-7,168:1)
Block(-2,8,-6,168:1)
Block(-2,8,-5,168:1)
Block(-2,8,-4,168:1)
Block(-2,8,2,168:1)
Block(-2,8,3,168:1)
Block(-2,8,4,168:1)
Block(-2,8,5,168:1)
Block(-2,9,-7,168:1)
Block(-2,9,-6,168:1)
Block(-2,9,-5,168:1)
Block(-2,9,-4,168:1)
Block(-2,9,2,168:1)
Block(-2,9,3,168:1)
Block(-2,9,4,168:1)
Block(-2,9,5,168:1)
Block(-2,10,-7,168:1)
Block(-2,10,-6,168:1)
Block(-2,10,-5,168:1)
Block(-2,10,-4,168:1)
Block(-2,10,2,168:1)
Block(-2,10,3,168:1)
Block(-2,10,4,168:1)
Block(-2,10,5,168:1)
Block(-2,11,-7,168:1)
Block(-2,11,-6,168:1)
Block(-2,11,-5,168:1)
Block(-2,11,-4,168:1)
Block(-2,11,-3,168)
Block(-2,11,-2,168)
Block(-2,11,-1,168)
Block(-2,11,0,168)
Block(-2,11,1,168)
Block(-2,11,2,168:1)
Block(-2,11,3,168:1)
Block(-2,11,4,168:1)
Block(-2,11,5,168:1)
Block(-2,11,6,168)
Block(-2,11,7,168)
Block(-2,11,8,168)
Block(-2,12,-7,168:1)
Block(-2,13,-6,168:1)
Block(-2,14,-5,168:1)
Block(-2,15,-4,168:1)
Block(-2,15,-3,168:1)
Block(-2,15,-2,168:1)
Block(-2,15,-1,168:1)
Block(-2,15,0,168:1)
Block(-2,15,1,168:1)
Block(-2,15,2,168:1)
Block(-2,15,3,168:1)
Block(-2,15,4,168:1)
Block(-2,15,5,168:1)
Block(-2,15,6,168:1)
Block(-2,15,7,168:1)
Block(-2,15,8,168:1)
Block(-1,0,-7,168:1)
Block(-1,0,-6,168:1)
Block(-1,0,-5,168:1)
Block(-1,0,-4,168:1)
Block(-1,0,2,168:1)
Block(-1,0,3,168:1)
Block(-1,0,4,168:1)
Block(-1,0,5,168:1)
Block(-1,1,-7,168:1)
Block(-1,1,-6,168:1)
Block(-1,1,-5,168:1)
Block(-1,1,-4,168:1)
Block(-1,1,2,168:1)
Block(-1,1,3,168:1)
Block(-1,1,4,168:1)
Block(-1,1,5,168:1)
Block(-1,2,-7,168:1)
Block(-1,2,-6,168:1)
Block(-1,2,-5,168:1)
Block(-1,2,-4,168:1)
Block(-1,2,2,168:1)
Block(-1,2,3,168:1)
Block(-1,2,4,168:1)
Block(-1,2,5,168:1)
Block(-1,3,-7,168:1)
Block(-1,3,-6,168:1)
Block(-1,3,-5,168:1)
Block(-1,3,-4,168:1)
Block(-1,3,2,168:1)
Block(-1,3,3,168:1)
Block(-1,3,4,168:1)
Block(-1,3,5,168:1)
Block(-1,4,-7,168:1)
Block(-1,4,-6,168:1)
Block(-1,4,-5,168:1)
Block(-1,4,-4,168:1)
Block(-1,4,2,168:1)
Block(-1,4,3,168:1)
Block(-1,4,4,168:1)
Block(-1,4,5,168:1)
Block(-1,5,-7,168:1)
Block(-1,5,-6,168:1)
Block(-1,5,-5,168:1)
Block(-1,5,-4,168:1)
Block(-1,5,2,168:1)
Block(-1,5,3,168:1)
Block(-1,5,4,168:1)
Block(-1,5,5,168:1)
Block(-1,6,-7,168:1)
Block(-1,6,-6,168:1)
Block(-1,6,-5,168:1)
Block(-1,6,-4,168:1)
Block(-1,6,2,168:1)
Block(-1,6,3,168:1)
Block(-1,6,4,168:1)
Block(-1,6,5,168:1)
Block(-1,7,-7,168:1)
Block(-1,7,-6,168:1)
Block(-1,7,-5,168:1)
Block(-1,7,-4,168:1)
Block(-1,7,2,168:1)
Block(-1,7,3,168:1)
Block(-1,7,4,168:1)
Block(-1,7,5,168:1)
Block(-1,8,-7,168:1)
Block(-1,8,-6,168:1)
Block(-1,8,-5,168:1)
Block(-1,8,-4,168:1)
Block(-1,8,2,168:1)
Block(-1,8,3,168:1)
Block(-1,8,4,168:1)
Block(-1,8,5,168:1)
Block(-1,9,-7,168:1)
Block(-1,9,-6,168:1)
Block(-1,9,-5,168:1)
Block(-1,9,-4,168:1)
Block(-1,9,2,168:1)
Block(-1,9,3,168:1)
Block(-1,9,4,168:1)
Block(-1,9,5,168:1)
Block(-1,10,-7,168:1)
Block(-1,10,-6,168:1)
Block(-1,10,-5,168:1)
Block(-1,10,-4,168:1)
Block(-1,10,2,168:1)
Block(-1,10,3,168:1)
Block(-1,10,4,168:1)
Block(-1,10,5,168:1)
Block(-1,11,-7,168:1)
Block(-1,11,-6,168:1)
Block(-1,11,-5,168:1)
Block(-1,11,-4,168:1)
Block(-1,11,-3,168)
Block(-1,11,-2,168)
Block(-1,11,-1,168)
Block(-1,11,0,168)
Block(-1,11,1,168)
Block(-1,11,2,168:1)
Block(-1,11,3,168:1)
Block(-1,11,4,168:1)
Block(-1,11,5,168:1)
Block(-1,11,6,168)
Block(-1,11,7,168)
Block(-1,11,8,168)
Block(-1,12,-7,168:1)
Block(-1,13,-6,168:1)
Block(-1,14,-5,168:1)
Block(-1,14,-4,168:1)
Block(-1,14,-3,168:1)
Block(-1,14,-2,168:1)
Block(-1,14,-1,168:1)
Block(-1,14,0,168:1)
Block(-1,14,1,168:1)
Block(-1,14,2,168:1)
Block(-1,14,3,168:1)
Block(-1,14,4,168:1)
Block(-1,14,5,168:1)
Block(-1,14,6,168:1)
Block(-1,14,7,168:1)
Block(-1,14,8,168:1)
Block(0,0,-7,168:1)
Block(0,0,-6,168:1)
Block(0,0,-5,168:1)
Block(0,0,-4,168:1)
Block(0,0,2,168:1)
Block(0,0,3,168:1)
Block(0,0,4,168:1)
Block(0,0,5,168:1)
Block(0,1,-7,168:1)
Block(0,1,-6,168:1)
Block(0,1,-5,168:1)
Block(0,1,-4,168:1)
Block(0,1,2,168:1)
Block(0,1,3,168:1)
Block(0,1,4,168:1)
Block(0,1,5,168:1)
Block(0,2,-7,168:1)
Block(0,2,-6,168:1)
Block(0,2,-5,168:1)
Block(0,2,-4,168:1)
Block(0,2,2,168:1)
Block(0,2,3,168:1)
Block(0,2,4,168:1)
Block(0,2,5,168:1)
Block(0,3,-7,168:1)
Block(0,3,-6,168:1)
Block(0,3,-5,168:1)
Block(0,3,-4,168:1)
Block(0,3,2,168:1)
Block(0,3,3,168:1)
Block(0,3,4,168:1)
Block(0,3,5,168:1)
Block(0,4,-7,168:1)
Block(0,4,-6,168:1)
Block(0,4,-5,168:1)
Block(0,4,-4,168:1)
Block(0,4,2,168:1)
Block(0,4,3,168:1)
Block(0,4,4,168:1)
Block(0,4,5,168:1)
Block(0,5,-7,168:1)
Block(0,5,-6,168:1)
Block(0,5,-5,168:1)
Block(0,5,-4,168:1)
Block(0,5,2,168:1)
Block(0,5,3,168:1)
Block(0,5,4,168:1)
Block(0,5,5,168:1)
Block(0,6,-7,168:1)
Block(0,6,-6,168:1)
Block(0,6,-5,168:1)
Block(0,6,-4,168:1)
Block(0,6,2,168:1)
Block(0,6,3,168:1)
Block(0,6,4,168:1)
Block(0,6,5,168:1)
Block(0,7,-7,168:1)
Block(0,7,-6,168:1)
Block(0,7,-5,168:1)
Block(0,7,-4,168:1)
Block(0,7,2,168:1)
Block(0,7,3,168:1)
Block(0,7,4,168:1)
Block(0,7,5,168:1)
Block(0,8,-7,168:1)
Block(0,8,-6,168:1)
Block(0,8,-5,168:1)
Block(0,8,-4,168:1)
Block(0,8,2,168:1)
Block(0,8,3,168:1)
Block(0,8,4,168:1)
Block(0,8,5,168:1)
Block(0,9,-7,168:1)
Block(0,9,-6,168:1)
Block(0,9,-5,168:1)
Block(0,9,-4,168:1)
Block(0,9,2,168:1)
Block(0,9,3,168:1)
Block(0,9,4,168:1)
Block(0,9,5,168:1)
Block(0,10,-7,168:1)
Block(0,10,-6,168:1)
Block(0,10,-5,168:1)
Block(0,10,-4,168:1)
Block(0,10,2,168:1)
Block(0,10,3,168:1)
Block(0,10,4,168:1)
Block(0,10,5,168:1)
Block(0,11,-7,168:1)
Block(0,11,-6,168:1)
Block(0,11,-5,168:1)
Block(0,11,-4,168:1)
Block(0,11,-3,168)
Block(0,11,-2,168)
Block(0,11,-1,168)
Block(0,11,0,168)
Block(0,11,1,168)
Block(0,11,2,168:1)
Block(0,11,3,168:1)
Block(0,11,4,168:1)
Block(0,11,5,168:1)
Block(0,11,6,168)
Block(0,11,7,168)
Block(0,11,8,168)
Block(0,12,-7,168:1)
Block(0,13,-6,168:1)
Block(0,13,-5,168:1)
Block(0,13,-4,168:1)
Block(0,13,-3,168:1)
Block(0,13,-2,168:1)
Block(0,13,-1,168:1)
Block(0,13,0,168:1)
Block(0,13,1,168:1)
Block(0,13,2,168:1)
Block(0,13,3,168:1)
Block(0,13,4,168:1)
Block(0,13,5,168:1)
Block(0,13,6,168:1)
Block(0,13,7,168:1)
Block(0,13,8,168:1)
Block(1,0,-7,168:1)
Block(1,0,-6,168:1)
Block(1,0,-5,168:1)
Block(1,0,-4,168:1)
Block(1,0,2,168:1)
Block(1,0,3,168:1)
Block(1,0,4,168:1)
Block(1,0,5,168:1)
Block(1,1,-7,168:1)
Block(1,1,-6,168:1)
Block(1,1,-5,168:1)
Block(1,1,-4,168:1)
Block(1,1,2,168:1)
Block(1,1,3,168:1)
Block(1,1,4,168:1)
Block(1,1,5,168:1)
Block(1,2,-7,168:1)
Block(1,2,-6,168:1)
Block(1,2,-5,168:1)
Block(1,2,-4,168:1)
Block(1,2,2,168:1)
Block(1,2,3,168:1)
Block(1,2,4,168:1)
Block(1,2,5,168:1)
Block(1,3,-7,168:1)
Block(1,3,-6,168:1)
Block(1,3,-5,168:1)
Block(1,3,-4,168:1)
Block(1,3,2,168:1)
Block(1,3,3,168:1)
Block(1,3,4,168:1)
Block(1,3,5,168:1)
Block(1,4,-7,168:1)
Block(1,4,-6,168:1)
Block(1,4,-5,168:1)
Block(1,4,-4,168:1)
Block(1,4,2,168:1)
Block(1,4,3,168:1)
Block(1,4,4,168:1)
Block(1,4,5,168:1)
Block(1,5,-7,168:1)
Block(1,5,-6,168:1)
Block(1,5,-5,168:1)
Block(1,5,-4,168:1)
Block(1,5,2,168:1)
Block(1,5,3,168:1)
Block(1,5,4,168:1)
Block(1,5,5,168:1)
Block(1,6,-7,168:1)
Block(1,6,-6,168:1)
Block(1,6,-5,168:1)
Block(1,6,-4,168:1)
Block(1,6,2,168:1)
Block(1,6,3,168:1)
Block(1,6,4,168:1)
Block(1,6,5,168:1)
Block(1,7,-7,168:1)
Block(1,7,-6,168:1)
Block(1,7,-5,168:1)
Block(1,7,-4,168:1)
Block(1,7,2,168:1)
Block(1,7,3,168:1)
Block(1,7,4,168:1)
Block(1,7,5,168:1)
Block(1,8,-7,168:1)
Block(1,8,-6,168:1)
Block(1,8,-5,168:1)
Block(1,8,-4,168:1)
Block(1,8,2,168:1)
Block(1,8,3,168:1)
Block(1,8,4,168:1)
Block(1,8,5,168:1)
Block(1,9,-7,168:1)
Block(1,9,-6,168:1)
Block(1,9,-5,168:1)
Block(1,9,-4,168:1)
Block(1,9,2,168:1)
Block(1,9,3,168:1)
Block(1,9,4,168:1)
Block(1,9,5,168:1)
Block(1,10,-7,168:1)
Block(1,10,-6,168:1)
Block(1,10,-5,168:1)
Block(1,10,-4,168:1)
Block(1,10,2,168:1)
Block(1,10,3,168:1)
Block(1,10,4,168:1)
Block(1,10,5,168:1)
Block(1,11,-7,168:1)
Block(1,11,-6,168:1)
Block(1,11,-5,168:1)
Block(1,11,-4,168:1)
Block(1,11,-3,168)
Block(1,11,-2,168)
Block(1,11,-1,168)
Block(1,11,0,168)
Block(1,11,1,168)
Block(1,11,2,168:1)
Block(1,11,3,168:1)
Block(1,11,4,168:1)
Block(1,11,5,168:1)
Block(1,11,6,168)
Block(1,11,7,168)
Block(1,11,8,168)
Block(1,12,-7,168:1)
Block(1,12,-6,168:1)
Block(1,12,-5,168:1)
Block(1,12,-4,168:1)
Block(1,12,-3,168:1)
Block(1,12,-2,168:1)
Block(1,12,-1,168:1)
Block(1,12,0,168:1)
Block(1,12,1,168:1)
Block(1,12,2,168:1)
Block(1,12,3,168:1)
Block(1,12,4,168:1)
Block(1,12,5,168:1)
Block(1,12,6,168:1)
Block(1,12,7,168:1)
Block(1,12,8,168:1)


#######################################################################
# +-----------------------------------------------------------------+ #
# |                             Entities                            | #
# +-----------------------------------------------------------------+ #
#######################################################################

# Entity() spawns an entity instead of a block. The entity is spawned only once when the BO3 is spawned.
# Entities are persistent by default so they don't de-spawn when no player is near, they are only unloaded.
# Usage: Entity(x,y,z,mobName,groupSize,NameTagOrNBTFileName) or Entity(x,y,z,mobName,groupSize)
# Use /tc entities or /otg entities to get a list of entities that can be used as mobName, this includes entities added by other mods.
# NameTagOrNBTFileName can be either a nametag for the mob or an nbt file (such as mymobinfo.nbt or mymobinfo.txt).
# When using a text file you can use the same mob spawning parameters used with the /summon command to equip the
# entity and give it custom attributes etc. You can copy the DATA part of a summon command including surrounding
# curly braces to a .txt file, for instance for: "/summon Skeleton x y z {DATA}"
Entity(-4,17,0,minecraft:guardian,1)

#######################################################################
# +-----------------------------------------------------------------+ #
# |                            BO3 checks                           | #
# +-----------------------------------------------------------------+ #
#######################################################################

# Require a condition at a certain location in order for the BO3 to be spawned.
# BlockCheck(x,y,z,BlockName[,BlockName[,...]]) - one of the blocks must be at the location
# BlockCheckNot(x,y,z,BlockName[,BlockName[,...]]) - all the blocks must not be at the location
# LightCheck(x,y,z,minLightLevel,maxLightLevel) - light must be between min and max (inclusive)

# You can use "Solid" as a BlockName for matching all solid blocks or "All" to match all blocks that aren't air.

# Examples:
#   BlockCheck(0,-1,0,GRASS,DIRT)  Require grass or dirt just below the object
#   BlockCheck(0,-1,0,Solid)       Require any solid block just below the object
#   BlockCheck(0,-1,0,WOOL)        Require any type of wool just below the object
#   BlockCheck(0,-1,0,WOOL:0)      Require white wool just below the object
#   BlockCheckNot(0,-1,0,WOOL:0)   Require that there is no white wool below the object
#   LightCheck(0,0,0,0,1)          Require almost complete darkness just below the object

#######################################################################
# +-----------------------------------------------------------------+ #
# |                             Branches                            | #
# +-----------------------------------------------------------------+ #
#######################################################################

# Branches are objects that will spawn when this object spawns when it is used in
# the CustomStructure resource. Branches can also have branches, making complex
# structures possible. See the wiki for more details.

# Regular Branches spawn each branch with an independent chance of spawning.
# Branch(x,y,z,branchName,rotation,chance[,anotherBranchName,rotation,chance[,...]][IndividualChance])
# branchName - name of the object to spawn.
# rotation - NORTH, SOUTH, EAST or WEST.
# IndividualChance - The chance each branch has to spawn, assumed to be 100 when left blank

# WeightedBranch(x,y,z,branchName,rotation,chance[,anotherBranchName,rotation,chance[,...]][MaxChanceOutOf])
# MaxChanceOutOf - The chance all branches have to spawn out of, assumed to be 100 when left blank
