#######################################################################
# +-----------------------------------------------------------------+ #
# |                            BO3 object                           | #
# +-----------------------------------------------------------------+ #
#######################################################################

# The descriptions in this file are accurate only for TerrainControl and OTG.
# For MCW and OTG+ these descriptions are only accurate if the BO3 is used as a CustomObject.
# MCW and OTG+ completely reimplemented CustomStructure, check the MCW/OTG+ documentation for more information.

# This is the config file of a custom object.
# If you add this object correctly to your BiomeConfigs, it will spawn in the world.

# This is the creator of this BO3 object
Author: DedMaxim99

# A short description of this BO3 object
Description: This BO3 was converted from a schematic using OTGEdit. The author and description information of the schematic could not be found. If you know who the author of the schematic is then please add this information.

# The BO3 version, don't change this! It can be used by external applications to do a version check.
Version: 3

# The settings mode, WriteAll, WriteWithoutComments or WriteDisable. See WorldConfig.
SettingsMode: WriteDisable

#######################################################################
# +-----------------------------------------------------------------+ #
# |                          Main settings                          | #
# +-----------------------------------------------------------------+ #
#######################################################################

# This needs to be set to true to spawn the object in the Tree and Sapling resources.
Tree: false

# The frequency of the BO3 from 1 to 200. Tries this many times to spawn this BO3 when using the CustomObject(...) resource.
# Ignored by Tree(..), Sapling(..) and CustomStructure(..)
Frequency: 40

# The rarity of the BO3 from 0 to 100. Each spawn attempt has rarity% chance to succeed when using the CustomObject(...) resource.
# Ignored by Tree(..), Sapling(..) and CustomStructure(..)
Rarity: 100.0

# If you set this to true, the BO3 will be placed with a random rotation.
RotateRandomly: false

# The spawn height of the BO3 - randomY, highestBlock or highestSolidBlock.
SpawnHeight: randomY

# The height limits for the BO3.
MinHeight: 0

MaxHeight: 75

# Objects can have other objects attached to it: branches. Branches can also
# have branches attached to it, which can also have branches, etc. This is the
# maximum branch depth for this objects.
MaxBranchDepth: 10

# When spawned with the UseWorld keyword, this BO3 should NOT spawn in the following biomes.
# If you writer.write the BO3 name directly in the BiomeConfigs, this will be ignored.
ExcludedBiomes: All

# To optimise this BO3 for faster loading times you can use Notepad++ to find/replace comments and abbreviate things.
# Notepad++ find/replace with regex:
# Find: ^[#;].* replace to nothing removes all lines starting with # 
# Find: ^\s*$ replace to nothing removes most empty lines 
# Notepad++ find/replace without regex:
# *Warning: This will only work for OTG 1.10.2 v21 / OTG 1.11.2 v6 or higher. B( is not recognised by lower versions.
# Find: Block( replace to B(

#######################################################################
# +-----------------------------------------------------------------+ #
# |                      Source block settings                      | #
# +-----------------------------------------------------------------+ #
#######################################################################

# The block(s) the BO3 should spawn in.
SourceBlocks: AIR

# The maximum percentage of the BO3 that can be outside the SourceBlock.
# The BO3 won't be placed on a location with more blocks outside the SourceBlock than this percentage.
MaxPercentageOutsideSourceBlock: 100

# What to do when a block is about to be placed outside the SourceBlock? (dontPlace, placeAnyway)
OutsideSourceBlock: placeAnyway

#######################################################################
# +-----------------------------------------------------------------+ #
# |                              Blocks                             | #
# +-----------------------------------------------------------------+ #
#######################################################################

# All the blocks used in the BO3 are listed here. Possible blocks:
# Block(x,y,z,id[.data][,nbtfile.nbt) or B(x,y,z,id[.data][,nbtfile.nbt)
# RandomBlock(x,y,z,id[:data][,nbtfile.nbt],chance[,id[:data][,nbtfile.nbt],chance[,...]])
# So RandomBlock(0,0,0,CHEST,chest.nbt,50,CHEST,anotherchest.nbt,100) will spawn a chest at
# the BO3 origin, and give it a 50% chance to have the contents of chest.nbt, or, if that
# fails, a 100% percent chance to have the contents of anotherchest.nbt.

Block(-2,29,0,11)
Block(-2,30,0,11)
Block(-2,30,1,11)
Block(-2,31,1,11)
Block(-2,31,2,11)
Block(-2,32,1,11)
Block(-2,32,2,11)
Block(-2,44,-1,11)
Block(-2,45,-1,11)
Block(-2,45,0,11)
Block(-2,46,-2,11)
Block(-2,46,-1,11)
Block(-2,46,0,11)
Block(-2,47,-2,11)
Block(-2,47,-1,11)
Block(-2,47,0,11)
Block(-2,48,-2,11)
Block(-2,48,-1,11)
Block(-2,49,-2,11)
Block(-2,49,-1,11)
Block(-2,50,-2,11)
Block(-2,51,-2,11)
Block(-2,52,-2,11)
Block(-2,53,-2,11)
Block(-2,53,-1,11)
Block(-2,54,-2,11)
Block(-1,27,-2,11)
Block(-1,27,-1,11)
Block(-1,28,-1,11)
Block(-1,28,0,11)
Block(-1,29,-1,11)
Block(-1,29,0,11)
Block(-1,29,1,11)
Block(-1,30,-1,11)
Block(-1,30,0,11)
Block(-1,30,1,11)
Block(-1,30,2,11)
Block(-1,31,-1,11)
Block(-1,31,0,11)
Block(-1,31,1,11)
Block(-1,31,2,11)
Block(-1,32,0,11)
Block(-1,32,1,11)
Block(-1,32,2,11)
Block(-1,32,3,11)
Block(-1,33,0,11)
Block(-1,33,1,11)
Block(-1,33,2,11)
Block(-1,33,3,11)
Block(-1,34,1,11)
Block(-1,34,2,11)
Block(-1,34,3,11)
Block(-1,35,1,11)
Block(-1,35,2,11)
Block(-1,35,3,11)
Block(-1,36,2,11)
Block(-1,41,1,11)
Block(-1,42,0,11)
Block(-1,42,1,11)
Block(-1,42,2,11)
Block(-1,43,-1,11)
Block(-1,43,0,11)
Block(-1,43,1,11)
Block(-1,43,2,11)
Block(-1,44,-1,11)
Block(-1,44,0,11)
Block(-1,44,1,11)
Block(-1,45,-2,11)
Block(-1,45,-1,11)
Block(-1,45,0,11)
Block(-1,46,-2,11)
Block(-1,46,-1,11)
Block(-1,46,0,11)
Block(-1,47,-3,11)
Block(-1,47,-2,11)
Block(-1,47,-1,11)
Block(-1,47,0,11)
Block(-1,48,-3,11)
Block(-1,48,-2,11)
Block(-1,48,-1,11)
Block(-1,48,0,11)
Block(-1,49,-3,11)
Block(-1,49,-2,11)
Block(-1,49,-1,11)
Block(-1,49,0,11)
Block(-1,50,-3,11)
Block(-1,50,-2,11)
Block(-1,50,-1,11)
Block(-1,51,-3,11)
Block(-1,51,-2,11)
Block(-1,51,-1,11)
Block(-1,52,-3,11)
Block(-1,52,-2,11)
Block(-1,52,-1,11)
Block(-1,53,-2,11)
Block(-1,53,-1,11)
Block(-1,54,-2,11)
Block(-1,54,-1,11)
Block(-1,55,-2,11)
Block(-1,55,-1,11)
Block(-1,56,-1,11)
Block(-1,57,-1,11)
Block(0,25,-3,11)
Block(0,26,-3,11)
Block(0,26,-2,11)
Block(0,27,-3,11)
Block(0,27,-2,11)
Block(0,27,-1,11)
Block(0,27,0,11)
Block(0,27,1,11)
Block(0,28,-2,11)
Block(0,28,-1,11)
Block(0,28,0,11)
Block(0,28,1,11)
Block(0,29,-1,11)
Block(0,29,0,11)
Block(0,29,1,11)
Block(0,29,2,11)
Block(0,30,-1,11)
Block(0,30,0,11)
Block(0,30,1,11)
Block(0,30,2,11)
Block(0,30,3,11)
Block(0,31,-1,11)
Block(0,31,0,11)
Block(0,31,1,11)
Block(0,31,2,11)
Block(0,31,3,11)
Block(0,32,0,11)
Block(0,32,1,11)
Block(0,32,2,11)
Block(0,32,3,11)
Block(0,33,1,11)
Block(0,33,2,11)
Block(0,33,3,11)
Block(0,34,1,11)
Block(0,34,2,11)
Block(0,34,3,11)
Block(0,34,4,11)
Block(0,35,1,11)
Block(0,35,2,11)
Block(0,35,3,11)
Block(0,35,4,11)
Block(0,36,1,11)
Block(0,36,2,11)
Block(0,36,3,11)
Block(0,36,4,11)
Block(0,37,2,11)
Block(0,37,3,11)
Block(0,37,4,11)
Block(0,38,2,11)
Block(0,38,3,11)
Block(0,38,4,11)
Block(0,39,2,11)
Block(0,39,3,11)
Block(0,39,4,11)
Block(0,40,1,11)
Block(0,40,2,11)
Block(0,40,3,11)
Block(0,41,0,11)
Block(0,41,1,11)
Block(0,41,2,11)
Block(0,41,3,11)
Block(0,42,0,11)
Block(0,42,1,11)
Block(0,42,2,11)
Block(0,42,3,11)
Block(0,43,-1,11)
Block(0,43,0,11)
Block(0,43,1,11)
Block(0,43,2,11)
Block(0,44,-2,11)
Block(0,44,-1,11)
Block(0,44,0,11)
Block(0,44,1,11)
Block(0,44,2,11)
Block(0,45,-2,11)
Block(0,45,-1,11)
Block(0,45,0,11)
Block(0,45,1,11)
Block(0,45,2,11)
Block(0,46,-2,11)
Block(0,46,-1,11)
Block(0,46,0,11)
Block(0,46,1,11)
Block(0,46,2,11)
Block(0,47,-3,11)
Block(0,47,-2,11)
Block(0,47,-1,11)
Block(0,47,0,11)
Block(0,47,1,11)
Block(0,48,-3,11)
Block(0,48,-2,11)
Block(0,48,-1,11)
Block(0,48,0,11)
Block(0,49,-3,11)
Block(0,49,-2,11)
Block(0,49,-1,11)
Block(0,49,0,11)
Block(0,50,-2,11)
Block(0,50,-1,11)
Block(0,51,-2,11)
Block(0,51,-1,11)
Block(1,22,-4,11)
Block(1,23,-4,11)
Block(1,24,-4,11)
Block(1,24,-3,11)
Block(1,25,-4,11)
Block(1,25,-3,11)
Block(1,25,-2,11)
Block(1,26,-3,11)
Block(1,26,-2,11)
Block(1,26,-1,11)
Block(1,26,0,11)
Block(1,27,-3,11)
Block(1,27,-2,11)
Block(1,27,-1,11)
Block(1,27,0,11)
Block(1,27,1,11)
Block(1,28,-2,11)
Block(1,28,-1,11)
Block(1,28,0,11)
Block(1,28,1,11)
Block(1,29,-2,11)
Block(1,29,-1,11)
Block(1,29,0,11)
Block(1,29,1,11)
Block(1,30,-1,11)
Block(1,30,0,11)
Block(1,30,1,11)
Block(1,30,2,11)
Block(1,31,0,11)
Block(1,31,1,11)
Block(1,31,2,11)
Block(1,31,3,11)
Block(1,32,1,11)
Block(1,32,2,11)
Block(1,32,3,11)
Block(1,32,4,11)
Block(1,33,1,11)
Block(1,33,2,11)
Block(1,33,3,11)
Block(1,33,4,11)
Block(1,33,5,11)
Block(1,34,1,11)
Block(1,34,2,11)
Block(1,34,3,11)
Block(1,34,4,11)
Block(1,34,5,11)
Block(1,35,1,11)
Block(1,35,2,11)
Block(1,35,3,11)
Block(1,35,4,11)
Block(1,35,5,11)
Block(1,36,2,11)
Block(1,36,3,11)
Block(1,36,4,11)
Block(1,37,1,11)
Block(1,37,2,11)
Block(1,37,3,11)
Block(1,37,4,11)
Block(1,38,1,11)
Block(1,38,2,11)
Block(1,38,3,11)
Block(1,38,4,11)
Block(1,38,5,11)
Block(1,39,0,11)
Block(1,39,1,11)
Block(1,39,2,11)
Block(1,39,3,11)
Block(1,39,4,11)
Block(1,40,0,11)
Block(1,40,1,11)
Block(1,40,2,11)
Block(1,40,3,11)
Block(1,40,4,11)
Block(1,41,0,11)
Block(1,41,1,11)
Block(1,41,2,11)
Block(1,41,3,11)
Block(1,41,4,11)
Block(1,42,-1,11)
Block(1,42,0,11)
Block(1,42,1,11)
Block(1,42,2,11)
Block(1,42,3,11)
Block(1,42,4,11)
Block(1,43,-1,11)
Block(1,43,0,11)
Block(1,43,1,11)
Block(1,43,2,11)
Block(1,43,3,11)
Block(1,43,4,11)
Block(1,44,-1,11)
Block(1,44,0,11)
Block(1,44,1,11)
Block(1,44,2,11)
Block(1,44,3,11)
Block(1,45,-2,11)
Block(1,45,-1,11)
Block(1,45,0,11)
Block(1,45,1,11)
Block(1,45,2,11)
Block(1,46,-2,11)
Block(1,46,-1,11)
Block(1,46,0,11)
Block(1,46,1,11)
Block(1,46,2,11)
Block(1,47,-2,11)
Block(1,47,-1,11)
Block(1,47,0,11)
Block(1,47,1,11)
Block(1,48,-2,11)
Block(1,48,-1,11)
Block(1,48,0,11)
Block(1,49,-2,11)
Block(1,49,-1,11)
Block(1,50,-2,11)
Block(2,19,-5,11)
Block(2,20,-6,11)
Block(2,20,-5,11)
Block(2,20,-4,11)
Block(2,21,-6,11)
Block(2,21,-5,11)
Block(2,21,-4,11)
Block(2,21,-3,11)
Block(2,22,-6,11)
Block(2,22,-5,11)
Block(2,22,-4,11)
Block(2,22,-3,11)
Block(2,22,-2,11)
Block(2,23,-5,11)
Block(2,23,-4,11)
Block(2,23,-3,11)
Block(2,23,-2,11)
Block(2,24,-5,11)
Block(2,24,-4,11)
Block(2,24,-3,11)
Block(2,24,-2,11)
Block(2,24,-1,11)
Block(2,25,-4,11)
Block(2,25,-3,11)
Block(2,25,-2,11)
Block(2,25,-1,11)
Block(2,26,-4,11)
Block(2,26,-3,11)
Block(2,26,-2,11)
Block(2,26,-1,11)
Block(2,26,0,11)
Block(2,27,-4,11)
Block(2,27,-3,11)
Block(2,27,-2,11)
Block(2,27,-1,11)
Block(2,27,0,11)
Block(2,28,-2,11)
Block(2,28,-1,11)
Block(2,28,0,11)
Block(2,29,-1,11)
Block(2,29,0,11)
Block(2,32,3,11)
Block(2,33,3,11)
Block(2,33,4,11)
Block(2,34,2,11)
Block(2,34,3,11)
Block(2,34,4,11)
Block(2,34,5,11)
Block(2,35,2,11)
Block(2,35,3,11)
Block(2,35,4,11)
Block(2,35,5,11)
Block(2,36,2,11)
Block(2,36,3,11)
Block(2,36,4,11)
Block(2,36,5,11)
Block(2,37,1,11)
Block(2,37,2,11)
Block(2,37,3,11)
Block(2,37,4,11)
Block(2,37,5,11)
Block(2,38,1,11)
Block(2,38,2,11)
Block(2,38,3,11)
Block(2,38,4,11)
Block(2,38,5,11)
Block(2,39,1,11)
Block(2,39,2,11)
Block(2,39,3,11)
Block(2,39,4,11)
Block(2,39,5,11)
Block(2,40,0,11)
Block(2,40,1,11)
Block(2,40,2,11)
Block(2,40,3,11)
Block(2,40,4,11)
Block(2,41,0,11)
Block(2,41,1,11)
Block(2,41,2,11)
Block(2,41,3,11)
Block(2,41,4,11)
Block(2,42,-1,11)
Block(2,42,0,11)
Block(2,42,1,11)
Block(2,42,2,11)
Block(2,42,3,11)
Block(2,42,4,11)
Block(2,43,-1,11)
Block(2,43,0,11)
Block(2,43,1,11)
Block(2,43,2,11)
Block(2,43,3,11)
Block(2,44,0,11)
Block(2,44,1,11)
Block(2,44,2,11)
Block(2,44,3,11)
Block(2,45,0,11)
Block(2,45,1,11)
Block(2,46,-1,11)
Block(2,46,0,11)
Block(2,47,-1,11)
Block(2,47,0,11)
Block(3,18,-4,11)
Block(3,19,-6,11)
Block(3,19,-5,11)
Block(3,19,-4,11)
Block(3,19,-3,11)
Block(3,20,-6,11)
Block(3,20,-5,11)
Block(3,20,-4,11)
Block(3,20,-3,11)
Block(3,21,-6,11)
Block(3,21,-5,11)
Block(3,21,-4,11)
Block(3,21,-3,11)
Block(3,21,-2,11)
Block(3,22,-6,11)
Block(3,22,-5,11)
Block(3,22,-4,11)
Block(3,22,-3,11)
Block(3,22,-2,11)
Block(3,23,-6,11)
Block(3,23,-5,11)
Block(3,23,-4,11)
Block(3,23,-3,11)
Block(3,23,-2,11)
Block(3,23,-1,11)
Block(3,24,-5,11)
Block(3,24,-4,11)
Block(3,24,-3,11)
Block(3,24,-2,11)
Block(3,24,-1,11)
Block(3,25,-4,11)
Block(3,25,-3,11)
Block(3,25,-2,11)
Block(3,25,-1,11)
Block(3,26,-4,11)
Block(3,26,-3,11)
Block(3,26,-2,11)
Block(3,26,-1,11)
Block(3,27,-3,11)
Block(3,27,-2,11)
Block(3,27,-1,11)
Block(3,28,-2,11)
Block(3,34,3,11)
Block(3,34,4,11)
Block(3,35,2,11)
Block(3,35,3,11)
Block(3,35,4,11)
Block(3,36,2,11)
Block(3,36,3,11)
Block(3,36,4,11)
Block(3,37,2,11)
Block(3,37,3,11)
Block(3,37,4,11)
Block(3,37,5,11)
Block(3,38,2,11)
Block(3,38,3,11)
Block(3,38,4,11)
Block(3,39,1,11)
Block(3,39,2,11)
Block(3,39,3,11)
Block(3,39,4,11)
Block(3,40,1,11)
Block(3,40,2,11)
Block(3,40,3,11)
Block(3,40,4,11)
Block(3,41,0,11)
Block(3,41,1,11)
Block(3,41,2,11)
Block(3,41,3,11)
Block(3,42,0,11)
Block(3,42,1,11)
Block(3,42,2,11)
Block(3,42,3,11)
Block(3,43,0,11)
Block(3,43,1,11)
Block(3,43,2,11)
Block(3,44,1,11)
Block(3,44,2,11)
Block(4,16,-4,11)
Block(4,17,-5,11)
Block(4,17,-4,11)
Block(4,18,-6,11)
Block(4,18,-5,11)
Block(4,18,-4,11)
Block(4,18,-3,11)
Block(4,19,-6,11)
Block(4,19,-5,11)
Block(4,19,-4,11)
Block(4,19,-3,11)
Block(4,20,-6,11)
Block(4,20,-5,11)
Block(4,20,-4,11)
Block(4,20,-3,11)
Block(4,21,-6,11)
Block(4,21,-5,11)
Block(4,21,-4,11)
Block(4,21,-3,11)
Block(4,22,-5,11)
Block(4,22,-4,11)
Block(4,22,-3,11)
Block(4,23,-5,11)
Block(4,23,-4,11)
Block(4,23,-3,11)
Block(4,23,-2,11)
Block(4,24,-4,11)
Block(4,36,3,11)
Block(4,37,2,11)
Block(4,37,3,11)
Block(4,38,2,11)
Block(4,38,3,11)
Block(4,39,2,11)
Block(4,39,3,11)
Block(4,40,3,11)
Block(5,15,-4,11)
Block(5,16,-5,11)
Block(5,16,-4,11)
Block(5,17,-6,11)
Block(5,17,-5,11)
Block(5,17,-4,11)
Block(5,18,-6,11)
Block(5,18,-5,11)
Block(5,18,-4,11)
Block(5,19,-6,11)
Block(5,19,-5,11)
Block(5,19,-4,11)
Block(5,20,-6,11)
Block(5,20,-5,11)
Block(5,20,-4,11)
Block(5,21,-6,11)
Block(5,21,-5,11)
Block(5,21,-4,11)
Block(6,14,-4,11)
Block(6,14,-3,11)
Block(6,15,-4,11)
Block(6,15,-3,11)
Block(6,16,-5,11)
Block(6,16,-4,11)
Block(6,16,-3,11)
Block(6,17,-5,11)
Block(6,17,-4,11)
Block(6,18,-6,11)
Block(6,18,-5,11)
Block(6,18,-4,11)
Block(6,19,-6,11)
Block(6,19,-5,11)
Block(6,19,-4,11)
Block(6,20,-5,11)
Block(7,11,-3,11)
Block(7,12,-3,11)
Block(7,13,-3,11)
Block(7,14,-4,11)
Block(7,14,-3,11)
Block(7,15,-4,11)
Block(7,15,-3,11)
Block(7,16,-5,11)
Block(7,16,-4,11)
Block(7,17,-5,11)
Block(7,17,-4,11)
Block(7,18,-4,11)


#######################################################################
# +-----------------------------------------------------------------+ #
# |                             Entities                            | #
# +-----------------------------------------------------------------+ #
#######################################################################

# Entity() spawns an entity instead of a block. The entity is spawned only once when the BO3 is spawned.
# Entities are persistent by default so they don't de-spawn when no player is near, they are only unloaded.
# Usage: Entity(x,y,z,mobName,groupSize,NameTagOrNBTFileName) or Entity(x,y,z,mobName,groupSize)
# Use /tc entities or /otg entities to get a list of entities that can be used as mobName, this includes entities added by other mods.
# NameTagOrNBTFileName can be either a nametag for the mob or an nbt file (such as mymobinfo.nbt or mymobinfo.txt).
# When using a text file you can use the same mob spawning parameters used with the /summon command to equip the
# entity and give it custom attributes etc. You can copy the DATA part of a summon command including surrounding
# curly braces to a .txt file, for instance for: "/summon Skeleton x y z {DATA}"

#######################################################################
# +-----------------------------------------------------------------+ #
# |                            BO3 checks                           | #
# +-----------------------------------------------------------------+ #
#######################################################################

# Require a condition at a certain location in order for the BO3 to be spawned.
# BlockCheck(x,y,z,BlockName[,BlockName[,...]]) - one of the blocks must be at the location
# BlockCheckNot(x,y,z,BlockName[,BlockName[,...]]) - all the blocks must not be at the location
# LightCheck(x,y,z,minLightLevel,maxLightLevel) - light must be between min and max (inclusive)

# You can use "Solid" as a BlockName for matching all solid blocks or "All" to match all blocks that aren't air.

# Examples:
#   BlockCheck(0,-1,0,GRASS,DIRT)  Require grass or dirt just below the object
#   BlockCheck(0,-1,0,Solid)       Require any solid block just below the object
#   BlockCheck(0,-1,0,WOOL)        Require any type of wool just below the object
#   BlockCheck(0,-1,0,WOOL:0)      Require white wool just below the object
#   BlockCheckNot(0,-1,0,WOOL:0)   Require that there is no white wool below the object
#   LightCheck(0,0,0,0,1)          Require almost complete darkness just below the object

#######################################################################
# +-----------------------------------------------------------------+ #
# |                             Branches                            | #
# +-----------------------------------------------------------------+ #
#######################################################################

# Branches are objects that will spawn when this object spawns when it is used in
# the CustomStructure resource. Branches can also have branches, making complex
# structures possible. See the wiki for more details.

# Regular Branches spawn each branch with an independent chance of spawning.
# Branch(x,y,z,branchName,rotation,chance[,anotherBranchName,rotation,chance[,...]][IndividualChance])
# branchName - name of the object to spawn.
# rotation - NORTH, SOUTH, EAST or WEST.
# IndividualChance - The chance each branch has to spawn, assumed to be 100 when left blank

# WeightedBranch(x,y,z,branchName,rotation,chance[,anotherBranchName,rotation,chance[,...]][MaxChanceOutOf])
# MaxChanceOutOf - The chance all branches have to spawn out of, assumed to be 100 when left blank
