
#######################################################################
# +-----------------------------------------------------------------+ #
# |                            BO3 object                           | #
# +-----------------------------------------------------------------+ #
#######################################################################

# This is the config file of a custom object.
# If you add this object correctly to your BiomeConfigs, it will spawn in the world.

# This is the creator of this BO3 object
Author: DedMaxim99

# A short description of this BO3 object
Description: No description given

# The BO3 version, don't change this! It can be used by external applications to do a version check.
Version: 3

# The settings mode, WriteAll, WriteWithoutComments or WriteDisable. See WorldConfig.
SettingsMode: WriteDisable


#######################################################################
# +-----------------------------------------------------------------+ #
# |                          Main settings                          | #
# +-----------------------------------------------------------------+ #
#######################################################################

# This needs to be set to true to spawn the object in the Tree and Sapling resources.
Tree: false

# The frequency of the BO3 from 1 to 200. Tries this many times to spawn this BO3 when using the CustomObject(...) resource.
# Ignored by Tree(..), Sapling(..) and CustomStructure(..)
Frequency: 1

# The rarity of the BO3 from 0 to 100. Each spawn attempt has rarity% chance to succeed when using the CustomObject(...) resource.
# Ignored by Tree(..), Sapling(..) and CustomStructure(..)
Rarity: 10.0

# If you set this to true, the BO3 will be placed with a random rotation.
RotateRandomly: true

# The spawn height of the BO3: randomY, highestBlock or highestSolidBlock.
SpawnHeight: randomY

# The offset from the spawn height to spawn this BO3
# Ex. SpawnHeight = highestSolidBlock, SpawnHeightOffset = 3; This object will spawn 3 blocks above the highest solid block
SpawnHeightOffset: 0

# A random amount to offset the spawn location from the spawn offset height
# Ex. SpawnHeightOffset = 3, SpawnHeightVariance = 3; This object will spawn 3 to 6 blocks above the original spot it would have spawned
SpawnHeightVariance: 0

##############################
# Height Limits for the BO3. #
##############################

# When in randomY mode used as the minimum Y or in atMinY mode as the actual Y to spawn this BO3 at.
MinHeight: 0

# When in randomY mode used as the maximum Y to spawn this BO3 at.
MaxHeight: 100

######################
# Extrusion settings #
######################

# The style of extrusion you wish to use - BottomDown, TopUp, None (Default)
ExtrudeMode: None

# The blocks to extrude your BO3 through
ExtrudeThroughBlocks: AIR

# Objects can have other objects attacthed to it: branches. Branches can also
# have branches attached to it, which can also have branches, etc. This is the
# maximum branch depth for this objects.
MaxBranchDepth: 10

# When spawned with the UseWorld keyword, this BO3 should NOT spawn in the following biomes.
# If you write the BO3 name directly in the BiomeConfigs, this will be ignored.
ExcludedBiomes: All


#######################################################################
# +-----------------------------------------------------------------+ #
# |                      Source block settings                      | #
# +-----------------------------------------------------------------+ #
#######################################################################

# The block(s) the BO3 should spawn in.
SourceBlocks: AIR

# The maximum percentage of the BO3 that can be outside the SourceBlock.
# The BO3 won't be placed on a location with more blocks outside the SourceBlock than this percentage.
MaxPercentageOutsideSourceBlock: 100

# What to do when a block is about to be placed outside the SourceBlock? (dontPlace, placeAnyway)
OutsideSourceBlock: placeAnyway

# OTG+ settings #
# Legacy setting, rename this file to .BO4 instead. Set this to true to enable the advanced customstructure features of OTG+.
IsOTGPlus: false


#######################################################################
# +-----------------------------------------------------------------+ #
# |                              Blocks                             | #
# +-----------------------------------------------------------------+ #
#######################################################################

# All the blocks used in the BO3 are listed here. Possible blocks:
# Block(x,y,z,id[.data][,nbtfile.nbt)
# RandomBlock(x,y,z,id[:data][,nbtfile.nbt],chance[,id[:data][,nbtfile.nbt],chance[,...]])
#  So RandomBlock(0,0,0,CHEST,chest.nbt,50,CHEST,anotherchest.nbt,100) will spawn a chest at
#  the BO3 origin, and give it a 50% chance to have the contents of chest.nbt, or, if that
#  fails, a 100% percent chance to have the contents of anotherchest.nbt.
# *Note: Unlike Entity() and Spawner(), for Block() .txt files don't work, only .nbt files work.
# MinecraftObject(x,y,z,name) (TODO: This may not work anymore and needs to be tested.
#  Spawns an object in the Mojang NBT structure format. For example, 
#  MinecraftObject(0,0,0,minecraft:igloo/igloo_bottom)
#  spawns the bottom part of an igloo.
Block(-14,0,-15,AIR)
Block(-14,1,-15,AIR)
Block(-14,1,-14,AIR)
Block(-14,2,-15,AIR)
Block(-14,2,-14,AIR)
Block(-14,3,-14,AIR)
Block(-14,4,-14,AIR)
Block(-14,4,-13,AIR)
Block(-14,5,-14,AIR)
Block(-14,5,-13,AIR)
Block(-14,5,-12,AIR)
Block(-14,6,-14,AIR)
Block(-14,6,-13,AIR)
Block(-14,6,-12,AIR)
Block(-14,7,-14,AIR)
Block(-14,7,-13,AIR)
Block(-14,7,-12,AIR)
Block(-14,8,-12,AIR)
Block(-13,1,-15,AIR)
Block(-13,1,-14,AIR)
Block(-13,2,-15,AIR)
Block(-13,2,-14,AIR)
Block(-13,3,-15,AIR)
Block(-13,3,-14,AIR)
Block(-13,4,-15,AIR)
Block(-13,4,-14,AIR)
Block(-13,4,-13,AIR)
Block(-13,5,-15,AIR)
Block(-13,5,-14,AIR)
Block(-13,5,-13,AIR)
Block(-13,5,-12,AIR)
Block(-13,6,-14,AIR)
Block(-13,6,-13,AIR)
Block(-13,6,-12,AIR)
Block(-13,7,-14,AIR)
Block(-13,7,-13,AIR)
Block(-13,7,-12,AIR)
Block(-13,8,-14,AIR)
Block(-13,8,-13,AIR)
Block(-13,8,-12,AIR)
Block(-13,9,-13,AIR)
Block(-13,9,-12,AIR)
Block(-12,4,-14,AIR)
Block(-12,5,-14,AIR)
Block(-12,5,-13,AIR)
Block(-12,6,-14,AIR)
Block(-12,6,-13,AIR)
Block(-12,6,-12,AIR)
Block(-12,7,-14,AIR)
Block(-12,7,-13,AIR)
Block(-12,7,-12,AIR)
Block(-12,8,-14,AIR)
Block(-12,8,-13,AIR)
Block(-12,8,-12,AIR)
Block(-12,8,-11,AIR)
Block(-12,9,-14,AIR)
Block(-12,9,-13,AIR)
Block(-12,9,-12,AIR)
Block(-12,9,-11,AIR)
Block(-12,10,-13,AIR)
Block(-12,10,-12,AIR)
Block(-11,5,-14,AIR)
Block(-11,6,-14,AIR)
Block(-11,6,-13,AIR)
Block(-11,6,-12,AIR)
Block(-11,7,-14,AIR)
Block(-11,7,-13,AIR)
Block(-11,7,-12,AIR)
Block(-11,7,-11,AIR)
Block(-11,8,-14,AIR)
Block(-11,8,-13,AIR)
Block(-11,8,-12,AIR)
Block(-11,8,-11,AIR)
Block(-11,9,-14,AIR)
Block(-11,9,-13,AIR)
Block(-11,9,-12,AIR)
Block(-11,9,-11,AIR)
Block(-11,9,-10,AIR)
Block(-11,10,-13,AIR)
Block(-11,10,-12,AIR)
Block(-11,10,-11,AIR)
Block(-11,10,-10,AIR)
Block(-11,11,-12,AIR)
Block(-11,11,-11,AIR)
Block(-11,11,-10,AIR)
Block(-11,11,-9,AIR)
Block(-11,12,-11,AIR)
Block(-11,12,-10,AIR)
Block(-11,12,-9,AIR)
Block(-11,14,-6,AIR)
Block(-11,14,-5,AIR)
Block(-11,14,-4,AIR)
Block(-11,14,-3,AIR)
Block(-11,15,-5,AIR)
Block(-11,15,-4,AIR)
Block(-11,15,-3,AIR)
Block(-10,6,-14,AIR)
Block(-10,7,-14,AIR)
Block(-10,7,-13,AIR)
Block(-10,7,-12,AIR)
Block(-10,8,-14,AIR)
Block(-10,8,-13,AIR)
Block(-10,8,-12,AIR)
Block(-10,8,-11,AIR)
Block(-10,9,-14,AIR)
Block(-10,9,-13,AIR)
Block(-10,9,-12,AIR)
Block(-10,9,-11,AIR)
Block(-10,9,-10,AIR)
Block(-10,10,-13,AIR)
Block(-10,10,-12,AIR)
Block(-10,10,-11,AIR)
Block(-10,10,-10,AIR)
Block(-10,10,-9,AIR)
Block(-10,11,-12,AIR)
Block(-10,11,-11,AIR)
Block(-10,11,-10,AIR)
Block(-10,11,-9,AIR)
Block(-10,11,-8,AIR)
Block(-10,12,-12,AIR)
Block(-10,12,-11,AIR)
Block(-10,12,-10,AIR)
Block(-10,12,-9,AIR)
Block(-10,12,-8,AIR)
Block(-10,12,-7,AIR)
Block(-10,13,-9,AIR)
Block(-10,13,-8,AIR)
Block(-10,13,-7,AIR)
Block(-10,13,-6,AIR)
Block(-10,13,-5,AIR)
Block(-10,13,-4,AIR)
Block(-10,13,-3,AIR)
Block(-10,13,-2,AIR)
Block(-10,14,-7,AIR)
Block(-10,14,-6,AIR)
Block(-10,14,-5,AIR)
Block(-10,14,-4,AIR)
Block(-10,14,-3,AIR)
Block(-10,14,-2,AIR)
Block(-10,14,-1,AIR)
Block(-10,15,-6,AIR)
Block(-10,15,-5,AIR)
Block(-10,15,-4,AIR)
Block(-10,15,-3,AIR)
Block(-10,15,-2,AIR)
Block(-10,16,-5,AIR)
Block(-10,16,-4,AIR)
Block(-10,16,-3,AIR)
Block(-9,8,-13,AIR)
Block(-9,8,-12,AIR)
Block(-9,9,-13,AIR)
Block(-9,9,-12,AIR)
Block(-9,9,-11,AIR)
Block(-9,9,-10,AIR)
Block(-9,10,-12,AIR)
Block(-9,10,-11,AIR)
Block(-9,10,-10,AIR)
Block(-9,10,-9,AIR)
Block(-9,11,-11,AIR)
Block(-9,11,-10,AIR)
Block(-9,11,-9,AIR)
Block(-9,11,-8,AIR)
Block(-9,11,-7,AIR)
Block(-9,11,-6,AIR)
Block(-9,12,-10,AIR)
Block(-9,12,-9,AIR)
Block(-9,12,-8,AIR)
Block(-9,12,-7,AIR)
Block(-9,12,-6,AIR)
Block(-9,13,-10,AIR)
Block(-9,13,-9,AIR)
Block(-9,13,-8,AIR)
Block(-9,13,-7,AIR)
Block(-9,13,-6,AIR)
Block(-9,13,-5,AIR)
Block(-9,13,-4,AIR)
Block(-9,13,-3,AIR)
Block(-9,13,-2,AIR)
Block(-9,14,-8,AIR)
Block(-9,14,-7,AIR)
Block(-9,14,-6,AIR)
Block(-9,14,-5,AIR)
Block(-9,14,-4,AIR)
Block(-9,14,-3,AIR)
Block(-9,14,-2,AIR)
Block(-9,14,-1,AIR)
Block(-9,14,0,AIR)
Block(-9,15,-7,AIR)
Block(-9,15,-6,AIR)
Block(-9,15,-5,AIR)
Block(-9,15,-4,AIR)
Block(-9,15,-3,AIR)
Block(-9,15,-2,AIR)
Block(-9,15,-1,AIR)
Block(-9,15,0,AIR)
Block(-9,15,1,AIR)
Block(-9,16,-6,AIR)
Block(-9,16,-5,AIR)
Block(-9,16,-4,AIR)
Block(-9,16,-3,AIR)
Block(-9,16,-2,AIR)
Block(-9,16,-1,AIR)
Block(-8,11,-10,AIR)
Block(-8,11,-9,AIR)
Block(-8,11,-8,AIR)
Block(-8,11,-7,AIR)
Block(-8,11,-6,AIR)
Block(-8,12,-10,AIR)
Block(-8,12,-9,AIR)
Block(-8,12,-8,AIR)
Block(-8,12,-7,AIR)
Block(-8,12,-6,AIR)
Block(-8,12,-5,AIR)
Block(-8,12,-4,AIR)
Block(-8,13,-9,AIR)
Block(-8,13,-8,AIR)
Block(-8,13,-7,AIR)
Block(-8,13,-6,AIR)
Block(-8,13,-5,AIR)
Block(-8,13,-4,AIR)
Block(-8,13,-3,AIR)
Block(-8,13,-2,AIR)
Block(-8,14,-8,AIR)
Block(-8,14,-7,AIR)
Block(-8,14,-6,AIR)
Block(-8,14,-5,AIR)
Block(-8,14,-4,AIR)
Block(-8,14,-3,AIR)
Block(-8,14,-2,AIR)
Block(-8,14,-1,AIR)
Block(-8,14,0,AIR)
Block(-8,15,-7,AIR)
Block(-8,15,-6,AIR)
Block(-8,15,-5,AIR)
Block(-8,15,-4,AIR)
Block(-8,15,-3,AIR)
Block(-8,15,-2,AIR)
Block(-8,15,-1,AIR)
Block(-8,15,0,AIR)
Block(-8,15,1,AIR)
Block(-8,15,2,AIR)
Block(-8,16,-4,AIR)
Block(-8,16,-3,AIR)
Block(-8,16,-2,AIR)
Block(-8,16,-1,AIR)
Block(-8,16,0,AIR)
Block(-8,16,1,AIR)
Block(-7,11,-10,mossy_cobblestone)
Block(-7,11,-9,cobblestone)
Block(-7,11,-8,cobblestone)
Block(-7,11,-7,cobblestone)
Block(-7,11,-6,cobblestone)
Block(-7,11,-5,cobblestone)
Block(-7,11,-4,mossy_cobblestone)
Block(-7,12,-10,mossy_cobblestone)
Block(-7,12,-9,stone:6)
RandomBlock(-7,12,-8,WEB,25,AIR,100)
Block(-7,12,-7,AIR)
Block(-7,12,-6,AIR)
Block(-7,12,-5,stone:6)
Block(-7,12,-4,cobblestone)
Block(-7,13,-10,cobblestone)
Block(-7,13,-9,stonebrick:3)
Block(-7,13,-8,AIR)
RandomBlock(-7,13,-7,WEB,25,AIR,100)
RandomBlock(-7,13,-6,WEB,25,AIR,100)
Block(-7,13,-5,stonebrick:3)
Block(-7,13,-4,mossy_cobblestone)
Block(-7,13,-3,AIR)
Block(-7,13,-2,AIR)
Block(-7,14,-10,mossy_cobblestone)
Block(-7,14,-9,stone:6)
Block(-7,14,-8,stone_stairs:7)
Block(-7,14,-7,AIR)
Block(-7,14,-6,stone_stairs:6)
Block(-7,14,-5,stone:6)
Block(-7,14,-4,cobblestone)
Block(-7,14,-2,AIR)
RandomBlock(-7,14,-1,WEB,25,AIR,100)
RandomBlock(-7,14,0,WEB,25,AIR,100)
RandomBlock(-7,14,1,WEB,25,AIR,100)
Block(-7,15,-10,cobblestone)
Block(-7,15,-9,cobblestone)
Block(-7,15,-8,cobblestone)
Block(-7,15,-7,cobblestone)
Block(-7,15,-6,cobblestone)
Block(-7,15,-5,cobblestone)
Block(-7,15,-4,cobblestone)
Block(-7,15,-2,AIR)
Block(-7,15,-1,AIR)
Block(-7,15,0,AIR)
Block(-7,15,1,AIR)
RandomBlock(-7,15,2,WEB,25,AIR,100)
Block(-7,15,3,AIR)
Block(-7,16,-9,cobblestone)
Block(-7,16,-8,cobblestone)
Block(-7,16,-7,mossy_cobblestone)
Block(-7,16,-6,mossy_cobblestone)
Block(-7,16,-5,cobblestone)
Block(-7,16,-1,AIR)
Block(-7,16,0,AIR)
Block(-7,16,1,AIR)
RandomBlock(-7,16,2,WEB,25,AIR,100)
Block(-7,16,3,AIR)
RandomBlock(-7,16,4,WEB,25,AIR,100)
Block(-7,17,0,AIR)
Block(-7,17,1,AIR)
RandomBlock(-7,17,2,WEB,25,AIR,100)
Block(-6,11,-10,cobblestone)
Block(-6,11,-9,cobblestone)
Block(-6,11,-8,cobblestone)
Block(-6,11,-7,mossy_cobblestone)
Block(-6,11,-6,cobblestone)
Block(-6,11,-5,mossy_cobblestone)
Block(-6,11,-4,cobblestone)
Block(-6,12,-10,cobblestone)
RandomBlock(-6,12,-9,WEB,25,AIR,100)
Block(-6,12,-8,AIR)
Block(-6,12,-7,AIR)
Block(-6,12,-6,AIR)
Block(-6,12,-5,AIR)
Block(-6,12,-4,mossy_cobblestone)
Block(-6,13,-10,mossy_cobblestone)
RandomBlock(-6,13,-9,WEB,25,AIR,100)
Block(-6,13,-8,AIR)
Block(-6,13,-7,AIR)
Block(-6,13,-6,AIR)
Block(-6,13,-5,AIR)
Block(-6,13,-4,cobblestone)
Block(-6,14,-10,mossy_cobblestone)
Block(-6,14,-9,stone_stairs:5)
RandomBlock(-6,14,-8,WEB,25,AIR,100)
Block(-6,14,-7,AIR)
Block(-6,14,-6,AIR)
Block(-6,14,-5,stone_stairs:5)
Block(-6,14,-4,cobblestone)
RandomBlock(-6,14,-1,WEB,25,AIR,100)
Block(-6,14,0,AIR)
RandomBlock(-6,14,1,WEB,25,AIR,100)
Block(-6,15,-10,mossy_cobblestone)
Block(-6,15,-9,stone:6)
Block(-6,15,-8,AIR)
RandomBlock(-6,15,-7,WEB,25,AIR,100)
Block(-6,15,-6,AIR)
Block(-6,15,-5,stone:6)
Block(-6,15,-4,cobblestone)
RandomBlock(-6,15,-1,WEB,25,AIR,100)
RandomBlock(-6,15,0,WEB,25,AIR,100)
Block(-6,15,1,AIR)
Block(-6,15,2,AIR)
Block(-6,15,3,AIR)
Block(-6,15,4,AIR)
Block(-6,16,-9,cobblestone)
Block(-6,16,-8,cobblestone)
Block(-6,16,-7,mossy_cobblestone)
Block(-6,16,-6,cobblestone)
Block(-6,16,-5,mossy_cobblestone)
RandomBlock(-6,16,-1,WEB,25,AIR,100)
Block(-6,16,0,AIR)
Block(-6,16,1,AIR)
RandomBlock(-6,16,2,WEB,25,AIR,100)
Block(-6,16,3,AIR)
Block(-6,16,4,AIR)
Block(-6,17,0,AIR)
Block(-6,17,1,AIR)
Block(-6,17,2,AIR)
Block(-6,17,3,AIR)
Block(-6,17,4,AIR)
RandomBlock(-6,18,1,WEB,25,AIR,100)
Block(-6,18,2,AIR)
Block(-5,11,-10,mossy_cobblestone)
Block(-5,11,-9,mossy_cobblestone)
Block(-5,11,-8,mossy_cobblestone)
Block(-5,11,-7,mossy_cobblestone)
Block(-5,11,-6,cobblestone)
Block(-5,11,-5,cobblestone)
Block(-5,11,-4,cobblestone)
Block(-5,12,-11,stone:6)
Block(-5,12,-10,TRIPWIRE_HOOK:4)
Block(-5,12,-9,TRIPWIRE:4)
Block(-5,12,-8,TRIPWIRE:4)
Block(-5,12,-7,TRIPWIRE:4)
Block(-5,12,-6,TRIPWIRE:4)
Block(-5,12,-5,TRIPWIRE:4)
Block(-5,12,-4,TRIPWIRE_HOOK:6)
Block(-5,12,-3,stone:6)
RandomBlock(-5,13,-11,DISPENSER:3,../../nbt/dispenserArrows.nbt,100)
Block(-5,13,-10,AIR)
Block(-5,13,-9,AIR)
Block(-5,13,-8,AIR)
RandomBlock(-5,13,-7,WEB,25,AIR,100)
Block(-5,13,-6,AIR)
Block(-5,13,-5,AIR)
Block(-5,13,-4,AIR)
RandomBlock(-5,13,-3,DISPENSER:2,../../nbt/dispenserArrows.nbt,100)
Block(-5,14,-10,stone_stairs:7)
Block(-5,14,-9,AIR)
Block(-5,14,-8,AIR)
Block(-5,14,-7,AIR)
Block(-5,14,-6,AIR)
RandomBlock(-5,14,-5,WEB,25,AIR,100)
Block(-5,14,-4,stone_stairs:6)
Block(-5,14,-1,AIR)
Block(-5,14,0,AIR)
Block(-5,14,1,AIR)
Block(-5,15,-10,cobblestone)
Block(-5,15,-9,stone:6)
Block(-5,15,-8,AIR)
RandomBlock(-5,15,-7,WEB,25,AIR,100)
Block(-5,15,-6,AIR)
Block(-5,15,-5,stone:6)
Block(-5,15,-4,mossy_cobblestone)
Block(-5,15,-1,AIR)
Block(-5,15,0,AIR)
RandomBlock(-5,15,1,WEB,25,AIR,100)
Block(-5,15,2,AIR)
Block(-5,15,3,AIR)
Block(-5,15,4,AIR)
Block(-5,16,-9,cobblestone)
Block(-5,16,-8,mossy_cobblestone)
Block(-5,16,-7,cobblestone)
Block(-5,16,-6,mossy_cobblestone)
Block(-5,16,-5,cobblestone)
Block(-5,16,0,AIR)
Block(-5,16,1,AIR)
RandomBlock(-5,16,2,WEB,25,AIR,100)
Block(-5,16,3,AIR)
Block(-5,16,4,AIR)
Block(-5,16,5,AIR)
Block(-5,17,0,AIR)
Block(-5,17,1,AIR)
Block(-5,17,2,AIR)
Block(-5,17,3,AIR)
Block(-5,17,4,AIR)
RandomBlock(-5,17,5,WEB,25,AIR,100)
Block(-5,18,1,AIR)
Block(-5,18,2,AIR)
Block(-5,18,3,AIR)
Block(-5,18,4,AIR)
RandomBlock(-5,18,5,WEB,25,AIR,100)
RandomBlock(-5,18,6,WEB,25,AIR,100)
Block(-5,19,2,AIR)
Block(-5,19,3,AIR)
Block(-4,11,-10,cobblestone)
Block(-4,11,-9,cobblestone)
Block(-4,11,-8,cobblestone)
Block(-4,11,-7,cobblestone)
Block(-4,11,-6,mossy_cobblestone)
Block(-4,11,-5,cobblestone)
Block(-4,11,-4,cobblestone)
Block(-4,12,-10,mossy_cobblestone)
Block(-4,12,-9,AIR)
Block(-4,12,-8,AIR)
RandomBlock(-4,12,-7,WEB,25,AIR,100)
Block(-4,12,-6,AIR)
Block(-4,12,-5,AIR)
Block(-4,12,-4,cobblestone)
Block(-4,13,-10,mossy_cobblestone)
Block(-4,13,-9,AIR)
Block(-4,13,-8,AIR)
RandomBlock(-4,13,-7,WEB,25,AIR,100)
Block(-4,13,-6,AIR)
Block(-4,13,-5,AIR)
Block(-4,13,-4,cobblestone)
Block(-4,14,-10,cobblestone)
Block(-4,14,-9,stone_stairs:4)
Block(-4,14,-8,AIR)
Block(-4,14,-7,AIR)
Block(-4,14,-6,AIR)
Block(-4,14,-5,stone_stairs:4)
Block(-4,14,-4,cobblestone)
Block(-4,15,-10,mossy_cobblestone)
Block(-4,15,-9,stone:6)
Block(-4,15,-8,AIR)
RandomBlock(-4,15,-7,WEB,25,AIR,100)
Block(-4,15,-6,AIR)
Block(-4,15,-5,stone:6)
Block(-4,15,-4,mossy_cobblestone)
Block(-4,15,0,AIR)
Block(-4,15,1,AIR)
RandomBlock(-4,15,2,WEB,25,AIR,100)
Block(-4,15,3,AIR)
Block(-4,15,4,AIR)
Block(-4,16,-9,cobblestone)
Block(-4,16,-8,cobblestone)
Block(-4,16,-7,cobblestone)
Block(-4,16,-6,mossy_cobblestone)
Block(-4,16,-5,cobblestone)
Block(-4,16,0,AIR)
Block(-4,16,1,AIR)
Block(-4,16,2,AIR)
RandomBlock(-4,16,3,WEB,25,AIR,100)
Block(-4,16,4,AIR)
Block(-4,16,5,AIR)
Block(-4,17,0,AIR)
Block(-4,17,1,AIR)
Block(-4,17,2,AIR)
Block(-4,17,3,AIR)
Block(-4,17,4,AIR)
Block(-4,17,5,AIR)
Block(-4,17,6,AIR)
Block(-4,18,1,AIR)
RandomBlock(-4,18,2,WEB,25,AIR,100)
Block(-4,18,3,AIR)
Block(-4,18,4,AIR)
Block(-4,18,5,AIR)
Block(-4,18,6,AIR)
Block(-4,18,7,AIR)
Block(-4,19,2,AIR)
Block(-4,19,3,AIR)
Block(-4,19,4,AIR)
Block(-4,19,5,AIR)
Block(-4,19,6,AIR)
Block(-4,19,7,AIR)
RandomBlock(-4,20,3,WEB,25,AIR,100)
Block(-4,20,4,AIR)
Block(-4,20,5,AIR)
Block(-4,20,6,AIR)
Block(-3,11,-10,cobblestone)
Block(-3,11,-9,cobblestone)
Block(-3,11,-8,cobblestone)
Block(-3,11,-7,cobblestone)
Block(-3,11,-6,cobblestone)
Block(-3,11,-5,cobblestone)
Block(-3,11,-4,cobblestone)
Block(-3,12,-10,cobblestone)
Block(-3,12,-9,stone:6)
Block(-3,12,-8,AIR)
RandomBlock(-3,12,-7,WEB,25,AIR,100)
Block(-3,12,-6,AIR)
Block(-3,12,-5,stone:6)
Block(-3,12,-4,cobblestone)
Block(-3,13,-10,mossy_cobblestone)
Block(-3,13,-9,stonebrick:3)
Block(-3,13,-8,AIR)
RandomBlock(-3,13,-7,WEB,25,AIR,100)
Block(-3,13,-6,AIR)
Block(-3,13,-5,stonebrick:3)
Block(-3,13,-4,cobblestone)
Block(-3,14,-10,cobblestone)
Block(-3,14,-9,stone:6)
RandomBlock(-3,14,-8,WEB,25,AIR,100)
Block(-3,14,-7,AIR)
Block(-3,14,-6,AIR)
Block(-3,14,-5,stone:6)
Block(-3,14,-4,cobblestone)
Block(-3,15,-10,cobblestone)
Block(-3,15,-9,cobblestone)
Block(-3,15,-8,stone_stairs:7)
Block(-3,15,-7,stone_slab:11)
Block(-3,15,-6,stone_stairs:6)
Block(-3,15,-5,cobblestone)
Block(-3,15,-4,mossy_cobblestone)
Block(-3,16,-9,cobblestone)
Block(-3,16,-8,cobblestone)
Block(-3,16,-7,cobblestone)
Block(-3,16,-6,mossy_cobblestone)
Block(-3,16,-5,cobblestone)
Block(-3,16,0,AIR)
RandomBlock(-3,16,1,WEB,25,AIR,100)
Block(-3,16,2,AIR)
Block(-3,16,3,AIR)
Block(-3,17,1,AIR)
Block(-3,17,2,AIR)
Block(-3,17,3,AIR)
Block(-3,17,4,AIR)
Block(-3,17,5,AIR)
Block(-3,17,6,AIR)
Block(-3,18,2,AIR)
Block(-3,18,3,AIR)
RandomBlock(-3,18,4,WEB,25,AIR,100)
Block(-3,18,5,AIR)
Block(-3,18,6,AIR)
Block(-3,18,7,AIR)
Block(-3,18,8,AIR)
Block(-3,19,3,AIR)
Block(-3,19,4,AIR)
Block(-3,19,5,AIR)
Block(-3,19,6,AIR)
RandomBlock(-3,19,7,WEB,25,AIR,100)
RandomBlock(-3,19,8,WEB,25,AIR,100)
RandomBlock(-3,19,9,WEB,25,AIR,100)
RandomBlock(-3,20,3,WEB,25,AIR,100)
Block(-3,20,4,AIR)
Block(-3,20,5,AIR)
Block(-3,20,6,AIR)
Block(-3,20,7,AIR)
Block(-3,20,8,AIR)
Block(-3,20,9,AIR)
Block(-3,20,10,AIR)
Block(-3,21,5,AIR)
Block(-3,21,6,AIR)
RandomBlock(-3,21,7,WEB,25,AIR,100)
Block(-3,21,8,AIR)
Block(-3,21,9,AIR)
Block(-3,21,10,AIR)
Block(-3,22,7,AIR)
Block(-3,22,8,AIR)
RandomBlock(-3,22,9,WEB,25,AIR,100)
Block(-3,22,10,AIR)
Block(-3,22,11,AIR)
RandomBlock(-3,23,11,WEB,25,AIR,100)
Block(-2,11,-10,cobblestone)
Block(-2,11,-9,cobblestone)
Block(-2,11,-8,mossy_cobblestone)
Block(-2,11,-7,mossy_cobblestone)
Block(-2,11,-6,cobblestone)
Block(-2,11,-5,cobblestone)
Block(-2,11,-4,cobblestone)
Block(-2,12,-10,cobblestone)
Block(-2,12,-9,AIR)
RandomBlock(-2,12,-8,WEB,25,AIR,100)
Block(-2,12,-7,AIR)
Block(-2,12,-6,AIR)
Block(-2,12,-5,AIR)
Block(-2,12,-4,cobblestone)
Block(-2,13,-10,mossy_cobblestone)
Block(-2,13,-9,AIR)
Block(-2,13,-8,AIR)
RandomBlock(-2,13,-7,WEB,25,AIR,100)
Block(-2,13,-6,AIR)
Block(-2,13,-5,AIR)
Block(-2,13,-4,cobblestone)
Block(-2,14,-10,cobblestone)
Block(-2,14,-9,stone_stairs:5)
Block(-2,14,-8,AIR)
Block(-2,14,-7,AIR)
RandomBlock(-2,14,-6,WEB,25,AIR,100)
Block(-2,14,-5,stone_stairs:5)
Block(-2,14,-4,cobblestone)
Block(-2,15,-10,cobblestone)
Block(-2,15,-9,stone:6)
Block(-2,15,-8,AIR)
Block(-2,15,-7,AIR)
Block(-2,15,-6,AIR)
Block(-2,15,-5,stone:6)
Block(-2,15,-4,cobblestone)
Block(-2,16,-9,cobblestone)
Block(-2,16,-8,cobblestone)
Block(-2,16,-7,cobblestone)
Block(-2,16,-6,cobblestone)
Block(-2,16,-5,mossy_cobblestone)
Block(-2,18,3,AIR)
Block(-2,18,4,AIR)
Block(-2,18,5,AIR)
RandomBlock(-2,18,6,WEB,25,AIR,100)
Block(-2,18,7,AIR)
Block(-2,18,8,AIR)
Block(-2,19,4,AIR)
Block(-2,19,5,AIR)
Block(-2,19,6,AIR)
Block(-2,19,7,AIR)
Block(-2,19,8,AIR)
RandomBlock(-2,19,9,WEB,25,AIR,100)
Block(-2,19,10,AIR)
Block(-2,20,5,AIR)
Block(-2,20,6,AIR)
Block(-2,20,7,AIR)
Block(-2,20,8,AIR)
RandomBlock(-2,20,9,WEB,25,AIR,100)
Block(-2,20,10,AIR)
Block(-2,20,11,AIR)
Block(-2,21,6,AIR)
Block(-2,21,7,AIR)
Block(-2,21,8,AIR)
Block(-2,21,9,AIR)
Block(-2,21,10,AIR)
RandomBlock(-2,21,11,WEB,25,AIR,100)
Block(-2,22,7,AIR)
Block(-2,22,8,AIR)
Block(-2,22,9,AIR)
Block(-2,22,10,AIR)
Block(-2,22,11,AIR)
Block(-2,22,12,AIR)
Block(-2,22,13,AIR)
RandomBlock(-2,23,8,WEB,25,AIR,100)
RandomBlock(-2,23,9,WEB,25,AIR,100)
Block(-2,23,10,AIR)
Block(-2,23,11,AIR)
Block(-2,23,12,AIR)
Block(-1,11,-10,cobblestone)
Block(-1,11,-9,cobblestone)
Block(-1,11,-8,cobblestone)
Block(-1,11,-7,cobblestone)
Block(-1,11,-6,cobblestone)
Block(-1,11,-5,mossy_cobblestone)
Block(-1,11,-4,mossy_cobblestone)
Block(-1,12,-11,stone:6)
Block(-1,12,-10,TRIPWIRE_HOOK:4)
Block(-1,12,-9,TRIPWIRE:4)
Block(-1,12,-8,TRIPWIRE:4)
Block(-1,12,-7,TRIPWIRE:4)
Block(-1,12,-6,TRIPWIRE:4)
Block(-1,12,-5,TRIPWIRE:4)
Block(-1,12,-4,TRIPWIRE_HOOK:6)
Block(-1,12,-3,stone:6)
RandomBlock(-1,13,-11,DISPENSER:3,../../nbt/dispenserArrows.nbt,100)
Block(-1,13,-10,AIR)
Block(-1,13,-9,AIR)
RandomBlock(-1,13,-8,WEB,25,AIR,100)
Block(-1,13,-7,AIR)
Block(-1,13,-6,AIR)
Block(-1,13,-5,AIR)
Block(-1,13,-4,AIR)
RandomBlock(-1,13,-3,DISPENSER:2,../../nbt/dispenserArrows.nbt,100)
Block(-1,14,-10,stone_stairs:7)
Block(-1,14,-9,AIR)
Block(-1,14,-8,AIR)
RandomBlock(-1,14,-7,WEB,25,AIR,100)
Block(-1,14,-6,AIR)
Block(-1,14,-5,AIR)
Block(-1,14,-4,stone_stairs:6)
Block(-1,15,-10,cobblestone)
Block(-1,15,-9,stone:6)
Block(-1,15,-8,AIR)
Block(-1,15,-7,AIR)
Block(-1,15,-6,AIR)
Block(-1,15,-5,stone:6)
Block(-1,15,-4,cobblestone)
Block(-1,16,-9,cobblestone)
Block(-1,16,-8,cobblestone)
Block(-1,16,-7,cobblestone)
Block(-1,16,-6,cobblestone)
Block(-1,16,-5,cobblestone)
Block(-1,19,7,AIR)
Block(-1,19,8,AIR)
Block(-1,19,9,AIR)
RandomBlock(-1,20,7,WEB,25,AIR,100)
RandomBlock(-1,20,8,WEB,25,AIR,100)
Block(-1,20,9,AIR)
Block(-1,20,10,AIR)
Block(-1,20,11,AIR)
Block(-1,20,12,AIR)
Block(-1,21,7,AIR)
Block(-1,21,8,AIR)
Block(-1,21,9,AIR)
Block(-1,21,10,AIR)
Block(-1,21,11,AIR)
Block(-1,21,12,AIR)
RandomBlock(-1,21,13,WEB,25,AIR,100)
Block(-1,21,14,AIR)
Block(-1,22,8,AIR)
Block(-1,22,9,AIR)
Block(-1,22,10,AIR)
Block(-1,22,11,AIR)
RandomBlock(-1,22,12,WEB,25,AIR,100)
Block(-1,22,13,AIR)
Block(-1,22,14,AIR)
Block(-1,22,15,AIR)
Block(-1,23,8,AIR)
Block(-1,23,9,AIR)
Block(-1,23,10,AIR)
Block(-1,23,11,AIR)
RandomBlock(-1,23,12,WEB,25,AIR,100)
Block(-1,23,13,AIR)
Block(-1,23,14,AIR)
Block(-1,24,8,AIR)
Block(-1,24,9,AIR)
Block(-1,24,10,AIR)
Block(-1,24,11,AIR)
Block(-1,24,12,AIR)
RandomBlock(-1,24,13,WEB,25,AIR,100)
Block(0,11,-10,cobblestone)
Block(0,11,-9,cobblestone)
Block(0,11,-8,mossy_cobblestone)
Block(0,11,-7,mossy_cobblestone)
Block(0,11,-6,cobblestone)
Block(0,11,-5,cobblestone)
Block(0,11,-4,cobblestone)
Block(0,12,-10,cobblestone)
RandomBlock(0,12,-9,AIWEB,25,AIR,100R)
Block(0,12,-8,AIR)
Block(0,12,-7,AIR)
Block(0,12,-6,AIR)
Block(0,12,-5,AIR)
Block(0,12,-4,mossy_cobblestone)
Block(0,13,-10,cobblestone)
Block(0,13,-9,AIR)
Block(0,13,-8,AIR)
Block(0,13,-7,AIR)
Block(0,13,-6,AIR)
RandomBlock(0,13,-5,WEB,25,AIR,100)
Block(0,13,-4,mossy_cobblestone)
Block(0,14,-10,cobblestone)
Block(0,14,-9,stone_stairs:4)
RandomBlock(0,14,-8,WEB,25,AIR,100)
Block(0,14,-7,AIR)
Block(0,14,-6,AIR)
Block(0,14,-5,stone_stairs:4)
Block(0,14,-4,mossy_cobblestone)
Block(0,15,-10,cobblestone)
Block(0,15,-9,stone:6)
Block(0,15,-8,AIR)
Block(0,15,-7,AIR)
Block(0,15,-6,AIR)
Block(0,15,-5,stone:6)
Block(0,15,-4,cobblestone)
Block(0,16,-9,cobblestone)
Block(0,16,-8,cobblestone)
Block(0,16,-7,cobblestone)
Block(0,16,-6,mossy_cobblestone)
Block(0,16,-5,mossy_cobblestone)
Block(0,21,9,AIR)
Block(0,21,10,AIR)
RandomBlock(0,21,11,WEB,25,AIR,100)
Block(0,21,12,AIR)
Block(0,21,13,AIR)
Block(0,21,14,AIR)
Block(0,22,8,AIR)
Block(0,22,9,AIR)
Block(0,22,10,AIR)
Block(0,22,11,AIR)
Block(0,22,12,AIR)
Block(0,22,13,AIR)
RandomBlock(0,22,14,WEB,25,AIR,100)
Block(0,22,15,AIR)
Block(0,23,8,AIR)
Block(0,23,9,AIR)
Block(0,23,10,AIR)
Block(0,23,11,AIR)
Block(0,23,12,AIR)
Block(0,23,13,AIR)
Block(0,23,14,AIR)
Block(0,23,15,AIR)
RandomBlock(0,24,8,WEB,25,AIR,100)
RandomBlock(0,24,9,WEB,25,AIR,100)
Block(0,24,10,AIR)
Block(0,24,11,AIR)
Block(0,24,12,AIR)
Block(0,24,13,AIR)
Block(1,11,-10,cobblestone)
Block(1,11,-9,cobblestone)
Block(1,11,-8,cobblestone)
Block(1,11,-7,cobblestone)
Block(1,11,-6,cobblestone)
Block(1,11,-5,cobblestone)
Block(1,11,-4,cobblestone)
Block(1,12,-10,cobblestone)
Block(1,12,-9,stone:6)
Block(1,12,-8,AIR)
Block(1,12,-7,AIR)
Block(1,12,-6,AIR)
Block(1,12,-5,stone:6)
Block(1,12,-4,cobblestone)
Block(1,13,-10,cobblestone)
Block(1,13,-9,stonebrick:3)
Block(1,13,-8,AIR)
Block(1,13,-7,AIR)
Block(1,13,-6,AIR)
Block(1,13,-5,stonebrick:3)
Block(1,13,-4,mossy_cobblestone)
Block(1,14,-10,cobblestone)
Block(1,14,-9,stone:6)
RandomBlock(1,14,-8,WEB,25,AIR,100)
Block(1,14,-7,AIR)
Block(1,14,-6,AIR)
Block(1,14,-5,stone:6)
Block(1,14,-4,cobblestone)
Block(1,15,-10,cobblestone)
Block(1,15,-9,cobblestone)
Block(1,15,-8,stone_stairs:7)
Block(1,15,-7,stone_slab:11)
Block(1,15,-6,stone_stairs:6)
Block(1,15,-5,cobblestone)
Block(1,15,-4,mossy_cobblestone)
Block(1,16,-9,mossy_cobblestone)
Block(1,16,-8,mossy_cobblestone)
Block(1,16,-7,mossy_cobblestone)
Block(1,16,-6,mossy_cobblestone)
Block(1,16,-5,cobblestone)
Block(1,22,12,AIR)
RandomBlock(1,22,13,WEB,25,AIR,100)
Block(1,22,14,AIR)
Block(1,22,15,AIR)
Block(1,23,15,AIR)
Block(1,23,16,AIR)
Block(2,11,-10,cobblestone)
Block(2,11,-9,cobblestone)
Block(2,11,-8,cobblestone)
Block(2,11,-7,cobblestone)
Block(2,11,-6,cobblestone)
Block(2,11,-5,cobblestone)
Block(2,11,-4,mossy_cobblestone)
Block(2,12,-10,cobblestone)
Block(2,12,-9,AIR)
Block(2,12,-8,AIR)
Block(2,12,-7,AIR)
Block(2,12,-6,AIR)
Block(2,12,-5,AIR)
Block(2,12,-4,cobblestone)
Block(2,13,-10,cobblestone)
Block(2,13,-9,AIR)
Block(2,13,-8,AIR)
RandomBlock(2,13,-7,WEB,25,AIR,100)
Block(2,13,-6,AIR)
Block(2,13,-5,AIR)
Block(2,13,-4,cobblestone)
Block(2,14,-10,cobblestone)
Block(2,14,-9,stone_stairs:7)
Block(2,14,-8,AIR)
Block(2,14,-7,AIR)
Block(2,14,-6,AIR)
Block(2,14,-5,stone_stairs:6)
Block(2,14,-4,mossy_cobblestone)
Block(2,15,-10,cobblestone)
Block(2,15,-9,stone:6)
Block(2,15,-8,AIR)
Block(2,15,-7,AIR)
RandomBlock(2,15,-6,WEB,25,AIR,100)
Block(2,15,-5,stone:6)
Block(2,15,-4,cobblestone)
Block(2,16,-9,cobblestone)
Block(2,16,-8,cobblestone)
Block(2,16,-7,cobblestone)
Block(2,16,-6,cobblestone)
Block(2,16,-5,mossy_cobblestone)
Block(3,11,-10,cobblestone)
Block(3,11,-9,cobblestone)
Block(3,11,-8,cobblestone)
Block(3,11,-7,cobblestone)
Block(3,11,-6,cobblestone)
Block(3,11,-5,mossy_cobblestone)
Block(3,11,-4,mossy_cobblestone)
Block(3,12,-11,stone:6)
Block(3,12,-10,stone:6)
Block(3,12,-9,stone:6)
Block(3,12,-8,IRON_FENCE)
Block(3,12,-7,IRON_FENCE)
Block(3,12,-6,IRON_FENCE)
Block(3,12,-5,stone:6)
Block(3,12,-4,stone:6)
Block(3,12,-3,stone:6)
Block(3,13,-11,stone:6)
Block(3,13,-10,stone:6)
Block(3,13,-9,stonebrick:3)
Block(3,13,-8,IRON_FENCE)
Block(3,13,-7,IRON_FENCE)
Block(3,13,-6,IRON_FENCE)
Block(3,13,-5,stonebrick:3)
Block(3,13,-4,stone:6)
Block(3,13,-3,stone:6)
Block(3,14,-11,stone:6)
Block(3,14,-10,stone:6)
Block(3,14,-9,stone:6)
Block(3,14,-8,IRON_FENCE)
Block(3,14,-7,IRON_FENCE)
Block(3,14,-6,IRON_FENCE)
Block(3,14,-5,stone:6)
Block(3,14,-4,stone:6)
Block(3,14,-3,stone:6)
Block(3,15,-11,stone:6)
Block(3,15,-10,stone:6)
Block(3,15,-9,stone:6)
Block(3,15,-8,stone:6)
Block(3,15,-7,stone:6)
Block(3,15,-6,stone:6)
Block(3,15,-5,stone:6)
Block(3,15,-4,stone:6)
Block(3,15,-3,stone:6)
Block(3,16,-9,mossy_cobblestone)
Block(3,16,-8,cobblestone)
Block(3,16,-7,cobblestone)
Block(3,16,-6,cobblestone)
Block(3,16,-5,cobblestone)
Block(4,11,-13,cobblestone)
Block(4,11,-12,mossy_cobblestone)
Block(4,11,-11,cobblestone)
Block(4,11,-10,cobblestone)
Block(4,11,-9,cobblestone)
Block(4,11,-8,cobblestone)
Block(4,11,-7,cobblestone)
Block(4,11,-6,cobblestone)
Block(4,11,-5,cobblestone)
Block(4,11,-4,mossy_cobblestone)
Block(4,11,-3,mossy_cobblestone)
Block(4,11,-2,cobblestone)
Block(4,11,-1,cobblestone)
Block(4,12,-13,cobblestone)
Block(4,12,-12,stone:6)
Block(4,12,-11,stone_stairs:3)
Block(4,12,-10,AIR)
Block(4,12,-9,AIR)
Block(4,12,-8,AIR)
Block(4,12,-7,AIR)
Block(4,12,-6,AIR)
Block(4,12,-5,AIR)
Block(4,12,-4,AIR)
Block(4,12,-3,stone_stairs:2)
Block(4,12,-2,stone:6)
Block(4,12,-1,cobblestone)
Block(4,13,-13,mossy_cobblestone)
Block(4,13,-12,stone:6)
Block(4,13,-11,stone_stairs:7)
Block(4,13,-10,AIR)
Block(4,13,-9,AIR)
RandomBlock(4,13,-8,WEB,25,AIR,100)
RandomBlock(4,13,-7,WEB,25,AIR,100)
Block(4,13,-6,AIR)
Block(4,13,-5,AIR)
Block(4,13,-4,AIR)
Block(4,13,-3,stone_stairs:6)
Block(4,13,-2,stone:6)
Block(4,13,-1,cobblestone)
Block(4,14,-13,cobblestone)
Block(4,14,-12,stone:6)
Block(4,14,-11,stone_stairs:3)
RandomBlock(4,14,-10,WEB,25,AIR,100)
Block(4,14,-9,AIR)
Block(4,14,-8,AIR)
Block(4,14,-7,AIR)
Block(4,14,-6,AIR)
Block(4,14,-5,AIR)
Block(4,14,-4,AIR)
Block(4,14,-3,stone_stairs:2)
Block(4,14,-2,stone:6)
Block(4,14,-1,mossy_cobblestone)
Block(4,15,-13,cobblestone)
Block(4,15,-12,cobblestone)
Block(4,15,-11,stone_stairs:7)
Block(4,15,-10,stone_slab:11)
Block(4,15,-9,stone_slab:11)
Block(4,15,-8,stone_slab:11)
Block(4,15,-7,stone_slab:11)
Block(4,15,-6,stone_slab:11)
Block(4,15,-5,stone_slab:11)
Block(4,15,-4,stone_slab:11)
Block(4,15,-3,stone_stairs:6)
Block(4,15,-2,cobblestone)
Block(4,15,-1,cobblestone)
Block(5,11,-13,mossy_cobblestone)
Block(5,11,-12,cobblestone)
Block(5,11,-11,cobblestone)
Block(5,11,-10,cobblestone)
Block(5,11,-9,mossy_cobblestone)
Block(5,11,-8,cobblestone)
Block(5,11,-7,cobblestone)
Block(5,11,-6,cobblestone)
Block(5,11,-5,mossy_cobblestone)
Block(5,11,-4,cobblestone)
Block(5,11,-3,cobblestone)
Block(5,11,-2,mossy_cobblestone)
Block(5,11,-1,cobblestone)
Block(5,12,-13,stone:6)
RandomBlock(5,12,-12,WEB,25,AIR,100)
Block(5,12,-11,stone:6)
Block(5,12,-10,AIR)
Block(5,12,-9,AIR)
Block(5,12,-8,AIR)
Block(5,12,-7,AIR)
Block(5,12,-6,AIR)
Block(5,12,-5,AIR)
Block(5,12,-4,AIR)
Block(5,12,-3,stone:6)
Block(5,12,-2,AIR)
Block(5,12,-1,stone:6)
Block(5,13,-13,stone:6)
Block(5,13,-12,AIR)
Block(5,13,-11,stone:6)
Block(5,13,-10,AIR)
Block(5,13,-9,AIR)
Block(5,13,-8,AIR)
Block(5,13,-7,AIR)
Block(5,13,-6,AIR)
Block(5,13,-5,AIR)
Block(5,13,-4,AIR)
Block(5,13,-3,stone:6)
Block(5,13,-2,AIR)
Block(5,13,-1,stone:6)
Block(5,14,-13,stone:6)
Block(5,14,-12,AIR)
Block(5,14,-11,stone:6)
Block(5,14,-10,AIR)
Block(5,14,-9,AIR)
Block(5,14,-8,AIR)
Block(5,14,-7,AIR)
Block(5,14,-6,AIR)
Block(5,14,-5,AIR)
RandomBlock(5,14,-4,WEB,25,AIR,100)
Block(5,14,-3,stone:6)
Block(5,14,-2,AIR)
Block(5,14,-1,stone:6)
Block(5,15,-13,mossy_cobblestone)
Block(5,15,-12,stone:6)
Block(5,15,-11,stone:6)
Block(5,15,-10,stone_slab:11)
Block(5,15,-9,AIR)
Block(5,15,-8,AIR)
Block(5,15,-7,AIR)
Block(5,15,-6,AIR)
Block(5,15,-5,AIR)
Block(5,15,-4,stone_slab:11)
Block(5,15,-3,stone:6)
Block(5,15,-2,stone:6)
Block(5,15,-1,cobblestone)
Block(5,16,-9,stone:6)
Block(5,16,-8,stone:6)
Block(5,16,-7,stone:6)
Block(5,16,-6,stone:6)
Block(5,16,-5,stone:6)
Block(6,11,-13,cobblestone)
Block(6,11,-12,mossy_cobblestone)
Block(6,11,-11,cobblestone)
Block(6,11,-10,mossy_cobblestone)
Block(6,11,-9,cobblestone)
Block(6,11,-8,stone_stairs:1)
Block(6,11,-7,stone_stairs:1)
Block(6,11,-6,stone_stairs:2)
Block(6,11,-5,cobblestone)
Block(6,11,-4,mossy_cobblestone)
Block(6,11,-3,cobblestone)
Block(6,11,-2,cobblestone)
Block(6,11,-1,cobblestone)
Block(6,12,-13,stone:6)
RandomBlock(6,12,-12,WEB,25,AIR,100)
RandomBlock(6,12,-11,WEB,25,AIR,100)
RandomBlock(6,12,-10,WEB,25,AIR,100)
Block(6,12,-9,AIR)
Block(6,12,-8,AIR)
Block(6,12,-7,AIR)
Block(6,12,-6,AIR)
Block(6,12,-5,AIR)
Block(6,12,-4,AIR)
Block(6,12,-3,IRON_FENCE)
Block(6,12,-2,AIR)
Block(6,12,-1,stone:6)
Block(6,13,-13,stone:6)
Block(6,13,-12,AIR)
Block(6,13,-11,AIR)
Block(6,13,-10,AIR)
Block(6,13,-9,AIR)
Block(6,13,-8,AIR)
Block(6,13,-7,AIR)
Block(6,13,-6,AIR)
Block(6,13,-5,AIR)
Block(6,13,-4,AIR)
Block(6,13,-3,IRON_FENCE)
Block(6,13,-2,AIR)
Block(6,13,-1,stone:6)
Block(6,14,-13,stone:6)
Block(6,14,-12,AIR)
Block(6,14,-11,AIR)
Block(6,14,-10,AIR)
Block(6,14,-9,AIR)
Block(6,14,-8,AIR)
Block(6,14,-7,AIR)
Block(6,14,-6,AIR)
Block(6,14,-5,AIR)
Block(6,14,-4,AIR)
Block(6,14,-3,IRON_FENCE)
RandomBlock(6,14,-2,WEB,25,AIR,100)
Block(6,14,-1,stone:6)
Block(6,15,-13,cobblestone)
Block(6,15,-12,stone:6)
Block(6,15,-11,stone:6)
Block(6,15,-10,stone_slab:11)
Block(6,15,-9,AIR)
Block(6,15,-8,AIR)
Block(6,15,-7,AIR)
Block(6,15,-6,AIR)
Block(6,15,-5,AIR)
Block(6,15,-4,stone_slab:11)
Block(6,15,-3,stone:6)
Block(6,15,-2,stone:6)
Block(6,15,-1,mossy_cobblestone)
Block(6,16,-9,stone:6)
Block(6,16,-8,stone:6)
Block(6,16,-7,stone:6)
Block(6,16,-6,stone:6)
Block(6,16,-5,stone:6)
Block(7,11,-13,cobblestone)
Block(7,11,-12,mossy_cobblestone)
Block(7,11,-11,mossy_cobblestone)
Block(7,11,-10,mossy_cobblestone)
Block(7,11,-9,mossy_cobblestone)
Block(7,11,-8,stone_stairs:3)
Block(7,11,-7,stone:6)
Block(7,11,-6,stone_stairs:2)
Block(7,11,-5,cobblestone)
Block(7,11,-4,cobblestone)
Block(7,11,-3,cobblestone)
Block(7,11,-2,cobblestone)
Block(7,11,-1,mossy_cobblestone)
Block(7,12,-13,stone:6)
RandomBlock(7,12,-12,WEB,25,AIR,100)
RandomBlock(7,12,-11,WEB,25,AIR,100)
RandomBlock(7,12,-10,WEB,25,AIR,100)
Block(7,12,-9,AIR)
Block(7,12,-8,AIR)
Block(7,12,-7,AIR)
Block(7,12,-6,AIR)
Block(7,12,-5,AIR)
Block(7,12,-4,AIR)
Block(7,12,-3,IRON_FENCE)
Block(7,12,-2,AIR)
Block(7,12,-1,stone:6)
Block(7,13,-13,stone:6)
Block(7,13,-12,AIR)
Block(7,13,-11,AIR)
Block(7,13,-10,AIR)
Block(7,13,-9,AIR)
Block(7,13,-8,AIR)
Block(7,13,-7,AIR)
Block(7,13,-6,AIR)
Block(7,13,-5,AIR)
Block(7,13,-4,AIR)
Block(7,13,-3,IRON_FENCE)
Block(7,13,-2,AIR)
Block(7,13,-1,stone:6)
Block(7,14,-13,stone:6)
Block(7,14,-12,AIR)
Block(7,14,-11,IRON_FENCE)
Block(7,14,-10,AIR)
Block(7,14,-9,AIR)
Block(7,14,-8,AIR)
Block(7,14,-7,AIR)
Block(7,14,-6,AIR)
Block(7,14,-5,AIR)
Block(7,14,-4,AIR)
Block(7,14,-3,IRON_FENCE)
Block(7,14,-2,AIR)
Block(7,14,-1,stone:6)
Block(7,15,-13,cobblestone)
Block(7,15,-12,stone:6)
Block(7,15,-11,stone:6)
Block(7,15,-10,stone_slab:11)
Block(7,15,-9,AIR)
Block(7,15,-8,AIR)
Block(7,15,-7,AIR)
Block(7,15,-6,AIR)
Block(7,15,-5,AIR)
Block(7,15,-4,stone_slab:11)
Block(7,15,-3,stone:6)
Block(7,15,-2,stone:6)
Block(7,15,-1,cobblestone)
Block(7,16,-9,stone:6)
Block(7,16,-8,stone:6)
RandomBlock(7,16,-7,MOB_SPAWNER,../../nbt/spawnerSpiderCave.nbt,100)
Block(7,16,-6,stone:6)
Block(7,16,-5,stone:6)
Block(8,11,-13,cobblestone)
Block(8,11,-12,mossy_cobblestone)
Block(8,11,-11,cobblestone)
Block(8,11,-10,mossy_cobblestone)
Block(8,11,-9,mossy_cobblestone)
Block(8,11,-8,stone_stairs:0)
Block(8,11,-7,stone_stairs:0)
Block(8,11,-6,stone_stairs:0)
Block(8,11,-5,mossy_cobblestone)
Block(8,11,-4,mossy_cobblestone)
Block(8,11,-3,cobblestone)
Block(8,11,-2,mossy_cobblestone)
Block(8,11,-1,mossy_cobblestone)
Block(8,12,-13,stone:6)
Block(8,12,-12,AIR)
Block(8,12,-11,IRON_FENCE)
Block(8,12,-10,AIR)
Block(8,12,-9,AIR)
Block(8,12,-8,AIR)
Block(8,12,-7,AIR)
Block(8,12,-6,AIR)
Block(8,12,-5,AIR)
Block(8,12,-4,AIR)
Block(8,12,-3,AIR)
Block(8,12,-2,AIR)
Block(8,12,-1,stone:6)
Block(8,13,-13,stone:6)
Block(8,13,-12,AIR)
Block(8,13,-11,IRON_FENCE)
Block(8,13,-10,AIR)
Block(8,13,-9,AIR)
Block(8,13,-8,AIR)
Block(8,13,-7,AIR)
Block(8,13,-6,AIR)
Block(8,13,-5,AIR)
Block(8,13,-4,AIR)
Block(8,13,-3,AIR)
RandomBlock(8,13,-2,WEB,25,AIR,100)
Block(8,13,-1,stone:6)
Block(8,14,-13,stone:6)
Block(8,14,-12,AIR)
Block(8,14,-11,IRON_FENCE)
Block(8,14,-10,AIR)
Block(8,14,-9,AIR)
Block(8,14,-8,AIR)
Block(8,14,-7,AIR)
Block(8,14,-6,AIR)
Block(8,14,-5,AIR)
Block(8,14,-4,AIR)
Block(8,14,-3,IRON_FENCE)
Block(8,14,-2,AIR)
Block(8,14,-1,stone:6)
Block(8,15,-13,mossy_cobblestone)
Block(8,15,-12,stone:6)
Block(8,15,-11,stone:6)
Block(8,15,-10,stone_slab:11)
Block(8,15,-9,AIR)
Block(8,15,-8,AIR)
Block(8,15,-7,AIR)
Block(8,15,-6,AIR)
Block(8,15,-5,AIR)
Block(8,15,-4,stone_slab:11)
Block(8,15,-3,stone:6)
Block(8,15,-2,stone:6)
Block(8,15,-1,cobblestone)
Block(8,16,-9,stone:6)
Block(8,16,-8,stone:6)
Block(8,16,-7,stone:6)
Block(8,16,-6,stone:6)
Block(8,16,-5,stone:6)
Block(9,11,-13,mossy_cobblestone)
Block(9,11,-12,cobblestone)
Block(9,11,-11,cobblestone)
Block(9,11,-10,cobblestone)
Block(9,11,-9,cobblestone)
Block(9,11,-8,cobblestone)
Block(9,11,-7,mossy_cobblestone)
Block(9,11,-6,cobblestone)
Block(9,11,-5,cobblestone)
Block(9,11,-4,cobblestone)
Block(9,11,-3,mossy_cobblestone)
Block(9,11,-2,mossy_cobblestone)
Block(9,11,-1,cobblestone)
Block(9,12,-13,stone:6)
Block(9,12,-12,AIR)
Block(9,12,-11,stone:6)
Block(9,12,-10,AIR)
Block(9,12,-9,AIR)
Block(9,12,-8,AIR)
Block(9,12,-7,AIR)
Block(9,12,-6,AIR)
Block(9,12,-5,AIR)
RandomBlock(9,12,-4,WEB,25,AIR,100)
Block(9,12,-3,stone:6)
RandomBlock(9,12,-2,WEB,25,AIR,100)
Block(9,12,-1,stone:6)
Block(9,13,-13,stone:6)
Block(9,13,-12,AIR)
Block(9,13,-11,stone:6)
RandomBlock(9,13,-10,WEB,25,AIR,100)
RandomBlock(9,13,-9,WEB,25,AIR,100)
RandomBlock(9,13,-8,WEB,25,AIR,100)
Block(9,13,-7,AIR)
Block(9,13,-6,AIR)
Block(9,13,-5,AIR)
Block(9,13,-4,AIR)
Block(9,13,-3,stone:6)
Block(9,13,-2,AIR)
Block(9,13,-1,stone:6)
Block(9,14,-13,stone:6)
RandomBlock(9,14,-12,WEB,25,AIR,100)
Block(9,14,-11,stone:6)
Block(9,14,-10,AIR)
Block(9,14,-9,AIR)
Block(9,14,-8,AIR)
Block(9,14,-7,AIR)
Block(9,14,-6,AIR)
Block(9,14,-5,AIR)
Block(9,14,-4,AIR)
Block(9,14,-3,stone:6)
Block(9,14,-2,AIR)
Block(9,14,-1,stone:6)
Block(9,15,-13,cobblestone)
Block(9,15,-12,stone:6)
Block(9,15,-11,stone:6)
Block(9,15,-10,stone_slab:11)
RandomBlock(9,15,-9,WEB,25,AIR,100)
Block(9,15,-8,AIR)
Block(9,15,-7,AIR)
Block(9,15,-6,AIR)
Block(9,15,-5,AIR)
Block(9,15,-4,stone_slab:11)
Block(9,15,-3,stone:6)
Block(9,15,-2,stone:6)
Block(9,15,-1,cobblestone)
Block(9,16,-9,stone:6)
Block(9,16,-8,stone:6)
Block(9,16,-7,stone:6)
Block(9,16,-6,stone:6)
Block(9,16,-5,stone:6)
Block(10,11,-13,mossy_cobblestone)
Block(10,11,-12,cobblestone)
Block(10,11,-11,cobblestone)
Block(10,11,-10,cobblestone)
Block(10,11,-9,cobblestone)
Block(10,11,-8,mossy_cobblestone)
Block(10,11,-7,cobblestone)
Block(10,11,-6,mossy_cobblestone)
Block(10,11,-5,cobblestone)
Block(10,11,-4,cobblestone)
Block(10,11,-3,mossy_cobblestone)
Block(10,11,-2,cobblestone)
Block(10,11,-1,cobblestone)
Block(10,12,-13,mossy_cobblestone)
Block(10,12,-12,stone:6)
Block(10,12,-11,stone_stairs:3)
RandomBlock(10,12,-10,WEB,25,AIR,100)
RandomBlock(10,12,-9,WEB,25,AIR,100)
RandomBlock(10,12,-8,WEB,25,AIR,100)
RandomBlock(10,12,-7,WEB,25,AIR,100)
Block(10,12,-6,AIR)
Block(10,12,-5,AIR)
Block(10,12,-4,AIR)
Block(10,12,-3,stone_stairs:2)
Block(10,12,-2,stone:6)
Block(10,12,-1,cobblestone)
Block(10,13,-13,cobblestone)
Block(10,13,-12,stone:6)
Block(10,13,-11,stone_stairs:7)
Block(10,13,-10,AIR)
Block(10,13,-9,AIR)
Block(10,13,-8,AIR)
Block(10,13,-7,AIR)
Block(10,13,-6,AIR)
Block(10,13,-5,AIR)
RandomBlock(10,13,-4,WEB,25,AIR,100)
Block(10,13,-3,stone_stairs:6)
Block(10,13,-2,stone:6)
Block(10,13,-1,cobblestone)
Block(10,14,-13,cobblestone)
Block(10,14,-12,stone:6)
Block(10,14,-11,stone_stairs:3)
Block(10,14,-10,AIR)
Block(10,14,-9,AIR)
Block(10,14,-8,AIR)
Block(10,14,-7,AIR)
Block(10,14,-6,AIR)
RandomBlock(10,14,-5,WEB,25,AIR,100)
RandomBlock(10,14,-4,WEB,25,AIR,100)
Block(10,14,-3,stone_stairs:2)
Block(10,14,-2,stone:6)
Block(10,14,-1,mossy_cobblestone)
Block(10,15,-13,cobblestone)
Block(10,15,-12,cobblestone)
Block(10,15,-11,stone_stairs:7)
Block(10,15,-10,stone_slab:11)
Block(10,15,-9,stone_slab:11)
Block(10,15,-8,stone_slab:11)
Block(10,15,-7,stone_slab:11)
Block(10,15,-6,stone_slab:11)
Block(10,15,-5,stone_slab:11)
Block(10,15,-4,stone_slab:11)
Block(10,15,-3,stone_stairs:6)
Block(10,15,-2,cobblestone)
Block(10,15,-1,cobblestone)
Block(11,11,-9,cobblestone)
Block(11,11,-8,cobblestone)
Block(11,11,-7,cobblestone)
Block(11,11,-6,cobblestone)
Block(11,11,-5,cobblestone)
Block(11,12,-11,cobblestone)
Block(11,12,-10,cobblestone)
Block(11,12,-9,stone:6)
Block(11,12,-8,IRON_FENCE)
Block(11,12,-7,IRON_FENCE)
Block(11,12,-6,IRON_FENCE)
Block(11,12,-5,stone:6)
Block(11,12,-4,mossy_cobblestone)
Block(11,12,-3,cobblestone)
Block(11,13,-11,cobblestone)
Block(11,13,-10,cobblestone)
Block(11,13,-9,stone:6)
Block(11,13,-8,IRON_FENCE)
Block(11,13,-7,IRON_FENCE)
Block(11,13,-6,IRON_FENCE)
Block(11,13,-5,stone:6)
Block(11,13,-4,mossy_cobblestone)
Block(11,13,-3,mossy_cobblestone)
Block(11,14,-11,mossy_cobblestone)
Block(11,14,-10,cobblestone)
Block(11,14,-9,stone:6)
Block(11,14,-8,IRON_FENCE)
Block(11,14,-7,IRON_FENCE)
Block(11,14,-6,IRON_FENCE)
Block(11,14,-5,stone:6)
Block(11,14,-4,cobblestone)
Block(11,14,-3,cobblestone)
Block(11,15,-11,cobblestone)
Block(11,15,-10,cobblestone)
Block(11,15,-9,stone:6)
Block(11,15,-8,stone:6)
Block(11,15,-7,stone:6)
Block(11,15,-6,stone:6)
Block(11,15,-5,stone:6)
Block(11,15,-4,cobblestone)
Block(11,15,-3,cobblestone)
Block(12,11,-9,mossy_cobblestone)
Block(12,11,-8,cobblestone)
Block(12,11,-7,cobblestone)
Block(12,11,-6,cobblestone)
Block(12,11,-5,mossy_cobblestone)
Block(12,12,-9,cobblestone)
RandomBlock(12,12,-8,WEB,25,AIR,100)
Block(12,12,-7,AIR)
Block(12,12,-6,WEB)
Block(12,12,-5,cobblestone)
Block(12,13,-9,cobblestone)
Block(12,13,-8,AIR)
Block(12,13,-7,AIR)
Block(12,13,-6,AIR)
Block(12,13,-5,cobblestone)
Block(12,14,-9,mossy_cobblestone)
Block(12,14,-8,WEB)
Block(12,14,-7,AIR)
RandomBlock(12,14,-6,WEB,25,AIR,100)
Block(12,14,-5,mossy_cobblestone)
Block(12,15,-9,mossy_cobblestone)
Block(12,15,-8,cobblestone)
Block(12,15,-7,cobblestone)
Block(12,15,-6,cobblestone)
Block(12,15,-5,mossy_cobblestone)
Block(13,11,-9,cobblestone)
Block(13,11,-8,cobblestone)
Block(13,11,-7,cobblestone)
Block(13,11,-6,cobblestone)
Block(13,11,-5,cobblestone)
Block(13,12,-9,mossy_cobblestone)
Block(13,12,-8,WEB)
Block(13,12,-7,WEB)
Block(13,12,-6,WEB)
Block(13,12,-5,cobblestone)
Block(13,13,-9,cobblestone)
Block(13,13,-8,WEB)
RandomBlock(13,13,-7,WEB,25,AIR,100)
RandomBlock(13,13,-6,WEB,25,AIR,100)
Block(13,13,-5,cobblestone)
Block(13,14,-9,mossy_cobblestone)
Block(13,14,-8,AIR)
Block(13,14,-7,AIR)
Block(13,14,-6,WEB)
Block(13,14,-5,cobblestone)
Block(13,15,-9,cobblestone)
Block(13,15,-8,cobblestone)
Block(13,15,-7,cobblestone)
Block(13,15,-6,mossy_cobblestone)
Block(13,15,-5,cobblestone)
Block(14,11,-9,mossy_cobblestone)
Block(14,11,-8,mossy_cobblestone)
Block(14,11,-7,mossy_cobblestone)
Block(14,11,-6,cobblestone)
Block(14,11,-5,cobblestone)
Block(14,12,-9,cobblestone)
RandomBlock(14,12,-8,CHEST:4,../../nbt/chestDungeon.nbt,100)
Block(14,12,-7,WEB)
RandomBlock(14,12,-6,CHEST:4,../../nbt/chestDungeon.nbt,100)
Block(14,12,-5,cobblestone)
Block(14,13,-9,cobblestone)
Block(14,13,-8,WEB)
Block(14,13,-7,WEB)
Block(14,13,-6,WEB)
Block(14,13,-5,cobblestone)
Block(14,14,-9,cobblestone)
Block(14,14,-8,WEB)
Block(14,14,-7,WEB)
Block(14,14,-6,WEB)
Block(14,14,-5,cobblestone)
Block(14,15,-9,cobblestone)
Block(14,15,-8,cobblestone)
Block(14,15,-7,mossy_cobblestone)
Block(14,15,-6,cobblestone)
Block(14,15,-5,cobblestone)
Block(15,11,-9,cobblestone)
Block(15,11,-8,cobblestone)
Block(15,11,-7,cobblestone)
Block(15,11,-6,cobblestone)
Block(15,11,-5,cobblestone)
Block(15,12,-9,mossy_cobblestone)
Block(15,12,-8,mossy_cobblestone)
Block(15,12,-7,mossy_cobblestone)
Block(15,12,-6,mossy_cobblestone)
Block(15,12,-5,mossy_cobblestone)
Block(15,13,-9,cobblestone)
Block(15,13,-8,cobblestone)
Block(15,13,-7,cobblestone)
Block(15,13,-6,cobblestone)
Block(15,13,-5,cobblestone)
Block(15,14,-9,mossy_cobblestone)
Block(15,14,-8,cobblestone)
Block(15,14,-7,cobblestone)
Block(15,14,-6,mossy_cobblestone)
Block(15,14,-5,cobblestone)
Block(15,15,-9,cobblestone)
Block(15,15,-8,cobblestone)
Block(15,15,-7,cobblestone)
Block(15,15,-6,mossy_cobblestone)
Block(15,15,-5,cobblestone)

#######################################################################
# +-----------------------------------------------------------------+ #
# |                            BO3 checks                           | #
# +-----------------------------------------------------------------+ #
#######################################################################

# Require a condition at a certain location in order for the BO3 to be spawned.
# BlockCheck(x,y,z,BlockName[,BlockName[,...]]) - one of the blocks must be at the location
# BlockCheckNot(x,y,z,BlockName[,BlockName[,...]]) - all the blocks must not be at the location
# LightCheck(x,y,z,minLightLevel,maxLightLevel) - light must be between min and max (inclusive)
# ModCheck(ModName[,ModName[,...]]) - all the mods listed must be loaded
# ModCheckNot(ModName[,ModName[,...]]) - all the mods listed must not be loaded

# You can use "Solid" as a BlockName for matching all solid blocks or "All" to match all blocks that aren't air.

# Examples:
#   BlockCheck(0,-1,0,GRASS,DIRT)  Require grass or dirt just below the object
#   BlockCheck(0,-1,0,Solid)       Require any solid block just below the object
#   BlockCheck(0,-1,0,WOOL)        Require any type of wool just below the object
#   BlockCheck(0,-1,0,WOOL:0)      Require white wool just below the object
#   BlockCheckNot(0,-1,0,WOOL:0)   Require that there is no white wool below the object
#   LightCheck(0,0,0,0,1)          Require almost complete darkness just below the object

#######################################################################
# +-----------------------------------------------------------------+ #
# |                             Branches                            | #
# +-----------------------------------------------------------------+ #
#######################################################################

# Branches are child-BO3's that spawn if this BO3 is configured to spawn as a
# CustomStructure resource in a biome config. Branches can have branches,
# making complex structures possible. See the wiki for more details.

# Regular Branches spawn each branch with an independent chance of spawning.
# Branch(x,y,z,branchName,rotation,chance[,anotherBranchName,rotation,chance[,...]][IndividualChance])
# branchName - name of the object to spawn.
# rotation - NORTH, SOUTH, EAST or WEST.
# IndividualChance - The chance each branch has to spawn, assumed to be 100 when left blank
# isRequiredBranch - If this is set to true then at least one of the branches in this BO3 must spawn at these x,y,z coordinates. If no branch can spawn there then this BO3 fails to spawn and its branch is rolled back.
# isRequiredBranch:true branches must spawn or the current branch is rolled back entirely. This is useful for grouping BO3's that must spawn together, for instance a single room made of multiple BO3's/branches.
# If all parts of the room are connected together via isRequiredBranch:true branches then either the entire room will spawns or no part of it will spawn.
# *Note: When isRequiredBranch:true only one BO3 can be added per Branch() and it will automatically have a rarity of 100.0.
# isRequiredBranch:false branches are used to make optional parts of structures, for instance the middle section of a tunnel that has a beginning, middle and end BO3/branch and can have a variable length by repeating the middle BO3/branch.
# By making the start and end branches isRequiredBranch:true and the middle branch isRequiredbranch:false you can make it so that either:
# A. A tunnel spawns with at least a beginning and end branch
# B. A tunnel spawns with a beginning and end branch and as many middle branches as will fit in the available space.
# C. No tunnel spawns at all because there wasn't enough space to spawn at least a beginning and end branch.
# branchDepth - When creating a chain of branches that contains optional (isRequiredBranch:false) branches branch depth is configured for the first BO3 in the chain to determine the maximum length of the chain.
# branchDepth - 1 is inherited by each isRequiredBranch:false branch in the chain. When branchDepth is zero isRequiredBranch:false branches cannot spawn and the chain ends. In the case of the tunnel this means the last middle branch would be
# rolled back and an IsRequiredBranch:true end branch could be spawned in its place to make sure the tunnel has a proper ending.
# Instead of inheriting branchDepth - 1 from the parent branchDepth can be overridden by child branches if it is set higher than 0 (the default value).
# isRequiredBranch:true branches do inherit branchDepth and pass it on to their own branches, however they cannot be prevented from spawning by it and also don't subtract 1 from branchDepth when inheriting it.

# Weighted Branches spawn branches with a dependent chance of spawning.
# WeightedBranch(x,y,z,branchName,rotation,chance[,anotherBranchName,rotation,chance[,...]][MaxChanceOutOf])
# *Note: isRequiredBranch must be set to false. It is not possible to use isRequiredBranch:true with WeightedBranch() since isRequired:true branches must spawn and automatically have a rarity of 100.0.
# MaxChanceOutOf - The chance all branches have to spawn out of, assumed to be 100 when left blank
Branch(0,0,0,dungeonDesertC0R0,NORTH,100.0)

#######################################################################
# +-----------------------------------------------------------------+ #
# |                             Entities                            | #
# +-----------------------------------------------------------------+ #
#######################################################################

# Forge only (this may have changed, check for updates).
# An EntityFunction spawns an entity instead of a block. The entity is spawned only once when the BO3 is spawned.
# Entities are persistent by default so they don't de-spawn when no player is near, they are only unloaded.
# Usage: Entity(x,y,z,entityName,groupSize,NameTagOrNBTFileName) or Entity(x,y,z,mobName,groupSize)
# Use /otg entities to get a list of entities that can be used as entityName, this includes entities added by other mods and non-living entities.
# NameTagOrNBTFileName can be either a nametag for the mob or an .txt file with nbt data (such as myentityinfo.txt).
# In the text file you can use the same mob spawning parameters used with the /summon command to equip the
# entity and give it custom attributes etc. You can copy the DATA part of a summon command including surrounding 
# curly braces to a .txt file, for instance for: "/summon Skeleton x y z {DATA}"
# *Note: Unlike Block(), for Entity() .nbt files don't work, only .txt files work.


#######################################################################
# +-----------------------------------------------------------------+ #
# |                            Particles                            | #
# +-----------------------------------------------------------------+ #
#######################################################################

# Forge only (this may have changed, check for updates).
# Creates an invisible particle spawner at the given location that spawns particles every x milliseconds.
# Usage: Particle(x,y,z,particleName,interval,velocityX,velocityY,velocityZ)
# velocityX, velocityY and velocityZ are optional.
# Only vanilla particle names can be used, for 1.11.2 these are;
# explode, largeexplode, hugeexplosion, fireworksSpark, bubble, splash, wake, suspended
# depthsuspend, crit, magicCrit, smoke, largesmoke, spell, instantSpell, mobSpell
# mobSpellAmbient, witchMagic, dripWater, dripLava, angryVillager, happyVillager
# townaura, note, portal, enchantmenttable, flame, lava, footstep, cloud, reddust
# snowballpoof,  snowshovel, slime, heart, barrier, iconcrack, blockcrack, blockdust
# droplet, take, mobappearance, dragonbreath, endRod, damageIndicator, sweepAttack
# fallingdust, totem, spit.
# velocityX,velocityY,velocityZ - Spawn the enemy with the given velocity. If this is not filled in then a small random velocity is applied.

#######################################################################
# +-----------------------------------------------------------------+ #
# |                             Spawners                            | #
# +-----------------------------------------------------------------+ #
#######################################################################

# Forge only (this may have changed, check for updates).
# Creates an invisible entity spawner at the given location that spawns entities every x seconds.
# Entities can only spawn if their spawn requirements are met (zombies/skeletons only spawn in the dark etc). Max entity count for the server is ignored, each spawner has its own maxCount setting.
# Usage: Spawner(x,y,z,entityName,nbtFileName,groupSize,interval,spawnChance,maxCount,despawnTime,velocityX,velocityY,velocityZ,yaw,pitch)
# nbtFileName, despawnTime, velocityX, velocityY, velocityZ, yaw and pitch are optional
# Example Spawner(0, 0, 0, Villager, 1, 5, 100, 5) or Spawner(0, 0, 0, Villager, villager1.txt, 1, 5, 100, 5) or Spawner(0, 0, 0, Villager, 1, 5, 100, 5, 30, 1, 1, 1, 0, 0)
# entityName - Name of the entity to spawn, use /otg entities to get a list of entities that can be used as entityName, this includes entities added by other mods and non-living entities.
# nbtFileName - A .txt file with nbt data (such as myentityinfo.txt).
# In the text file you can use the same mob spawning parameters used with the /summon command to equip the
# entity and give it custom attributes etc. You can copy the DATA part of a summon command including surrounding 
# curly braces to a .txt file, for instance for: "/summon Skeleton x y z {DATA}"
# *Note: Unlike Block(), for Spawner() .nbt files don't work, only .txt files work.
# groupSize - Number of entities that should spawn for each successful spawn attempt.
# interval - Time in seconds between each spawn attempt.
# spawnChance - For each spawn attempt, the chance between 0-100 that the spawn attempt will succeed.
# maxCount - The maximum amount of this kind of entity that can exist within 32 blocks. If there are already maxCount or more entities of this type in a 32 radius this spawner will not spawn anything.
# despawnTime - After despawnTime seconds, if there is no player within 32 blocks of the entity it will despawn..
# velocityX,velocityY,velocityZ,yaw,pitch - Spawn the enemy with the given velocity and angle, handy for making traps and launchers (shooting arrows and fireballs etc).

#######################################################################
# +-----------------------------------------------------------------+ #
# |                             ModData                             | #
# +-----------------------------------------------------------------+ #
#######################################################################

# Forge only.
# Use the ModData() tag to include data that other mods can use
# Mod makers can use ModData and the /otg GetModData command to test IMC communications between OTG
# and their mod.
# Normal users can use it to spawn some mobs and blocks on command.
# ModData(x,y,z,"ModName", "MyModDataAsText"
# Example: ModData(x,y,z,MyCystomNPCMod,SpawnBobHere/WithAPotato/And50Health)
# Try not to use exotic/reserved characters, like brackets and comma's etc, this stuff isn't fool-proof.
# Also, use this only to store IDs/object names etc for your mod, DO NOT include things like character dialogue,
# messages on signs, loot lists etc in this file. As much as possible just store id's/names here and store all the data related to those id's/names in your own mod.
# OTG has some built in ModData commands for basic mob and block spawning.
# These are mostly just a demonstration for mod makers to show how ModData.
# can be used by other mods.
# For mob spawning in OTG use: ModData(x,y,z,OTG,mob/MobType/Count/Persistent/Name)
# mob: Makes OTG recognise this as a mob spawning command.
# MobType: Lower-case, no spaces. Any vanilla mob like dragon, skeleton, wither, villager etc
# Count: The number of mobs to spawn
# Persistent (true/false): Should the mobs never de-spawn? If set to true the mob will get a
# name-tag ingame so you can recognise it.
# Name: A name-tag for the monster/npc.
# Example: ModData(0,0,0,OTG,villager/1/true/Bob)
# To spawn blocks using ModData use: ModData(x,y,z,OTG,block/material)
# block: Makes OTG recognise this as a block spawning command.
# material: id or text, custom blocks can be added using ModName:MaterialName.
# To send all ModData within a radius in chunks around the player to the specified mod
# use this console command: /otg GetModData ModName Radius
# ModName: name of the mod, for OTG commands use OTG 
# Radius (optional): Radius in chunks around the player.
